{"arg":{"channel":"tickers","instId":"ETH-USDT-SWAP"},"data":[{"instType":"SWAP","instId":"ETH-USDT-SWAP","last":"3124.91","lastSz":"0.13","askPx":"3126","askSz":"2.19","bidPx":"3124.91","bidSz":"202.04","open24h":"3248.4","high24h":"3315.64","low24h":"3072.11","sodUtc0":"3108.41","sodUtc8":"3174.4","volCcy24h":"19462823.251","vol24h":"194628232.51","ts":"1765631997611"}]}
{"arg":{"channel":"bbo-tbt","instId":"ETH-USDT-SWAP"},"data":[{"asks":[["3126","2.11","0","1"]],"bids":[["3124.91","201.73","0","2"]],"ts":"1765631997647","seqId":1158518881}]}
{"arg":{"channel":"books","instId":"ETH-USDT-SWAP"},"action":"update","data":[{"asks":[["3126","2.11","0","1"]],"bids":[["3124.91","201.73","0","2"]],"ts":"1765631997707","checksum":-1741089739,"seqId":1158518881,"prevSeqId":1158518877}]}
{"arg":{"channel":"books5","instId":"ETH-USDT-SWAP"},"data":[{"asks":[["3126","2.11","0","1"],["3126.32","0.15","0","1"],["3126.39","37.73","0","1"],["3126.43","0.02","0","1"],["3126.5","0.07","0","4"]],"bids":[["3124.91","201.73","0","2"],["3124.9","18.78","0","3"],["3124.89","0.1","0","2"],["3124.88","198.47","0","4"],["3124.87","0.78","0","5"]],"instId":"ETH-USDT-SWAP","ts":"1765631997707","seqId":1158518881}]}
{"arg":{"channel":"tickers","instId":"ETH-USDT-SWAP"},"data":[{"instType":"SWAP","instId":"ETH-USDT-SWAP","last":"3126","lastSz":"0.08","askPx":"3126","askSz":"2.11","bidPx":"3124.91","bidSz":"201.73","open24h":"3248.4","high24h":"3315.64","low24h":"3072.11","sodUtc0":"3108.41","sodUtc8":"3174.4","volCcy24h":"19462823.29","vol24h":"194628232.9","ts":"1765631997765"}]}
{"arg":{"channel":"bbo-tbt","instId":"ETH-USDT-SWAP"},"data":[{"asks":[["3126","2.11","0","1"]],"bids":[["3124.91","201.61","0","2"]],"ts":"1765631997827","seqId":1158518894}]}
{"arg":{"channel":"bbo-tbt","instId":"ETH-USDT-SWAP"},"data":[{"asks":[["3126","2.11","0","1"]],"bids":[["3124.88","196.88","0","4"]],"ts":"1765631997837","seqId":1158518930}]}
{"arg":{"channel":"bbo-tbt","instId":"ETH-USDT-SWAP"},"data":[{"asks":[["3126","2.11","0","1"]],"bids":[["3124.88","196.77","0","4"]],"ts":"1765631997857","seqId":1158518933}]}
{"arg":{"channel":"bbo-tbt","instId":"ETH-USDT-SWAP"},"data":[{"asks":[["3126","2.11","0","1"]],"bids":[["3124.88","196.62","0","4"]],"ts":"1765631997887","seqId":1158518935}]}
{"arg":{"channel":"bbo-tbt","instId":"ETH-USDT-SWAP"},"data":[{"asks":[["3126","2.05","0","1"]],"bids":[["3124.88","196.62","0","4"]],"ts":"1765631997897","seqId":1158518937}]}
{"arg":{"channel":"books","instId":"ETH-USDT-SWAP"},"action":"update","data":[{"asks":[["3126","2.05","0","1"],["3126.16","0.01","0","1"],["3126.32","20.15","0","2"],["3126.8","0.02","0","2"],["3127.8","18.76","0","1"],["3128.01","0.03","0","2"],["3128.21","232.36","0","7"],["3132.11","0","0","0"],["3132.13","0","0","0"]],"bids":[["3124.91","0","0","0"],["3124.9","0","0","0"],["3124.89","0","0","0"],["3124.88","196.62","0","4"],["3120.53","3.13","0","8"],["3120.52","12.05","0","2"],["3120.51","0.11","0","5"]],"ts":"1765631997907","checksum":-1836088751,"seqId":1158518937,"prevSeqId":1158518881}]}
{"arg":{"channel":"books5","instId":"ETH-USDT-SWAP"},"data":[{"asks":[["3126","2.05","0","1"],["3126.16","0.01","0","1"],["3126.32","20.15","0","2"],["3126.39","37.73","0","1"],["3126.43","0.02","0","1"]],"bids":[["3124.88","196.62","0","4"],["3124.87","0.78","0","5"],["3124.86","47.42","0","1"],["3124.85","31.43","0","6"],["3124.84","4.02","0","3"]],"instId":"ETH-USDT-SWAP","ts":"1765631997907","seqId":1158518937}]}
{"arg":{"channel":"tickers","instId":"ETH-USDT-SWAP"},"data":[{"instType":"SWAP","instId":"ETH-USDT-SWAP","last":"3124.88","lastSz":"0.15","askPx":"3126","askSz":"2.11","bidPx":"3124.88","bidSz":"196.62","open24h":"3248.4","high24h":"3315.64","low24h":"3072.11","sodUtc0":"3108.41","sodUtc8":"3174.4","volCcy24h":"19462845.536","vol24h":"194628455.36","ts":"1765631997889"}]}
{"arg":{"channel":"bbo-tbt","instId":"ETH-USDT-SWAP"},"data":[{"asks":[["3126","2.05","0","1"]],"bids":[["3124.88","196.49","0","4"]],"ts":"1765631997927","seqId":1158518939}]}
{"arg":{"channel":"bbo-tbt","instId":"ETH-USDT-SWAP"},"data":[{"asks":[["3126","2.05","0","1"]],"bids":[["3124.88","195.27","0","4"]],"ts":"1765631997967","seqId":1158518951}]}
{"arg":{"channel":"books","instId":"ETH-USDT-SWAP"},"action":"update","data":[{"asks":[],"bids":[["3124.88","195.27","0","4"]],"ts":"1765631998007","checksum":2121232593,"seqId":1158518961,"prevSeqId":1158518937}]}
{"arg":{"channel":"books5","instId":"ETH-USDT-SWAP"},"data":[{"asks":[["3126","2.05","0","1"],["3126.16","0.01","0","1"],["3126.32","20.15","0","2"],["3126.39","37.73","0","1"],["3126.43","0.02","0","1"]],"bids":[["3124.88","195.27","0","4"],["3124.87","0.78","0","5"],["3124.86","47.42","0","1"],["3124.85","31.43","0","6"],["3124.84","4.02","0","3"]],"instId":"ETH-USDT-SWAP","ts":"1765631998007","seqId":1158518961}]}
{"arg":{"channel":"tickers","instId":"ETH-USDT-SWAP"},"data":[{"instType":"SWAP","instId":"ETH-USDT-SWAP","last":"3124.88","lastSz":"1.22","askPx":"3126","askSz":"2.05","bidPx":"3124.88","bidSz":"195.27","open24h":"3248.4","high24h":"3315.64","low24h":"3072.11","sodUtc0":"3108.41","sodUtc8":"3174.4","volCcy24h":"19462845.677","vol24h":"194628456.77","ts":"1765631998011"}]}
{"arg":{"channel":"bbo-tbt","instId":"ETH-USDT-SWAP"},"data":[{"asks":[["3126","2.05","0","1"]],"bids":[["3124.88","194.74","0","4"]],"ts":"1765631998037","seqId":1158518973}]}
{"arg":{"channel":"bbo-tbt","instId":"ETH-USDT-SWAP"},"data":[{"asks":[["3126","2.05","0","1"]],"bids":[["3124.88","194.62","0","4"]],"ts":"1765631998067","seqId":1158519011}]}
{"arg":{"channel":"bbo-tbt","instId":"ETH-USDT-SWAP"},"data":[{"asks":[["3126","2.05","0","1"]],"bids":[["3124.88","194.27","0","4"]],"ts":"1765631998077","seqId":1158519015}]}
{"arg":{"channel":"books","instId":"ETH-USDT-SWAP"},"action":"update","data":[{"asks":[],"bids":[["3124.88","194.27","0","4"]],"ts":"1765631998107","checksum":816645270,"seqId":1158519015,"prevSeqId":1158518961}]}
{"arg":{"channel":"books5","instId":"ETH-USDT-SWAP"},"data":[{"asks":[["3126","2.05","0","1"],["3126.16","0.01","0","1"],["3126.32","20.15","0","2"],["3126.39","37.73","0","1"],["3126.43","0.02","0","1"]],"bids":[["3124.88","194.27","0","4"],["3124.87","0.78","0","5"],["3124.86","47.42","0","1"],["3124.85","31.43","0","6"],["3124.84","4.02","0","3"]],"instId":"ETH-USDT-SWAP","ts":"1765631998107","seqId":1158519015}]}
{"arg":{"channel":"bbo-tbt","instId":"ETH-USDT-SWAP"},"data":[{"asks":[["3126","2.05","0","1"]],"bids":[["3124.88","194","0","4"]],"ts":"1765631998127","seqId":1158519017}]}
{"arg":{"channel":"bbo-tbt","instId":"ETH-USDT-SWAP"},"data":[{"asks":[["3126","2.05","0","1"]],"bids":[["3124.88","193.52","0","4"]],"ts":"1765631998137","seqId":1158519019}]}
{"arg":{"channel":"bbo-tbt","instId":"ETH-USDT-SWAP"},"data":[{"asks":[["3126","2.05","0","1"]],"bids":[["3124.88","191.77","0","4"]],"ts":"1765631998207","seqId":1158519021}]}
{"arg":{"channel":"books","instId":"ETH-USDT-SWAP"},"action":"update","data":[{"asks":[],"bids":[["3124.88","191.77","0","4"]],"ts":"1765631998207","checksum":1008122844,"seqId":1158519021,"prevSeqId":1158519015}]}
{"arg":{"channel":"books5","instId":"ETH-USDT-SWAP"},"data":[{"asks":[["3126","2.05","0","1"],["3126.16","0.01","0","1"],["3126.32","20.15","0","2"],["3126.39","37.73","0","1"],["3126.43","0.02","0","1"]],"bids":[["3124.88","191.77","0","4"],["3124.87","0.78","0","5"],["3124.86","47.42","0","1"],["3124.85","31.43","0","6"],["3124.84","4.02","0","3"]],"instId":"ETH-USDT-SWAP","ts":"1765631998207","seqId":1158519021}]}
{"arg":{"channel":"bbo-tbt","instId":"ETH-USDT-SWAP"},"data":[{"asks":[["3126","1.81","0","1"]],"bids":[["3124.88","191.77","0","4"]],"ts":"1765631998227","seqId":1158519023}]}
{"arg":{"channel":"tickers","instId":"ETH-USDT-SWAP"},"data":[{"instType":"SWAP","instId":"ETH-USDT-SWAP","last":"3124.88","lastSz":"0.27","askPx":"3126","askSz":"2.05","bidPx":"3124.88","bidSz":"194","open24h":"3248.4","high24h":"3315.64","low24h":"3072.11","sodUtc0":"3108.41","sodUtc8":"3174.4","volCcy24h":"19462845.804","vol24h":"194628458.04","ts":"1765631998127"}]}
{"arg":{"channel":"bbo-tbt","instId":"ETH-USDT-SWAP"},"data":[{"asks":[["3126","1.81","0","1"]],"bids":[["3124.88","191.62","0","4"]],"ts":"1765631998237","seqId":1158519025}]}
{"arg":{"channel":"bbo-tbt","instId":"ETH-USDT-SWAP"},"data":[{"asks":[["3126","1.74","0","1"]],"bids":[["3124.88","191.62","0","4"]],"ts":"1765631998267","seqId":1158519027}]}
{"arg":{"channel":"books","instId":"ETH-USDT-SWAP"},"action":"update","data":[{"asks":[["3126","1.74","0","1"]],"bids":[["3124.88","191.62","0","4"]],"ts":"1765631998307","checksum":-1025433687,"seqId":1158519027,"prevSeqId":1158519021}]}
{"arg":{"channel":"books5","instId":"ETH-USDT-SWAP"},"data":[{"asks":[["3126","1.74","0","1"],["3126.16","0.01","0","1"],["3126.32","20.15","0","2"],["3126.39","37.73","0","1"],["3126.43","0.02","0","1"]],"bids":[["3124.88","191.62","0","4"],["3124.87","0.78","0","5"],["3124.86","47.42","0","1"],["3124.85","31.43","0","6"],["3124.84","4.02","0","3"]],"instId":"ETH-USDT-SWAP","ts":"1765631998307","seqId":1158519027}]}
{"arg":{"channel":"tickers","instId":"ETH-USDT-SWAP"},"data":[{"instType":"SWAP","instId":"ETH-USDT-SWAP","last":"3124.88","lastSz":"0.15","askPx":"3126","askSz":"1.81","bidPx":"3124.88","bidSz":"191.62","open24h":"3248.4","high24h":"3315.64","low24h":"3072.11","sodUtc0":"3108.41","sodUtc8":"3174.4","volCcy24h":"19462846.066","vol24h":"194628460.66","ts":"1765631998239"}]}
{"arg":{"channel":"bbo-tbt","instId":"ETH-USDT-SWAP"},"data":[{"asks":[["3126","1.74","0","1"]],"bids":[["3124.88","191.09","0","4"]],"ts":"1765631998387","seqId":1158519081}]}
{"arg":{"channel":"bbo-tbt","instId":"ETH-USDT-SWAP"},"data":[{"asks":[["3126","1.37","0","1"]],"bids":[["3124.88","191.09","0","4"]],"ts":"1765631998397","seqId":1158519083}]}
{"arg":{"channel":"books","instId":"ETH-USDT-SWAP"},"action":"update","data":[{"asks":[["3126","1.37","0","1"]],"bids":[["3124.88","191.09","0","4"]],"ts":"1765631998407","checksum":-580056797,"seqId":1158519083,"prevSeqId":1158519027}]}
{"arg":{"channel":"books5","instId":"ETH-USDT-SWAP"},"data":[{"asks":[["3126","1.37","0","1"],["3126.16","0.01","0","1"],["3126.32","20.15","0","2"],["3126.39","37.73","0","1"],["3126.43","0.02","0","1"]],"bids":[["3124.88","191.09","0","4"],["3124.87","0.78","0","5"],["3124.86","47.42","0","1"],["3124.85","31.43","0","6"],["3124.84","4.02","0","3"]],"instId":"ETH-USDT-SWAP","ts":"1765631998407","seqId":1158519083}]}
{"arg":{"channel":"bbo-tbt","instId":"ETH-USDT-SWAP"},"data":[{"asks":[["3126","1.37","0","1"]],"bids":[["3124.88","190.97","0","4"]],"ts":"1765631998417","seqId":1158519085}]}
{"arg":{"channel":"tickers","instId":"ETH-USDT-SWAP"},"data":[{"instType":"SWAP","instId":"ETH-USDT-SWAP","last":"3126","lastSz":"0.07","askPx":"3126","askSz":"1.74","bidPx":"3124.88","bidSz":"191.62","open24h":"3248.4","high24h":"3315.64","low24h":"3072.11","sodUtc0":"3108.41","sodUtc8":"3174.4","volCcy24h":"19462846.073","vol24h":"194628460.73","ts":"1765631998365"}]}
{"arg":{"channel":"bbo-tbt","instId":"ETH-USDT-SWAP"},"data":[{"asks":[["3126","1.29","0","1"]],"bids":[["3124.88","190.49","0","4"]],"ts":"1765631998497","seqId":1158519089}]}
{"arg":{"channel":"bbo-tbt","instId":"ETH-USDT-SWAP"},"data":[{"asks":[["3126","1.29","0","1"]],"bids":[["3124.88","190.37","0","4"]],"ts":"1765631998507","seqId":1158519091}]}
{"arg":{"channel":"books","instId":"ETH-USDT-SWAP"},"action":"update","data":[{"asks":[["3126","1.29","0","1"]],"bids":[["3124.88","190.37","0","4"]],"ts":"1765631998507","checksum":-953877602,"seqId":1158519091,"prevSeqId":1158519083}]}
{"arg":{"channel":"books5","instId":"ETH-USDT-SWAP"},"data":[{"asks":[["3126","1.29","0","1"],["3126.16","0.01","0","1"],["3126.32","20.15","0","2"],["3126.39","37.73","0","1"],["3126.43","0.02","0","1"]],"bids":[["3124.88","190.37","0","4"],["3124.87","0.78","0","5"],["3124.86","47.42","0","1"],["3124.85","31.43","0","6"],["3124.84","4.02","0","3"]],"instId":"ETH-USDT-SWAP","ts":"1765631998507","seqId":1158519091}]}
{"arg":{"channel":"bbo-tbt","instId":"ETH-USDT-SWAP"},"data":[{"asks":[["3126","1.29","0","1"]],"bids":[["3124.88","190.28","0","4"]],"ts":"1765631998517","seqId":1158519095}]}
{"arg":{"channel":"bbo-tbt","instId":"ETH-USDT-SWAP"},"data":[{"asks":[["3126","1.05","0","1"]],"bids":[["3124.88","190.28","0","4"]],"ts":"1765631998567","seqId":1158519097}]}
{"arg":{"channel":"tickers","instId":"ETH-USDT-SWAP"},"data":[{"instType":"SWAP","instId":"ETH-USDT-SWAP","last":"3124.88","lastSz":"0.12","askPx":"3126","askSz":"1.37","bidPx":"3124.88","bidSz":"190.97","open24h":"3248.4","high24h":"3315.64","low24h":"3072.11","sodUtc0":"3108.41","sodUtc8":"3174.4","volCcy24h":"19462846.175","vol24h":"194628461.75","ts":"1765631998472"}]}
{"arg":{"channel":"bbo-tbt","instId":"ETH-USDT-SWAP"},"data":[{"asks":[["3126","0.99","0","1"]],"bids":[["3124.88","189.06","0","4"]],"ts":"1765631998607","seqId":1158519101}]}
{"arg":{"channel":"books","instId":"ETH-USDT-SWAP"},"action":"update","data":[{"asks":[["3126","0.99","0","1"]],"bids":[["3124.88","189.06","0","4"]],"ts":"1765631998607","checksum":1953232165,"seqId":1158519101,"prevSeqId":1158519091}]}
{"arg":{"channel":"books5","instId":"ETH-USDT-SWAP"},"data":[{"asks":[["3126","0.99","0","1"],["3126.16","0.01","0","1"],["3126.32","20.15","0","2"],["3126.39","37.73","0","1"],["3126.43","0.02","0","1"]],"bids":[["3124.88","189.06","0","4"],["3124.87","0.78","0","5"],["3124.86","47.42","0","1"],["3124.85","31.43","0","6"],["3124.84","4.02","0","3"]],"instId":"ETH-USDT-SWAP","ts":"1765631998607","seqId":1158519101}]}
{"arg":{"channel":"tickers","instId":"ETH-USDT-SWAP"},"data":[{"instType":"SWAP","instId":"ETH-USDT-SWAP","last":"3126","lastSz":"0.06","askPx":"3126","askSz":"0.99","bidPx":"3124.88","bidSz":"190.28","open24h":"3248.4","high24h":"3315.64","low24h":"3072.11","sodUtc0":"3108.41","sodUtc8":"3174.4","volCcy24h":"19462846.282","vol24h":"194628462.82","ts":"1765631998602"}]}
{"arg":{"channel":"bbo-tbt","instId":"ETH-USDT-SWAP"},"data":[{"asks":[["3126","0.76","0","1"]],"bids":[["3124.88","189.06","0","4"]],"ts":"1765631998677","seqId":1158519103}]}
{"arg":{"channel":"books","instId":"ETH-USDT-SWAP"},"action":"update","data":[{"asks":[["3126","0.76","0","1"]],"bids":[],"ts":"1765631998707","checksum":-1965883486,"seqId":1158519103,"prevSeqId":1158519101}]}
{"arg":{"channel":"books5","instId":"ETH-USDT-SWAP"},"data":[{"asks":[["3126","0.76","0","1"],["3126.16","0.01","0","1"],["3126.32","20.15","0","2"],["3126.39","37.73","0","1"],["3126.43","0.02","0","1"]],"bids":[["3124.88","189.06","0","4"],["3124.87","0.78","0","5"],["3124.86","47.42","0","1"],["3124.85","31.43","0","6"],["3124.84","4.02","0","3"]],"instId":"ETH-USDT-SWAP","ts":"1765631998707","seqId":1158519103}]}
{"arg":{"channel":"bbo-tbt","instId":"ETH-USDT-SWAP"},"data":[{"asks":[["3126","0.56","0","1"]],"bids":[["3124.88","189.06","0","4"]],"ts":"1765631998747","seqId":1158519107}]}
{"arg":{"channel":"tickers","instId":"ETH-USDT-SWAP"},"data":[{"instType":"SWAP","instId":"ETH-USDT-SWAP","last":"3126","lastSz":"0.23","askPx":"3126","askSz":"0.76","bidPx":"3124.88","bidSz":"189.06","open24h":"3248.4","high24h":"3315.64","low24h":"3072.11","sodUtc0":"3108.41","sodUtc8":"3174.4","volCcy24h":"19462846.427","vol24h":"194628464.27","ts":"1765631998711"}]}
{"arg":{"channel":"books","instId":"ETH-USDT-SWAP"},"action":"update","data":[{"asks":[["3126","0.56","0","1"]],"bids":[],"ts":"1765631998807","checksum":481173267,"seqId":1158519107,"prevSeqId":1158519103}]}
{"arg":{"channel":"books5","instId":"ETH-USDT-SWAP"},"data":[{"asks":[["3126","0.56","0","1"],["3126.16","0.01","0","1"],["3126.32","20.15","0","2"],["3126.39","37.73","0","1"],["3126.43","0.02","0","1"]],"bids":[["3124.88","189.06","0","4"],["3124.87","0.78","0","5"],["3124.86","47.42","0","1"],["3124.85","31.43","0","6"],["3124.84","4.02","0","3"]],"instId":"ETH-USDT-SWAP","ts":"1765631998807","seqId":1158519107}]}
{"arg":{"channel":"bbo-tbt","instId":"ETH-USDT-SWAP"},"data":[{"asks":[["3126","0.56","0","1"]],"bids":[["3124.88","188.94","0","4"]],"ts":"1765631998867","seqId":1158519163}]}
{"arg":{"channel":"bbo-tbt","instId":"ETH-USDT-SWAP"},"data":[{"asks":[["3126","0.56","0","1"]],"bids":[["3124.88","188.85","0","4"]],"ts":"1765631998897","seqId":1158519165}]}
{"arg":{"channel":"books","instId":"ETH-USDT-SWAP"},"action":"update","data":[{"asks":[],"bids":[["3124.88","188.85","0","4"]],"ts":"1765631998907","checksum":-1008856479,"seqId":1158519165,"prevSeqId":1158519107}]}
{"arg":{"channel":"books5","instId":"ETH-USDT-SWAP"},"data":[{"asks":[["3126","0.56","0","1"],["3126.16","0.01","0","1"],["3126.32","20.15","0","2"],["3126.39","37.73","0","1"],["3126.43","0.02","0","1"]],"bids":[["3124.88","188.85","0","4"],["3124.87","0.78","0","5"],["3124.86","47.42","0","1"],["3124.85","31.43","0","6"],["3124.84","4.02","0","3"]],"instId":"ETH-USDT-SWAP","ts":"1765631998907","seqId":1158519165}]}
{"arg":{"channel":"tickers","instId":"ETH-USDT-SWAP"},"data":[{"instType":"SWAP","instId":"ETH-USDT-SWAP","last":"3124.88","lastSz":"0.12","askPx":"3126","askSz":"0.56","bidPx":"3124.88","bidSz":"188.94","open24h":"3248.4","high24h":"3315.64","low24h":"3072.11","sodUtc0":"3108.41","sodUtc8":"3174.4","volCcy24h":"19462846.459","vol24h":"194628464.59","ts":"1765631998863"}]}
{"arg":{"channel":"bbo-tbt","instId":"ETH-USDT-SWAP"},"data":[{"asks":[["3126","0.56","0","1"]],"bids":[["3124.88","188.74","0","4"]],"ts":"1765631998927","seqId":1158519167}]}
{"arg":{"channel":"bbo-tbt","instId":"ETH-USDT-SWAP"},"data":[{"asks":[["3126","0.05","0","1"]],"bids":[["3124.88","188.66","0","4"]],"ts":"1765631998987","seqId":1158519171}]}
{"arg":{"channel":"bbo-tbt","instId":"ETH-USDT-SWAP"},"data":[{"asks":[["3126","0.05","0","1"]],"bids":[["3124.88","188.58","0","4"]],"ts":"1765631998997","seqId":1158519173}]}
{"arg":{"channel":"bbo-tbt","instId":"ETH-USDT-SWAP"},"data":[{"asks":[["3126.32","20.15","0","2"]],"bids":[["3125","3.2","0","1"]],"ts":"1765631999007","seqId":1158519183}]}
{"arg":{"channel":"books","instId":"ETH-USDT-SWAP"},"action":"update","data":[{"asks":[["3126","0","0","0"],["3126.16","0","0","0"],["3132.11","0.11","0","1"],["3132.13","359.73","0","7"]],"bids":[["3125","3.2","0","1"],["3124.9","0.01","0","1"],["3124.88","188.58","0","4"],["3120.52","0","0","0"],["3120.51","0","0","0"]],"ts":"1765631999007","checksum":562954241,"seqId":1158519183,"prevSeqId":1158519165}]}
{"arg":{"channel":"books5","instId":"ETH-USDT-SWAP"},"data":[{"asks":[["3126.32","20.15","0","2"],["3126.39","37.73","0","1"],["3126.43","0.02","0","1"],["3126.5","0.07","0","4"],["3126.53","0.09","0","1"]],"bids":[["3125","3.2","0","1"],["3124.9","0.01","0","1"],["3124.88","188.58","0","4"],["3124.87","0.78","0","5"],["3124.86","47.42","0","1"]],"instId":"ETH-USDT-SWAP","ts":"1765631999007","seqId":1158519183}]}
{"arg":{"channel":"tickers","instId":"ETH-USDT-SWAP"},"data":[{"instType":"SWAP","instId":"ETH-USDT-SWAP","last":"3124.88","lastSz":"0.08","askPx":"3126","askSz":"0.56","bidPx":"3124.88","bidSz":"188.66","open24h":"3248.4","high24h":"3315.64","low24h":"3072.11","sodUtc0":"3108.41","sodUtc8":"3174.4","volCcy24h":"19462846.487","vol24h":"194628464.87","ts":"1765631998982"}]}
{"arg":{"channel":"bbo-tbt","instId":"ETH-USDT-SWAP"},"data":[{"asks":[["3126.32","20.15","0","2"]],"bids":[["3125","2.54","0","1"]],"ts":"1765631999087","seqId":1158519213}]}
{"arg":{"channel":"books","instId":"ETH-USDT-SWAP"},"action":"update","data":[{"asks":[],"bids":[["3125","2.54","0","1"]],"ts":"1765631999107","checksum":843190834,"seqId":1158519235,"prevSeqId":1158519183}]}
{"arg":{"channel":"books5","instId":"ETH-USDT-SWAP"},"data":[{"asks":[["3126.32","20.15","0","2"],["3126.39","37.73","0","1"],["3126.43","0.02","0","1"],["3126.5","0.07","0","4"],["3126.53","0.09","0","1"]],"bids":[["3125","2.54","0","1"],["3124.9","0.01","0","1"],["3124.88","188.58","0","4"],["3124.87","0.78","0","5"],["3124.86","47.42","0","1"]],"instId":"ETH-USDT-SWAP","ts":"1765631999107","seqId":1158519235}]}
{"arg":{"channel":"bbo-tbt","instId":"ETH-USDT-SWAP"},"data":[{"asks":[["3126.32","20.15","0","2"]],"bids":[["3125","2.42","0","1"]],"ts":"1765631999117","seqId":1158519237}]}
{"arg":{"channel":"tickers","instId":"ETH-USDT-SWAP"},"data":[{"instType":"SWAP","instId":"ETH-USDT-SWAP","last":"3125","lastSz":"0.66","askPx":"3126.32","askSz":"20.15","bidPx":"3125","bidSz":"2.54","open24h":"3248.4","high24h":"3315.64","low24h":"3072.11","sodUtc0":"3108.41","sodUtc8":"3174.4","volCcy24h":"19462846.618","vol24h":"194628466.18","ts":"1765631999085"}]}
{"arg":{"channel":"bbo-tbt","instId":"ETH-USDT-SWAP"},"data":[{"asks":[["3126.32","20.15","0","2"]],"bids":[["3125","2.2","0","1"]],"ts":"1765631999187","seqId":1158519239}]}
{"arg":{"channel":"books","instId":"ETH-USDT-SWAP"},"action":"update","data":[{"asks":[],"bids":[["3125","2.2","0","1"]],"ts":"1765631999207","checksum":1784841316,"seqId":1158519239,"prevSeqId":1158519235}]}
{"arg":{"channel":"books5","instId":"ETH-USDT-SWAP"},"data":[{"asks":[["3126.32","20.15","0","2"],["3126.39","37.73","0","1"],["3126.43","0.02","0","1"],["3126.5","0.07","0","4"],["3126.53","0.09","0","1"]],"bids":[["3125","2.2","0","1"],["3124.9","0.01","0","1"],["3124.88","188.58","0","4"],["3124.87","0.78","0","5"],["3124.86","47.42","0","1"]],"instId":"ETH-USDT-SWAP","ts":"1765631999207","seqId":1158519239}]}
{"arg":{"channel":"tickers","instId":"ETH-USDT-SWAP"},"data":[{"instType":"SWAP","instId":"ETH-USDT-SWAP","last":"3125","lastSz":"0.22","askPx":"3126.32","askSz":"20.15","bidPx":"3125","bidSz":"2.2","open24h":"3248.4","high24h":"3315.64","low24h":"3072.11","sodUtc0":"3108.41","sodUtc8":"3174.4","volCcy24h":"19462846.652","vol24h":"194628466.52","ts":"1765631999186"}]}
{"arg":{"channel":"bbo-tbt","instId":"ETH-USDT-SWAP"},"data":[{"asks":[["3126.32","20.15","0","2"]],"bids":[["3125","2.07","0","1"]],"ts":"1765631999247","seqId":1158519241}]}
{"arg":{"channel":"books","instId":"ETH-USDT-SWAP"},"action":"update","data":[{"asks":[],"bids":[["3125","2.07","0","1"]],"ts":"1765631999307","checksum":802916489,"seqId":1158519241,"prevSeqId":1158519239}]}
{"arg":{"channel":"books5","instId":"ETH-USDT-SWAP"},"data":[{"asks":[["3126.32","20.15","0","2"],["3126.39","37.73","0","1"],["3126.43","0.02","0","1"],["3126.5","0.07","0","4"],["3126.53","0.09","0","1"]],"bids":[["3125","2.07","0","1"],["3124.9","0.01","0","1"],["3124.88","188.58","0","4"],["3124.87","0.78","0","5"],["3124.86","47.42","0","1"]],"instId":"ETH-USDT-SWAP","ts":"1765631999307","seqId":1158519241}]}
{"arg":{"channel":"bbo-tbt","instId":"ETH-USDT-SWAP"},"data":[{"asks":[["3126.32","20.15","0","2"]],"bids":[["3125","1.92","0","1"]],"ts":"1765631999317","seqId":1158519243}]}
{"arg":{"channel":"bbo-tbt","instId":"ETH-USDT-SWAP"},"data":[{"asks":[["3126.32","20.15","0","2"]],"bids":[["3125","1.84","0","1"]],"ts":"1765631999337","seqId":1158519245}]}
{"arg":{"channel":"tickers","instId":"ETH-USDT-SWAP"},"data":[{"instType":"SWAP","instId":"ETH-USDT-SWAP","last":"3125","lastSz":"0.13","askPx":"3126.32","askSz":"20.15","bidPx":"3125","bidSz":"2.07","open24h":"3248.4","high24h":"3315.64","low24h":"3072.11","sodUtc0":"3108.41","sodUtc8":"3174.4","volCcy24h":"19462846.665","vol24h":"194628466.65","ts":"1765631999297"}]}
{"arg":{"channel":"bbo-tbt","instId":"ETH-USDT-SWAP"},"data":[{"asks":[["3126.32","20.15","0","2"]],"bids":[["3125","1.63","0","1"]],"ts":"1765631999347","seqId":1158519249}]}
{"arg":{"channel":"books","instId":"ETH-USDT-SWAP"},"action":"update","data":[{"asks":[],"bids":[["3125","1.63","0","1"]],"ts":"1765631999407","checksum":1613205759,"seqId":1158519329,"prevSeqId":1158519241}]}
{"arg":{"channel":"books5","instId":"ETH-USDT-SWAP"},"data":[{"asks":[["3126.32","20.15","0","2"],["3126.39","37.73","0","1"],["3126.43","0.02","0","1"],["3126.5","0.07","0","4"],["3126.53","0.09","0","1"]],"bids":[["3125","1.63","0","1"],["3124.9","0.01","0","1"],["3124.88","188.58","0","4"],["3124.87","0.78","0","5"],["3124.86","47.42","0","1"]],"instId":"ETH-USDT-SWAP","ts":"1765631999407","seqId":1158519329}]}
{"arg":{"channel":"tickers","instId":"ETH-USDT-SWAP"},"data":[{"instType":"SWAP","instId":"ETH-USDT-SWAP","last":"3125","lastSz":"0.13","askPx":"3126.32","askSz":"20.15","bidPx":"3125","bidSz":"1.63","open24h":"3248.4","high24h":"3315.64","low24h":"3072.11","sodUtc0":"3108.41","sodUtc8":"3174.4","volCcy24h":"19462846.709","vol24h":"194628467.09","ts":"1765631999403"}]}
{"arg":{"channel":"bbo-tbt","instId":"ETH-USDT-SWAP"},"data":[{"asks":[["3126.32","19.78","0","1"]],"bids":[["3125","2.1","0","2"]],"ts":"1765631999477","seqId":1158519336}]}
{"arg":{"channel":"books","instId":"ETH-USDT-SWAP"},"action":"update","data":[{"asks":[["3126.32","19.78","0","1"]],"bids":[["3125","2.1","0","2"]],"ts":"1765631999507","checksum":-99504862,"seqId":1158519336,"prevSeqId":1158519329}]}
{"arg":{"channel":"books5","instId":"ETH-USDT-SWAP"},"data":[{"asks":[["3126.32","19.78","0","1"],["3126.39","37.73","0","1"],["3126.43","0.02","0","1"],["3126.5","0.07","0","4"],["3126.53","0.09","0","1"]],"bids":[["3125","2.1","0","2"],["3124.9","0.01","0","1"],["3124.88","188.58","0","4"],["3124.87","0.78","0","5"],["3124.86","47.42","0","1"]],"instId":"ETH-USDT-SWAP","ts":"1765631999507","seqId":1158519336}]}
{"arg":{"channel":"bbo-tbt","instId":"ETH-USDT-SWAP"},"data":[{"asks":[["3126.32","19.78","0","1"]],"bids":[["3125","1.98","0","2"]],"ts":"1765631999557","seqId":1158519348}]}
{"arg":{"channel":"tickers","instId":"ETH-USDT-SWAP"},"data":[{"instType":"SWAP","instId":"ETH-USDT-SWAP","last":"3126.32","lastSz":"0.22","askPx":"3126.32","askSz":"19.78","bidPx":"3125","bidSz":"2.1","open24h":"3248.4","high24h":"3315.64","low24h":"3072.11","sodUtc0":"3108.41","sodUtc8":"3174.4","volCcy24h":"19462846.746","vol24h":"194628467.46","ts":"1765631999510"}]}
{"arg":{"channel":"bbo-tbt","instId":"ETH-USDT-SWAP"},"data":[{"asks":[["3126.32","19.78","0","1"]],"bids":[["3125","1.86","0","2"]],"ts":"1765631999607","seqId":1158519367}]}
{"arg":{"channel":"books","instId":"ETH-USDT-SWAP"},"action":"update","data":[{"asks":[],"bids":[["3125","1.86","0","2"]],"ts":"1765631999607","checksum":-591066919,"seqId":1158519367,"prevSeqId":1158519336}]}
{"arg":{"channel":"books5","instId":"ETH-USDT-SWAP"},"data":[{"asks":[["3126.32","19.78","0","1"],["3126.39","37.73","0","1"],["3126.43","0.02","0","1"],["3126.5","0.07","0","4"],["3126.53","0.09","0","1"]],"bids":[["3125","1.86","0","2"],["3124.9","0.01","0","1"],["3124.88","188.58","0","4"],["3124.87","0.78","0","5"],["3124.86","47.42","0","1"]],"instId":"ETH-USDT-SWAP","ts":"1765631999607","seqId":1158519367}]}
{"arg":{"channel":"bbo-tbt","instId":"ETH-USDT-SWAP"},"data":[{"asks":[["3126.32","19.78","0","1"]],"bids":[["3125","1.33","0","2"]],"ts":"1765631999647","seqId":1158519386}]}
{"arg":{"channel":"bbo-tbt","instId":"ETH-USDT-SWAP"},"data":[{"asks":[["3126.32","19.54","0","1"]],"bids":[["3125","1.33","0","2"]],"ts":"1765631999667","seqId":1158519388}]}
{"arg":{"channel":"tickers","instId":"ETH-USDT-SWAP"},"data":[{"instType":"SWAP","instId":"ETH-USDT-SWAP","last":"3125","lastSz":"0.12","askPx":"3126.32","askSz":"19.78","bidPx":"3125","bidSz":"1.86","open24h":"3248.4","high24h":"3315.64","low24h":"3072.11","sodUtc0":"3108.41","sodUtc8":"3174.4","volCcy24h":"19462846.77","vol24h":"194628467.7","ts":"1765631999628"}]}
{"arg":{"channel":"bbo-tbt","instId":"ETH-USDT-SWAP"},"data":[{"asks":[["3126.32","19.48","0","1"]],"bids":[["3125","1.05","0","2"]],"ts":"1765631999677","seqId":1158519394}]}
{"arg":{"channel":"bbo-tbt","instId":"ETH-USDT-SWAP"},"data":[{"asks":[["3126.32","19.48","0","1"]],"bids":[["3124.88","188.42","0","4"]],"ts":"1765631999707","seqId":1158519402}]}
{"arg":{"channel":"books","instId":"ETH-USDT-SWAP"},"action":"update","data":[{"asks":[["3126.32","19.48","0","1"]],"bids":[["3125","0","0","0"],["3124.9","0","0","0"],["3124.88","188.42","0","4"],["3120.52","12.05","0","2"],["3120.51","0.11","0","5"]],"ts":"1765631999707","checksum":805634865,"seqId":1158519402,"prevSeqId":1158519367}]}
{"arg":{"channel":"books5","instId":"ETH-USDT-SWAP"},"data":[{"asks":[["3126.32","19.48","0","1"],["3126.39","37.73","0","1"],["3126.43","0.02","0","1"],["3126.5","0.07","0","4"],["3126.53","0.09","0","1"]],"bids":[["3124.88","188.42","0","4"],["3124.87","0.78","0","5"],["3124.86","47.42","0","1"],["3124.85","31.43","0","6"],["3124.84","4.02","0","3"]],"instId":"ETH-USDT-SWAP","ts":"1765631999707","seqId":1158519402}]}
{"arg":{"channel":"bbo-tbt","instId":"ETH-USDT-SWAP"},"data":[{"asks":[["3126","3.2","0","1"]],"bids":[["3124.88","188.42","0","4"]],"ts":"1765631999717","seqId":1158519407}]}
{"arg":{"channel":"bbo-tbt","instId":"ETH-USDT-SWAP"},"data":[{"asks":[["3126","3.2","0","1"]],"bids":[["3124.88","188.29","0","4"]],"ts":"1765631999787","seqId":1158519409}]}
{"arg":{"channel":"bbo-tbt","instId":"ETH-USDT-SWAP"},"data":[{"asks":[["3126","3.1","0","1"]],"bids":[["3124.88","188.29","0","4"]],"ts":"1765631999807","seqId":1158519411}]}
{"arg":{"channel":"books","instId":"ETH-USDT-SWAP"},"action":"update","data":[{"asks":[["3126","3.1","0","1"],["3126.16","0.01","0","1"],["3126.32","19.95","0","2"],["3132.11","0","0","0"],["3132.13","0","0","0"]],"bids":[["3124.88","188.29","0","4"]],"ts":"1765631999807","checksum":-1529189573,"seqId":1158519411,"prevSeqId":1158519402}]}
{"arg":{"channel":"books5","instId":"ETH-USDT-SWAP"},"data":[{"asks":[["3126","3.1","0","1"],["3126.16","0.01","0","1"],["3126.32","19.95","0","2"],["3126.39","37.73","0","1"],["3126.43","0.02","0","1"]],"bids":[["3124.88","188.29","0","4"],["3124.87","0.78","0","5"],["3124.86","47.42","0","1"],["3124.85","31.43","0","6"],["3124.84","4.02","0","3"]],"instId":"ETH-USDT-SWAP","ts":"1765631999807","seqId":1158519411}]}
{"arg":{"channel":"tickers","instId":"ETH-USDT-SWAP"},"data":[{"instType":"SWAP","instId":"ETH-USDT-SWAP","last":"3124.88","lastSz":"0.16","askPx":"3126.32","askSz":"19.48","bidPx":"3124.88","bidSz":"188.42","open24h":"3248.4","high24h":"3315.64","low24h":"3072.11","sodUtc0":"3108.41","sodUtc8":"3174.4","volCcy24h":"19462847.003","vol24h":"194628470.03","ts":"1765631999765"}]}
{"arg":{"channel":"bbo-tbt","instId":"ETH-USDT-SWAP"},"data":[{"asks":[["3126","3.1","0","1"]],"bids":[["3124.86","12.98","0","1"]],"ts":"1765631999837","seqId":1158519455}]}
{"arg":{"channel":"bbo-tbt","instId":"ETH-USDT-SWAP"},"data":[{"asks":[["3126","3.1","0","1"]],"bids":[["3124.86","11.23","0","1"]],"ts":"1765631999887","seqId":1158519457}]}
{"arg":{"channel":"books","instId":"ETH-USDT-SWAP"},"action":"update","data":[{"asks":[["3126.13","0.04","0","1"],["3126.31","0.02","0","1"],["3126.95","117.5","0","2"],["3127.93","36.78","0","2"],["3128","344.45","0","55"],["3128.02","1.55","0","3"],["3129.98","79.73","0","1"],["3132.07","0","0","0"],["3132.08","0","0","0"],["3132.1","0","0","0"]],"bids":[["3124.88","0","0","0"],["3124.87","0","0","0"],["3124.86","11.23","0","1"],["3120.5","53.99","0","12"],["3120.48","6.1","0","4"]],"ts":"1765631999907","checksum":86215207,"seqId":1158519457,"prevSeqId":1158519411}]}
{"arg":{"channel":"books5","instId":"ETH-USDT-SWAP"},"data":[{"asks":[["3126","3.1","0","1"],["3126.13","0.04","0","1"],["3126.16","0.01","0","1"],["3126.31","0.02","0","1"],["3126.32","19.95","0","2"]],"bids":[["3124.86","11.23","0","1"],["3124.85","31.43","0","6"],["3124.84","4.02","0","3"],["3124.83","16.04","0","7"],["3124.82","1.91","0","1"]],"instId":"ETH-USDT-SWAP","ts":"1765631999907","seqId":1158519457}]}
{"arg":{"channel":"bbo-tbt","instId":"ETH-USDT-SWAP"},"data":[{"asks":[["3126","3.1","0","1"]],"bids":[["3124.86","11.11","0","1"]],"ts":"1765631999937","seqId":1158519549}]}
{"arg":{"channel":"tickers","instId":"ETH-USDT-SWAP"},"data":[{"instType":"SWAP","instId":"ETH-USDT-SWAP","last":"3124.86","lastSz":"1.75","askPx":"3126","askSz":"3.1","bidPx":"3124.86","bidSz":"11.23","open24h":"3248.4","high24h":"3315.64","low24h":"3072.11","sodUtc0":"3108.41","sodUtc8":"3174.4","volCcy24h":"19462869.552","vol24h":"194628695.52","ts":"1765631999885"}]}
{"arg":{"channel":"bbo-tbt","instId":"ETH-USDT-SWAP"},"data":[{"asks":[["3126","3.02","0","1"]],"bids":[["3124.86","11.11","0","1"]],"ts":"1765631999947","seqId":1158519551}]}
{"arg":{"channel":"bbo-tbt","instId":"ETH-USDT-SWAP"},"data":[{"asks":[["3126","3.02","0","1"]],"bids":[["3124.86","11.02","0","1"]],"ts":"1765631999997","seqId":1158519651}]}
{"arg":{"channel":"bbo-tbt","instId":"ETH-USDT-SWAP"},"data":[{"asks":[["3126","3.02","0","1"]],"bids":[["3124.86","10.79","0","1"]],"ts":"1765632000007","seqId":1158519655}]}
{"arg":{"channel":"books","instId":"ETH-USDT-SWAP"},"action":"update","data":[{"asks":[["3126","3.02","0","1"]],"bids":[["3124.86","10.79","0","1"]],"ts":"1765632000007","checksum":-1748359661,"seqId":1158519655,"prevSeqId":1158519457}]}
{"arg":{"channel":"books5","instId":"ETH-USDT-SWAP"},"data":[{"asks":[["3126","3.02","0","1"],["3126.13","0.04","0","1"],["3126.16","0.01","0","1"],["3126.31","0.02","0","1"],["3126.32","19.95","0","2"]],"bids":[["3124.86","10.79","0","1"],["3124.85","31.43","0","6"],["3124.84","4.02","0","3"],["3124.83","16.04","0","7"],["3124.82","1.91","0","1"]],"instId":"ETH-USDT-SWAP","ts":"1765632000007","seqId":1158519655}]}
{"arg":{"channel":"bbo-tbt","instId":"ETH-USDT-SWAP"},"data":[{"asks":[["3126","3.02","0","1"]],"bids":[["3124.86","10.26","0","1"]],"ts":"1765632000027","seqId":1158519657}]}
{"arg":{"channel":"tickers","instId":"ETH-USDT-SWAP"},"data":[{"instType":"SWAP","instId":"ETH-USDT-SWAP","last":"3126","lastSz":"0.08","askPx":"3126","askSz":"3.02","bidPx":"3124.86","bidSz":"11.11","open24h":"3248.4","high24h":"3315.64","low24h":"3072.11","sodUtc0":"3108.41","sodUtc8":"3174.4","volCcy24h":"19462869.572","vol24h":"194628695.72","ts":"1765631999996"}]}
{"arg":{"channel":"bbo-tbt","instId":"ETH-USDT-SWAP"},"data":[{"asks":[["3126","2.96","0","1"]],"bids":[["3124.86","10.26","0","1"]],"ts":"1765632000107","seqId":1158519659}]}
{"arg":{"channel":"books","instId":"ETH-USDT-SWAP"},"action":"update","data":[{"asks":[["3126","2.96","0","1"]],"bids":[["3124.86","10.26","0","1"]],"ts":"1765632000107","checksum":61779461,"seqId":1158519659,"prevSeqId":1158519655}]}
{"arg":{"channel":"books5","instId":"ETH-USDT-SWAP"},"data":[{"asks":[["3126","2.96","0","1"],["3126.13","0.04","0","1"],["3126.16","0.01","0","1"],["3126.31","0.02","0","1"],["3126.32","19.95","0","2"]],"bids":[["3124.86","10.26","0","1"],["3124.85","31.43","0","6"],["3124.84","4.02","0","3"],["3124.83","16.04","0","7"],["3124.82","1.91","0","1"]],"instId":"ETH-USDT-SWAP","ts":"1765632000107","seqId":1158519659}]}
{"arg":{"channel":"tickers","instId":"ETH-USDT-SWAP"},"data":[{"instType":"SWAP","instId":"ETH-USDT-SWAP","last":"3126","lastSz":"0.06","askPx":"3126","askSz":"2.96","bidPx":"3124.86","bidSz":"10.26","open24h":"3248","high24h":"3315.64","low24h":"3072.11","sodUtc0":"3108.41","sodUtc8":"3174.4","volCcy24h":"19458797.662","vol24h":"194587976.62","ts":"1765632000108"}]}
{"arg":{"channel":"bbo-tbt","instId":"ETH-USDT-SWAP"},"data":[{"asks":[["3126","2.86","0","1"]],"bids":[["3124.86","10.26","0","1"]],"ts":"1765632000147","seqId":1158519661}]}
{"arg":{"channel":"bbo-tbt","instId":"ETH-USDT-SWAP"},"data":[{"asks":[["3126","2.79","0","1"]],"bids":[["3124.86","10.26","0","1"]],"ts":"1765632000157","seqId":1158519663}]}
{"arg":{"channel":"bbo-tbt","instId":"ETH-USDT-SWAP"},"data":[{"asks":[["3126","2.79","0","1"]],"bids":[["3124.86","9.04","0","1"]],"ts":"1765632000187","seqId":1158519675}]}
{"arg":{"channel":"bbo-tbt","instId":"ETH-USDT-SWAP"},"data":[{"asks":[["3126","2.79","0","1"]],"bids":[["3124.86","8.38","0","1"]],"ts":"1765632000207","seqId":1158519677}]}
{"arg":{"channel":"books","instId":"ETH-USDT-SWAP"},"action":"update","data":[{"asks":[["3126","2.79","0","1"]],"bids":[["3124.86","8.38","0","1"]],"ts":"1765632000207","checksum":821497529,"seqId":1158519677,"prevSeqId":1158519659}]}
{"arg":{"channel":"books5","instId":"ETH-USDT-SWAP"},"data":[{"asks":[["3126","2.79","0","1"],["3126.13","0.04","0","1"],["3126.16","0.01","0","1"],["3126.31","0.02","0","1"],["3126.32","19.95","0","2"]],"bids":[["3124.86","8.38","0","1"],["3124.85","31.43","0","6"],["3124.84","4.02","0","3"],["3124.83","16.04","0","7"],["3124.82","1.91","0","1"]],"instId":"ETH-USDT-SWAP","ts":"1765632000207","seqId":1158519677}]}
{"arg":{"channel":"tickers","instId":"ETH-USDT-SWAP"},"data":[{"instType":"SWAP","instId":"ETH-USDT-SWAP","last":"3124.86","lastSz":"0.66","askPx":"3126","askSz":"2.79","bidPx":"3124.86","bidSz":"8.38","open24h":"3248","high24h":"3315.64","low24h":"3072.11","sodUtc0":"3108.41","sodUtc8":"3174.4","volCcy24h":"19458797.867","vol24h":"194587978.67","ts":"1765632000210"}]}
{"arg":{"channel":"bbo-tbt","instId":"ETH-USDT-SWAP"},"data":[{"asks":[["3126","2.79","0","1"]],"bids":[["3124.86","8.29","0","1"]],"ts":"1765632000347","seqId":1158519753}]}
{"arg":{"channel":"bbo-tbt","instId":"ETH-USDT-SWAP"},"data":[{"asks":[["3126","2.79","0","1"]],"bids":[["3124.86","8.18","0","1"]],"ts":"1765632000357","seqId":1158519755}]}
{"arg":{"channel":"tickers","instId":"ETH-USDT-SWAP"},"data":[{"instType":"SWAP","instId":"ETH-USDT-SWAP","last":"3124.86","lastSz":"0.09","askPx":"3126","askSz":"2.79","bidPx":"3124.86","bidSz":"8.29","open24h":"3248","high24h":"3315.64","low24h":"3072.11","sodUtc0":"3108.41","sodUtc8":"3174.4","volCcy24h":"19458797.876","vol24h":"194587978.76","ts":"1765632000350"}]}
{"arg":{"channel":"bbo-tbt","instId":"ETH-USDT-SWAP"},"data":[{"asks":[["3126","2.79","0","1"]],"bids":[["3124.86","8.06","0","1"]],"ts":"1765632000377","seqId":1158519757}]}
{"arg":{"channel":"bbo-tbt","instId":"ETH-USDT-SWAP"},"data":[{"asks":[["3126","2.79","0","1"]],"bids":[["3124.86","7.75","0","1"]],"ts":"1765632000397","seqId":1158519759}]}
{"arg":{"channel":"books","instId":"ETH-USDT-SWAP"},"action":"update","data":[{"asks":[],"bids":[["3124.86","7.75","0","1"]],"ts":"1765632000407","checksum":-517085875,"seqId":1158519759,"prevSeqId":1158519677}]}
{"arg":{"channel":"books5","instId":"ETH-USDT-SWAP"},"data":[{"asks":[["3126","2.79","0","1"],["3126.13","0.04","0","1"],["3126.16","0.01","0","1"],["3126.31","0.02","0","1"],["3126.32","19.95","0","2"]],"bids":[["3124.86","7.75","0","1"],["3124.85","31.43","0","6"],["3124.84","4.02","0","3"],["3124.83","16.04","0","7"],["3124.82","1.91","0","1"]],"instId":"ETH-USDT-SWAP","ts":"1765632000407","seqId":1158519759}]}
{"arg":{"channel":"bbo-tbt","instId":"ETH-USDT-SWAP"},"data":[{"asks":[["3126","2.79","0","1"]],"bids":[["3124.86","7.67","0","1"]],"ts":"1765632000417","seqId":1158519761}]}
{"arg":{"channel":"bbo-tbt","instId":"ETH-USDT-SWAP"},"data":[{"asks":[["3126","2.79","0","1"]],"bids":[["3124.86","7.59","0","1"]],"ts":"1765632000437","seqId":1158519763}]}
{"arg":{"channel":"bbo-tbt","instId":"ETH-USDT-SWAP"},"data":[{"asks":[["3126","2.42","0","1"]],"bids":[["3124.86","7.59","0","1"]],"ts":"1765632000497","seqId":1158519765}]}
{"arg":{"channel":"books","instId":"ETH-USDT-SWAP"},"action":"update","data":[{"asks":[["3126","2.42","0","1"]],"bids":[["3124.86","7.59","0","1"]],"ts":"1765632000507","checksum":-1295735149,"seqId":1158519765,"prevSeqId":1158519759}]}
{"arg":{"channel":"books5","instId":"ETH-USDT-SWAP"},"data":[{"asks":[["3126","2.42","0","1"],["3126.13","0.04","0","1"],["3126.16","0.01","0","1"],["3126.31","0.02","0","1"],["3126.32","19.95","0","2"]],"bids":[["3124.86","7.59","0","1"],["3124.85","31.43","0","6"],["3124.84","4.02","0","3"],["3124.83","16.04","0","7"],["3124.82","1.91","0","1"]],"instId":"ETH-USDT-SWAP","ts":"1765632000507","seqId":1158519765}]}
{"arg":{"channel":"tickers","instId":"ETH-USDT-SWAP"},"data":[{"instType":"SWAP","instId":"ETH-USDT-SWAP","last":"3124.86","lastSz":"0.08","askPx":"3126","askSz":"2.79","bidPx":"3124.86","bidSz":"7.59","open24h":"3248","high24h":"3315.64","low24h":"3072.11","sodUtc0":"3108.41","sodUtc8":"3174.4","volCcy24h":"19458797.946","vol24h":"194587979.46","ts":"1765632000489"}]}
{"arg":{"channel":"tickers","instId":"ETH-USDT-SWAP"},"data":[{"instType":"SWAP","instId":"ETH-USDT-SWAP","last":"3126","lastSz":"0.37","askPx":"3126","askSz":"2.42","bidPx":"3124.86","bidSz":"7.59","open24h":"3248","high24h":"3315.64","low24h":"3072.11","sodUtc0":"3108.41","sodUtc8":"3174.4","volCcy24h":"19458797.983","vol24h":"194587979.83","ts":"1765632000610"}]}
{"arg":{"channel":"bbo-tbt","instId":"ETH-USDT-SWAP"},"data":[{"asks":[["3126","2.36","0","1"]],"bids":[["3124.86","7.59","0","1"]],"ts":"1765632000697","seqId":1158519801}]}
{"arg":{"channel":"books","instId":"ETH-USDT-SWAP"},"action":"update","data":[{"asks":[["3126","2.36","0","1"]],"bids":[],"ts":"1765632000707","checksum":897291775,"seqId":1158519801,"prevSeqId":1158519765}]}
{"arg":{"channel":"books5","instId":"ETH-USDT-SWAP"},"data":[{"asks":[["3126","2.36","0","1"],["3126.13","0.04","0","1"],["3126.16","0.01","0","1"],["3126.31","0.02","0","1"],["3126.32","19.95","0","2"]],"bids":[["3124.86","7.59","0","1"],["3124.85","31.43","0","6"],["3124.84","4.02","0","3"],["3124.83","16.04","0","7"],["3124.82","1.91","0","1"]],"instId":"ETH-USDT-SWAP","ts":"1765632000707","seqId":1158519801}]}
{"arg":{"channel":"bbo-tbt","instId":"ETH-USDT-SWAP"},"data":[{"asks":[["3126","2.36","0","1"]],"bids":[["3124.86","7.46","0","1"]],"ts":"1765632000747","seqId":1158519839}]}
{"arg":{"channel":"bbo-tbt","instId":"ETH-USDT-SWAP"},"data":[{"asks":[["3126","2.36","0","1"]],"bids":[["3124.86","7.31","0","1"]],"ts":"1765632000757","seqId":1158519841}]}
{"arg":{"channel":"books","instId":"ETH-USDT-SWAP"},"action":"update","data":[{"asks":[],"bids":[["3124.86","7.31","0","1"]],"ts":"1765632000807","checksum":-913692039,"seqId":1158519945,"prevSeqId":1158519801}]}
{"arg":{"channel":"books5","instId":"ETH-USDT-SWAP"},"data":[{"asks":[["3126","2.36","0","1"],["3126.13","0.04","0","1"],["3126.16","0.01","0","1"],["3126.31","0.02","0","1"],["3126.32","19.95","0","2"]],"bids":[["3124.86","7.31","0","1"],["3124.85","31.43","0","6"],["3124.84","4.02","0","3"],["3124.83","16.04","0","7"],["3124.82","1.91","0","1"]],"instId":"ETH-USDT-SWAP","ts":"1765632000807","seqId":1158519945}]}
{"arg":{"channel":"tickers","instId":"ETH-USDT-SWAP"},"data":[{"instType":"SWAP","instId":"ETH-USDT-SWAP","last":"3124.86","lastSz":"0.13","askPx":"3126","askSz":"2.36","bidPx":"3124.86","bidSz":"7.46","open24h":"3248","high24h":"3315.64","low24h":"3072.11","sodUtc0":"3108.41","sodUtc8":"3174.4","volCcy24h":"19458798.002","vol24h":"194587980.02","ts":"1765632000746"}]}
{"arg":{"channel":"bbo-tbt","instId":"ETH-USDT-SWAP"},"data":[{"asks":[["3126","2.26","0","1"]],"bids":[["3124.86","7.31","0","1"]],"ts":"1765632000847","seqId":1158519947}]}
{"arg":{"channel":"books","instId":"ETH-USDT-SWAP"},"action":"update","data":[{"asks":[["3126","2.26","0","1"]],"bids":[],"ts":"1765632000907","checksum":181984423,"seqId":1158519947,"prevSeqId":1158519945}]}
{"arg":{"channel":"books5","instId":"ETH-USDT-SWAP"},"data":[{"asks":[["3126","2.26","0","1"],["3126.13","0.04","0","1"],["3126.16","0.01","0","1"],["3126.31","0.02","0","1"],["3126.32","19.95","0","2"]],"bids":[["3124.86","7.31","0","1"],["3124.85","31.43","0","6"],["3124.84","4.02","0","3"],["3124.83","16.04","0","7"],["3124.82","1.91","0","1"]],"instId":"ETH-USDT-SWAP","ts":"1765632000907","seqId":1158519947}]}
{"arg":{"channel":"bbo-tbt","instId":"ETH-USDT-SWAP"},"data":[{"asks":[["3131.23","0.07","0","1"]],"bids":[["3124.86","7.31","0","1"]],"ts":"1765632000917","seqId":1158521947}]}
{"arg":{"channel":"bbo-tbt","instId":"ETH-USDT-SWAP"},"data":[{"asks":[["3131.23","0.07","0","1"]],"bids":[["3129.53","0.01","0","1"]],"ts":"1765632000927","seqId":1158523136}]}
{"arg":{"channel":"bbo-tbt","instId":"ETH-USDT-SWAP"},"data":[{"asks":[["3131.23","0.07","0","1"]],"bids":[["3129.57","11.11","0","1"]],"ts":"1765632000937","seqId":1158524073}]}
{"arg":{"channel":"tickers","instId":"ETH-USDT-SWAP"},"data":[{"instType":"SWAP","instId":"ETH-USDT-SWAP","last":"3126","lastSz":"0.1","askPx":"3126","askSz":"2.26","bidPx":"3124.86","bidSz":"7.31","open24h":"3248","high24h":"3315.64","low24h":"3072.11","sodUtc0":"3108.41","sodUtc8":"3174.4","volCcy24h":"19458798.027","vol24h":"194587980.27","ts":"1765632000850"}]}
{"arg":{"channel":"bbo-tbt","instId":"ETH-USDT-SWAP"},"data":[{"asks":[["3131","3.2","0","1"]],"bids":[["3129.94","0.01","0","1"]],"ts":"1765632000947","seqId":1158524276}]}
{"arg":{"channel":"bbo-tbt","instId":"ETH-USDT-SWAP"},"data":[{"asks":[["3131","2.96","0","1"]],"bids":[["3129.94","0.01","0","1"]],"ts":"1765632000987","seqId":1158524492}]}
{"arg":{"channel":"books","instId":"ETH-USDT-SWAP"},"action":"update","data":[{"asks":[["3126","0","0","0"],["3126.13","0","0","0"],["3126.16","0","0","0"],["3126.31","0","0","0"],["3126.32","0","0","0"],["3126.39","0","0","0"],["3126.43","0","0","0"],["3126.5","0","0","0"],["3126.53","0","0","0"],["3126.59","0","0","0"],["3126.67","0","0","0"],["3126.69","0","0","0"],["3126.7","0","0","0"],["3126.72","0","0","0"],["3126.73","0","0","0"],["3126.78","0","0","0"],["3126.8","0","0","0"],["3126.82","0","0","0"],["3126.87","0","0","0"],["3126.91","0","0","0"],["3126.92","0","0","0"],["3126.93","0","0","0"],["3126.94","0","0","0"],["3126.95","0","0","0"],["3127","0","0","0"],["3127.04","0","0","0"],["3127.1","0","0","0"],["3127.11","0","0","0"],["3127.17","0","0","0"],["3127.19","0","0","0"],["3127.2","0","0","0"],["3127.21","0","0","0"],["3127.22","0","0","0"],["3127.23","0","0","0"],["3127.24","0","0","0"],["3127.25","0","0","0"],["3127.27","0","0","0"],["3127.32","0","0","0"],["3127.33","0","0","0"],["3127.34","0","0","0"],["3127.39","0","0","0"],["3127.4","0","0","0"],["3127.42","0","0","0"],["3127.43","0","0","0"],["3127.45","0","0","0"],["3127.5","0","0","0"],["3127.51","0","0","0"],["3127.53","0","0","0"],["3127.58","0","0","0"],["3127.59","0","0","0"],["3127.6","0","0","0"],["3127.62","0","0","0"],["3127.63","0","0","0"],["3127.67","0","0","0"],["3127.68","0","0","0"],["3127.7","0","0","0"],["3127.72","0","0","0"],["3127.73","0","0","0"],["3127.75","0","0","0"],["3127.78","0","0","0"],["3127.79","0","0","0"],["3127.8","0","0","0"],["3127.81","0","0","0"],["3127.82","0","0","0"],["3127.85","0","0","0"],["3127.87","0","0","0"],["3127.89","0","0","0"],["3127.9","0","0","0"],["3127.93","0","0","0"],["3127.95","0","0","0"],["3127.96","0","0","0"],["3127.99","0","0","0"],["3128","0","0","0"],["3128.01","0","0","0"],["3128.02","0","0","0"],["3128.04","0","0","0"],["3128.05","0","0","0"],["3128.08","0","0","0"],["3128.1","0","0","0"],["3128.11","0","0","0"],["3128.13","0","0","0"],["3128.14","0","0","0"],["3128.15","0","0","0"],["3128.16","0","0","0"],["3128.17","0","0","0"],["3128.18","0","0","0"],["3128.2","0","0","0"],["3128.21","0","0","0"],["3128.22","0","0","0"],["3128.23","0","0","0"],["3128.24","0","0","0"],["3128.25","0","0","0"],["3128.27","0","0","0"],["3128.29","0","0","0"],["3128.3","0","0","0"],["3128.31","0","0","0"],["3128.32","0","0","0"],["3128.33","0","0","0"],["3128.34","0","0","0"],["3128.35","0","0","0"],["3128.36","0","0","0"],["3128.37","0","0","0"],["3128.38","0","0","0"],["3128.39","0","0","0"],["3128.4","0","0","0"],["3128.42","0","0","0"],["3128.43","0","0","0"],["3128.44","0","0","0"],["3128.47","0","0","0"],["3128.48","0","0","0"],["3128.5","0","0","0"],["3128.51","0","0","0"],["3128.53","0","0","0"],["3128.54","0","0","0"],["3128.55","0","0","0"],["3128.57","0","0","0"],["3128.58","0","0","0"],["3128.59","0","0","0"],["3128.6","0","0","0"],["3128.61","0","0","0"],["3128.62","0","0","0"],["3128.63","0","0","0"],["3128.65","0","0","0"],["3128.66","0","0","0"],["3128.67","0","0","0"],["3128.68","0","0","0"],["3128.69","0","0","0"],["3128.7","0","0","0"],["3128.71","0","0","0"],["3128.73","0","0","0"],["3128.75","0","0","0"],["3128.76","0","0","0"],["3128.79","0","0","0"],["3128.8","0","0","0"],["3128.81","0","0","0"],["3128.82","0","0","0"],["3128.83","0","0","0"],["3128.85","0","0","0"],["3128.86","0","0","0"],["3128.88","0","0","0"],["3128.89","0","0","0"],["3128.9","0","0","0"],["3128.94","0","0","0"],["3128.95","0","0","0"],["3128.97","0","0","0"],["3128.99","0","0","0"],["3129","0","0","0"],["3129.01","0","0","0"],["3129.02","0","0","0"],["3129.03","0","0","0"],["3129.04","0","0","0"],["3129.05","0","0","0"],["3129.06","0","0","0"],["3129.07","0","0","0"],["3129.09","0","0","0"],["3129.1","0","0","0"],["3129.11","0","0","0"],["3129.12","0","0","0"],["3129.13","0","0","0"],["3129.14","0","0","0"],["3129.15","0","0","0"],["3129.16","0","0","0"],["3129.17","0","0","0"],["3129.19","0","0","0"],["3129.2","0","0","0"],["3129.21","0","0","0"],["3129.22","0","0","0"],["3129.23","0","0","0"],["3129.25","0","0","0"],["3129.27","0","0","0"],["3129.28","0","0","0"],["3129.29","0","0","0"],["3129.3","0","0","0"],["3129.33","0","0","0"],["3129.34","0","0","0"],["3129.35","0","0","0"],["3129.36","0","0","0"],["3129.37","0","0","0"],["3129.39","0","0","0"],["3129.4","0","0","0"],["3129.41","0","0","0"],["3129.42","0","0","0"],["3129.43","0","0","0"],["3129.46","0","0","0"],["3129.47","0","0","0"],["3129.48","0","0","0"],["3129.49","0","0","0"],["3129.5","0","0","0"],["3129.51","0","0","0"],["3129.53","0","0","0"],["3129.54","0","0","0"],["3129.55","0","0","0"],["3129.56","0","0","0"],["3129.57","0","0","0"],["3129.59","0","0","0"],["3129.6","0","0","0"],["3129.62","0","0","0"],["3129.63","0","0","0"],["3129.64","0","0","0"],["3129.65","0","0","0"],["3129.66","0","0","0"],["3129.67","0","0","0"],["3129.68","0","0","0"],["3129.69","0","0","0"],["3129.7","0","0","0"],["3129.71","0","0","0"],["3129.73","0","0","0"],["3129.74","0","0","0"],["3129.75","0","0","0"],["3129.76","0","0","0"],["3129.77","0","0","0"],["3129.78","0","0","0"],["3129.79","0","0","0"],["3129.8","0","0","0"],["3129.81","0","0","0"],["3129.82","0","0","0"],["3129.84","0","0","0"],["3129.85","0","0","0"],["3129.86","0","0","0"],["3129.87","0","0","0"],["3129.88","0","0","0"],["3129.89","0","0","0"],["3129.9","0","0","0"],["3129.91","0","0","0"],["3129.92","0","0","0"],["3129.93","0","0","0"],["3129.94","0","0","0"],["3129.95","0","0","0"],["3129.97","0","0","0"],["3129.98","0","0","0"],["3130","0","0","0"],["3130.01","0","0","0"],["3130.02","0","0","0"],["3130.03","0","0","0"],["3130.04","0","0","0"],["3130.05","0","0","0"],["3130.07","0","0","0"],["3130.09","0","0","0"],["3130.1","0","0","0"],["3130.11","0","0","0"],["3130.12","0","0","0"],["3130.13","0","0","0"],["3130.15","0","0","0"],["3130.16","0","0","0"],["3130.18","0","0","0"],["3130.19","0","0","0"],["3130.2","0","0","0"],["3130.21","0","0","0"],["3130.22","0","0","0"],["3130.24","0","0","0"],["3130.25","0","0","0"],["3130.26","0","0","0"],["3130.27","0","0","0"],["3130.28","0","0","0"],["3130.3","0","0","0"],["3130.31","0","0","0"],["3130.32","0","0","0"],["3130.33","0","0","0"],["3130.34","0","0","0"],["3130.36","0","0","0"],["3130.37","0","0","0"],["3130.38","0","0","0"],["3130.39","0","0","0"],["3130.4","0","0","0"],["3130.42","0","0","0"],["3130.44","0","0","0"],["3130.45","0","0","0"],["3130.46","0","0","0"],["3130.47","0","0","0"],["3130.5","0","0","0"],["3130.53","0","0","0"],["3130.54","0","0","0"],["3130.56","0","0","0"],["3130.57","0","0","0"],["3130.58","0","0","0"],["3130.59","0","0","0"],["3130.6","0","0","0"],["3130.61","0","0","0"],["3130.62","0","0","0"],["3130.63","0","0","0"],["3130.65","0","0","0"],["3130.67","0","0","0"],["3130.68","0","0","0"],["3130.69","0","0","0"],["3130.7","0","0","0"],["3130.71","0","0","0"],["3130.72","0","0","0"],["3130.74","0","0","0"],["3130.75","0","0","0"],["3130.76","0","0","0"],["3130.77","0","0","0"],["3130.79","0","0","0"],["3130.8","0","0","0"],["3130.81","0","0","0"],["3130.82","0","0","0"],["3130.84","0","0","0"],["3130.86","0","0","0"],["3130.88","0","0","0"],["3130.89","0","0","0"],["3130.91","0","0","0"],["3130.92","0","0","0"],["3130.93","0","0","0"],["3130.94","0","0","0"],["3130.96","0","0","0"],["3130.97","0","0","0"],["3130.98","0","0","0"],["3130.99","0","0","0"],["3131","2.96","0","1"],["3131.01","0","0","0"],["3131.02","0","0","0"],["3131.04","0","0","0"],["3131.05","0","0","0"],["3131.06","0","0","0"],["3131.07","0.02","0","1"],["3131.08","0","0","0"],["3131.09","0","0","0"],["3131.1","0","0","0"],["3131.11","0","0","0"],["3131.12","0","0","0"],["3131.13","0","0","0"],["3131.14","0","0","0"],["3131.16","0","0","0"],["3131.17","0","0","0"],["3131.18","0","0","0"],["3131.19","0","0","0"],["3131.2","2.39","0","4"],["3131.22","0","0","0"],["3131.23","0.07","0","1"],["3132.07","23.55","0","3"],["3132.08","0.04","0","1"],["3132.1","1.53","0","1"],["3132.11","0.11","0","1"],["3132.13","359.73","0","7"],["3132.14","0.56","0","2"],["3132.15","0.52","0","7"],["3132.16","23.1","0","3"],["3132.17","17.82","0","9"],["3132.18","0.34","0","3"],["3132.2","0.3","0","2"],["3132.21","0.02","0","2"],["3132.22","3.46","0","2"],["3132.23","0.04","0","2"],["3132.24","4.12","0","3"],["3132.25","0.99","0","3"],["3132.26","0.02","0","1"],["3132.27","1.59","0","2"],["3132.28","0.01","0","1"],["3132.29","0.06","0","6"],["3132.3","5.1","0","9"],["3132.31","57.24","0","6"],["3132.32","11.09","0","2"],["3132.33","0.66","0","3"],["3132.34","0.11","0","3"],["3132.36","0.04","0","4"],["3132.37","3.63","0","3"],["3132.38","0.09","0","2"],["3132.39","0.02","0","1"],["3132.4","42396.83","0","6"],["3132.41","24.84","0","2"],["3132.42","0.01","0","1"],["3132.43","102.67","0","1"],["3132.44","63.74","0","6"],["3132.45","310.92","0","2"],["3132.46","0.1","0","1"],["3132.47","0.04","0","3"],["3132.48","2.83","0","4"],["3132.5","114.33","0","29"],["3132.51","0.02","0","1"],["3132.52","2.64","0","3"],["3132.53","50.05","0","2"],["3132.54","0.39","0","2"],["3132.55","0.42","0","2"],["3132.56","5.24","0","4"],["3132.57","1.06","0","5"],["3132.58","0.03","0","3"],["3132.59","4.17","0","6"],["3132.6","0.08","0","3"],["3132.61","250.14","0","5"],["3132.62","2.04","0","1"],["3132.63","0.07","0","1"],["3132.65","0.03","0","1"],["3132.66","12.05","0","2"],["3132.67","0.11","0","2"],["3132.68","208.64","0","3"],["3132.69","29.35","0","4"],["3132.71","4.8","0","4"],["3132.72","123.64","0","3"],["3132.73","0.06","0","2"],["3132.74","0.47","0","1"],["3132.75","0.04","0","1"],["3132.76","0.14","0","1"],["3132.77","0.01","0","1"],["3132.78","0.37","0","2"],["3132.79","0.02","0","1"],["3132.8","2010.17","0","16"],["3132.81","0.97","0","4"],["3132.82","33.97","0","3"],["3132.83","11","0","4"],["3132.84","0.07","0","3"],["3132.85","36","0","4"],["3132.86","199.38","0","5"],["3132.87","0.12","0","4"],["3132.88","0.13","0","1"],["3132.89","0.47","0","1"],["3132.9","2.44","0","4"],["3132.91","17.77","0","5"],["3132.92","0.54","0","5"],["3132.93","0.12","0","2"],["3132.94","0.6","0","5"],["3132.96","2.24","0","2"],["3132.97","70.72","0","2"],["3132.98","0.05","0","1"],["3132.99","0.04","0","2"],["3133","115.64","0","16"],["3133.01","1.06","0","2"],["3133.02","0.03","0","1"],["3133.03","16","0","2"],["3133.04","0.78","0","8"],["3133.05","68.74","0","2"],["3133.06","0.04","0","1"],["3133.07","0.05","0","1"],["3133.09","36.66","0","1"],["3133.1","30.22","0","4"],["3133.11","0.02","0","2"],["3133.12","0.23","0","2"],["3133.13","1.27","0","6"],["3133.14","0.01","0","1"],["3133.16","117.47","0","1"],["3133.17","0.01","0","1"],["3133.18","0.11","0","2"],["3133.19","0.25","0","1"],["3133.2","30.93","0","5"],["3133.21","0.03","0","1"],["3133.22","0.09","0","1"],["3133.24","2.3","0","1"],["3133.25","0.22","0","3"],["3133.26","47.43","0","2"],["3133.27","0.01","0","1"],["3133.28","1.07","0","2"],["3133.29","8.4","0","3"],["3133.31","0.74","0","3"],["3133.32","0.01","0","1"],["3133.33","570.23","0","73"],["3133.35","8.34","0","3"],["3133.36","11.22","0","4"],["3133.37","9.65","0","2"],["3133.38","0.04","0","2"],["3133.4","36.28","0","5"],["3133.41","2.35","0","3"],["3133.42","0.56","0","1"],["3133.43","0.42","0","6"],["3133.45","5.93","0","1"],["3133.46","1.12","0","1"],["3133.48","4.78","0","1"],["3133.49","15.33","0","4"],["3133.5","1398.94","0","12"],["3133.51","0.93","0","2"],["3133.52","0.49","0","1"],["3133.53","735.72","0","7"],["3133.54","1.76","0","3"],["3133.55","0.03","0","1"],["3133.56","0.69","0","4"],["3133.58","1.02","0","5"],["3133.6","61.59","0","11"],["3133.61","90.18","0","1"],["3133.63","10.92","0","3"],["3133.64","0.67","0","1"],["3133.66","49.96","0","2"],["3133.67","0.02","0","1"],["3133.68","0.06","0","2"],["3133.7","0.1","0","4"],["3133.71","4.04","0","5"],["3133.73","0.01","0","1"],["3133.74","0.05","0","2"],["3133.75","0.09","0","2"],["3133.76","4.84","0","6"],["3133.78","0.24","0","2"],["3133.79","0.03","0","2"],["3133.8","0.17","0","4"],["3133.81","8.57","0","2"],["3133.82","25.1","0","2"],["3133.83","0.45","0","4"],["3133.84","355.94","0","3"],["3133.85","0.1","0","1"],["3133.87","0.57","0","3"],["3133.89","25.5","0","1"],["3133.9","0.13","0","1"],["3133.92","0.92","0","1"],["3133.93","13.95","0","1"],["3133.94","0.08","0","3"],["3133.95","0.02","0","1"],["3133.96","17.12","0","6"],["3133.97","0.02","0","1"],["3133.98","0.14","0","1"],["3133.99","206.87","0","10"],["3134","455.04","0","80"],["3134.01","0.02","0","1"],["3134.02","2.91","0","3"],["3134.03","0.03","0","1"],["3134.04","0.94","0","3"],["3134.05","0.09","0","2"],["3134.06","14.59","0","3"],["3134.07","0.52","0","1"],["3134.08","0.12","0","3"],["3134.09","0.03","0","1"],["3134.1","1.22","0","4"],["3134.11","20.8","0","3"],["3134.12","0.35","0","3"],["3134.13","78.18","0","3"],["3134.14","50.04","0","1"],["3134.15","0.05","0","1"],["3134.17","0.02","0","1"],["3134.18","0.02","0","1"],["3134.19","0.19","0","2"],["3134.2","0.33","0","2"],["3134.21","0.61","0","5"],["3134.22","0.09","0","1"],["3134.23","11.12","0","3"],["3134.24","0.03","0","3"],["3134.25","0.2","0","3"],["3134.26","2.14","0","8"],["3134.27","42.54","0","1"],["3134.28","0.26","0","2"],["3134.29","3.55","0","6"],["3134.3","14.31","0","4"],["3134.31","0.32","0","2"],["3134.32","891.6","0","4"],["3134.33","0.52","0","3"],["3134.35","0.23","0","4"],["3134.36","31.43","0","2"],["3134.37","0.07","0","2"],["3134.38","1.48","0","4"],["3134.39","0.05","0","1"],["3134.4","90.37","0","11"],["3134.41","90.12","0","3"],["3134.42","0.12","0","2"],["3134.43","0.04","0","1"],["3134.44","81.04","0","2"],["3134.45","0.12","0","3"],["3134.46","0.03","0","2"],["3134.48","77.22","0","4"],["3134.49","0.11","0","1"],["3134.5","116.9","0","14"],["3134.51","0.06","0","2"],["3134.52","9.98","0","1"],["3134.53","36.85","0","5"],["3134.54","22.92","0","3"],["3134.55","0.37","0","5"],["3134.56","0.22","0","2"],["3134.57","4.02","0","3"],["3134.58","0.01","0","1"],["3134.59","0.99","0","2"],["3134.6","12.1","0","7"],["3134.61","0.15","0","3"],["3134.62","2.62","0","8"],["3134.63","0.09","0","4"],["3134.64","0.01","0","1"],["3134.65","0.01","0","1"],["3134.66","0.01","0","1"],["3134.67","49.65","0","3"],["3134.68","0.37","0","1"],["3134.69","4.58","0","9"],["3134.7","104.8","0","4"],["3134.71","2.34","0","2"],["3134.72","42.28","0","6"],["3134.73","3.62","0","2"],["3134.74","0.03","0","2"],["3134.75","2.6","0","5"],["3134.76","7.49","0","2"],["3134.77","0.02","0","2"],["3134.78","0.02","0","1"],["3134.79","14.92","0","5"],["3134.8","154.49","0","4"],["3134.81","245.76","0","5"],["3134.82","0.07","0","1"],["3134.85","1.74","0","3"],["3134.86","35.01","0","1"],["3134.87","124.23","0","6"],["3134.88","0.17","0","2"],["3134.91","0.01","0","1"],["3134.92","1.53","0","1"],["3134.93","0.17","0","1"],["3134.94","1.21","0","1"],["3134.95","15.73","0","6"],["3134.96","0.08","0","2"],["3134.97","0.17","0","3"],["3134.98","1.77","0","3"],["3134.99","3.5","0","8"],["3135","2081.67","0","126"],["3135.01","0.32","0","2"],["3135.02","24.05","0","2"],["3135.03","3087.13","0","8"],["3135.04","10.84","0","8"],["3135.05","0.33","0","4"],["3135.06","0.01","0","1"],["3135.07","0.01","0","1"],["3135.08","0.01","0","1"],["3135.09","79.76","0","2"],["3135.1","113.87","0","3"],["3135.11","0.12","0","3"],["3135.12","0.04","0","1"],["3135.13","0.26","0","4"],["3135.14","4.76","0","6"],["3135.15","0.07","0","2"],["3135.16","0.01","0","1"],["3135.17","0.21","0","2"],["3135.18","1.17","0","6"],["3135.19","171.31","0","2"],["3135.2","1.09","0","4"],["3135.21","9.54","0","1"],["3135.22","143.43","0","18"],["3135.23","117.65","0","4"],["3135.24","928.02","0","11"],["3135.25","1.54","0","2"],["3135.26","5.87","0","2"],["3135.28","0.12","0","5"],["3135.29","0.01","0","1"],["3135.3","1.48","0","5"],["3135.31","39.31","0","2"],["3135.33","26.03","0","6"],["3135.35","30.09","0","5"],["3135.36","48.81","0","7"],["3135.37","0.45","0","4"],["3135.38","2.76","0","7"],["3135.4","8.68","0","1"],["3135.41","2.33","0","4"],["3135.43","11.06","0","4"],["3135.45","17.6","0","2"],["3135.46","5.93","0","1"],["3135.47","45.22","0","6"],["3135.48","8.08","0","6"],["3135.49","1.17","0","2"],["3135.5","21617.05","0","12"],["3135.51","4.83","0","8"],["3135.53","0.51","0","3"],["3135.54","0.03","0","2"],["3135.56","0.14","0","6"],["3135.57","1.28","0","4"],["3135.58","0.49","0","4"],["3135.6","66.39","0","6"],["3135.61","0.01","0","1"],["3135.62","2.05","0","2"],["3135.63","40.46","0","2"],["3135.64","30.26","0","4"],["3135.65","0.02","0","1"],["3135.66","57.34","0","5"],["3135.67","5.86","0","2"],["3135.68","0.05","0","2"],["3135.69","12.05","0","2"],["3135.7","300.02","0","5"],["3135.71","94.85","0","9"],["3135.72","4.88","0","2"]],"bids":[["3129.94","0.01","0","1"],["3129.92","0.04","0","1"],["3129.64","0.05","0","1"],["3129.59","0.03","0","1"],["3129.57","11.11","0","1"],["3129.55","0.67","0","1"],["3129.54","13.9","0","1"],["3129.53","0.01","0","1"],["3129.5","0.03","0","3"],["3129.49","0.05","0","3"],["3129.47","0.02","0","1"],["3129.39","0.29","0","1"],["3129.37","0.01","0","1"],["3129.35","16","0","2"],["3129.33","50.04","0","1"],["3129.3","30.16","0","2"],["3129.27","0.01","0","1"],["3129.25","0.09","0","1"],["3129.2","0.94","0","2"],["3129.19","0.08","0","2"],["3129.17","37.73","0","1"],["3129.14","0.06","0","2"],["3129.13","3.45","0","1"],["3129.11","0.02","0","1"],["3129.09","7.4","0","2"],["3129.07","0.01","0","1"],["3129.06","47.58","0","2"],["3129.02","117.47","0","1"],["3129","14.25","0","5"],["3128.99","0.06","0","1"],["3128.97","0.92","0","1"],["3128.95","0.47","0","1"],["3128.9","2.3","0","1"],["3128.89","0.04","0","3"],["3128.85","0.25","0","1"],["3128.83","0.01","0","1"],["3128.8","1.18","0","2"],["3128.79","0.03","0","1"],["3128.76","36.66","0","1"],["3128.73","0.03","0","1"],["3128.71","0.01","0","1"],["3128.69","0.01","0","1"],["3128.68","0.01","0","1"],["3128.66","0.07","0","2"],["3128.65","90.05","0","1"],["3128.62","10.35","0","1"],["3128.6","0.01","0","1"],["3128.58","0.18","0","1"],["3128.54","3.14","0","2"],["3128.5","5.74","0","3"],["3128.48","1","0","1"],["3128.43","0.02","0","1"],["3128.42","0.02","0","1"],["3128.4","3.9","0","6"],["3128.39","0.02","0","2"],["3128.38","0.53","0","1"],["3128.37","0.1","0","1"],["3128.34","0.04","0","1"],["3128.33","0.01","0","1"],["3128.32","0.22","0","2"],["3128.31","0.01","0","1"],["3128.3","0.27","0","1"],["3128.29","0.05","0","1"],["3128.27","0.03","0","1"],["3128.23","0.09","0","1"],["3128.22","13.91","0","2"],["3128.21","0.05","0","3"],["3128.18","0.69","0","3"],["3128.16","0.01","0","1"],["3128.15","0.37","0","2"],["3128.14","25.5","0","1"],["3128.13","0.01","0","1"],["3128.11","0.01","0","1"],["3128.1","68.64","0","2"],["3128.08","0.01","0","1"],["3128.05","0.01","0","1"],["3128.04","30.15","0","4"],["3128.02","1.55","0","3"],["3128.01","0.03","0","2"],["3128","344.45","0","55"],["3127.99","0.29","0","1"],["3127.96","0.05","0","2"],["3127.95","0.02","0","1"],["3127.93","36.78","0","2"],["3127.91","42.54","0","1"],["3127.9","35.75","0","2"],["3127.89","0.14","0","4"],["3127.88","3.78","0","2"],["3127.87","3.23","0","2"],["3127.85","9.89","0","5"],["3127.82","17.7","0","4"],["3127.81","0.04","0","1"],["3127.8","18.76","0","1"],["3127.79","0.08","0","2"],["3127.78","37.93","0","2"],["3127.76","0.02","0","2"],["3127.75","0.02","0","1"],["3127.73","50.04","0","1"],["3127.72","0.1","0","1"],["3127.7","0.51","0","4"],["3127.68","0.12","0","1"],["3127.67","0.99","0","3"],["3127.66","0.91","0","1"],["3127.65","0.02","0","2"],["3127.63","15.52","0","5"],["3127.62","59.07","0","1"],["3127.61","1.12","0","1"],["3127.6","17.22","0","5"],["3127.59","0.02","0","1"],["3127.58","3.45","0","1"],["3127.56","8.83","0","1"],["3127.55","0.01","0","1"],["3127.53","0.29","0","2"],["3127.52","875.92","0","1"],["3127.51","65.89","0","2"],["3127.5","94.15","0","19"],["3127.48","0.23","0","1"],["3127.45","0.15","0","2"],["3127.43","6.45","0","2"],["3127.42","0.01","0","1"],["3127.4","23.83","0","4"],["3127.39","1.09","0","2"],["3127.38","0.02","0","1"],["3127.37","1.33","0","3"],["3127.34","0.1","0","1"],["3127.33","0.01","0","1"],["3127.32","37.61","0","3"],["3127.31","0.47","0","1"],["3127.29","1.91","0","1"],["3127.27","1.04","0","4"],["3127.25","0.22","0","3"],["3127.24","1.09","0","1"],["3127.23","0.03","0","1"],["3127.22","10.45","0","2"],["3127.21","90.07","0","2"],["3127.2","1.33","0","5"],["3127.19","0.06","0","1"],["3127.18","0.03","0","2"],["3127.17","0.18","0","1"],["3127.13","1.32","0","1"],["3127.12","0.1","0","1"],["3127.11","0.62","0","2"],["3127.1","4.77","0","3"],["3127.09","10.57","0","3"],["3127.08","0.05","0","1"],["3127.05","0.09","0","1"],["3127.04","0.01","0","1"],["3127.03","9.23","0","7"],["3127.02","0.01","0","1"],["3127.01","0.2","0","1"],["3127","79.29","0","14"],["3126.98","0.03","0","1"],["3126.97","0.01","0","1"],["3126.96","54.79","0","2"],["3126.95","117.5","0","2"],["3126.94","0.69","0","3"],["3126.93","0.02","0","2"],["3126.92","0.07","0","4"],["3126.91","13.92","0","2"],["3126.9","0.1","0","4"],["3126.89","0.16","0","1"],["3126.88","0.58","0","2"],["3126.87","0.22","0","4"],["3126.86","0.05","0","1"],["3126.85","0.16","0","2"],["3126.83","2.19","0","1"],["3126.82","0.86","0","4"],["3126.81","29.24","0","2"],["3126.8","0.74","0","4"],["3126.79","0.01","0","1"],["3126.78","31.32","0","2"],["3126.77","0.07","0","5"],["3126.76","90.5","0","2"],["3126.73","2.32","0","3"],["3126.72","0.01","0","1"],["3126.71","0.01","0","1"],["3126.7","25.95","0","5"],["3126.69","0.26","0","2"],["3126.68","0.04","0","2"],["3126.67","309.14","0","15"],["3126.65","0.6","0","6"],["3126.64","5.75","0","3"],["3126.63","0.1","0","1"],["3126.61","0.1","0","1"],["3126.6","37.5","0","7"],["3126.59","12.7","0","4"],["3126.58","1920.39","0","2"],["3126.56","2","0","4"],["3126.54","0.02","0","1"],["3126.53","0.09","0","1"],["3126.52","2.53","0","1"],["3126.51","0.01","0","1"],["3126.5","1229.41","0","9"],["3126.48","0.14","0","2"],["3126.47","734.99","0","2"],["3126.45","318.71","0","4"],["3126.43","0.02","0","1"],["3126.42","4.18","0","1"],["3126.41","0.01","0","1"],["3126.4","150.53","0","10"],["3126.39","37.75","0","3"],["3126.38","0.11","0","2"],["3126.37","0.06","0","2"],["3126.36","0.3","0","3"],["3126.35","0.03","0","1"],["3126.33","0.61","0","1"],["3126.32","0.47","0","1"],["3126.31","1.02","0","2"],["3126.3","0.01","0","1"],["3126.29","0.01","0","1"],["3126.27","1.1","0","4"],["3126.26","0.59","0","1"],["3126.25","1.07","0","1"],["3126.24","123.87","0","5"],["3126.23","4.87","0","1"],["3126.22","0.21","0","2"],["3126.21","0.57","0","3"],["3126.2","46.86","0","8"],["3126.19","1.7","0","1"],["3126.18","0.01","0","1"],["3126.17","24.35","0","3"],["3126.16","0.01","0","1"],["3126.15","1.02","0","2"],["3126.14","107.65","0","3"],["3126.13","50.12","0","5"],["3126.12","64.13","0","4"],["3126.1","11.71","0","3"],["3126.09","0.04","0","3"],["3126.08","0.02","0","1"],["3126.07","0.35","0","4"],["3126.06","0.06","0","2"],["3126.05","0.54","0","6"],["3126.04","4.03","0","3"],["3126.02","0.01","0","1"],["3126.01","9.54","0","1"],["3126","377.28","0","46"],["3125.97","0.03","0","1"],["3125.96","2.21","0","2"],["3125.95","0.03","0","2"],["3125.93","0.06","0","2"],["3125.92","0.02","0","2"],["3125.9","0.01","0","1"],["3125.88","37.96","0","4"],["3125.87","0.07","0","3"],["3125.86","0.09","0","7"],["3125.82","31.85","0","3"],["3125.81","0.16","0","3"],["3125.8","3.86","0","3"],["3125.79","1.67","0","4"],["3125.78","1.33","0","4"],["3125.77","109.15","0","2"],["3125.75","174.6","0","9"],["3125.74","0.11","0","4"],["3125.72","114.05","0","6"],["3125.71","0.15","0","4"],["3125.7","6.29","0","3"],["3125.69","0.01","0","1"],["3125.68","0.01","0","1"],["3125.67","17.01","0","3"],["3125.64","0.05","0","3"],["3125.63","56.78","0","2"],["3125.62","0.01","0","1"],["3125.6","3.12","0","8"],["3125.59","13.95","0","2"],["3125.58","0.1","0","1"],["3125.56","0.22","0","2"],["3125.55","0.08","0","3"],["3125.53","13.96","0","2"],["3125.52","30.11","0","1"],["3125.51","0.01","0","1"],["3125.5","208.7","0","14"],["3125.47","86.88","0","3"],["3125.46","2.31","0","4"],["3125.45","61.9","0","9"],["3125.44","0.33","0","2"],["3125.42","6.49","0","5"],["3125.4","0.11","0","3"],["3125.39","1.41","0","2"],["3125.38","0.24","0","3"],["3125.37","0.27","0","1"],["3125.34","1.98","0","1"],["3125.33","10.25","0","3"],["3125.32","1.88","0","1"],["3125.31","206.81","0","6"],["3125.3","0.05","0","1"],["3125.27","17.6","0","2"],["3125.26","25.5","0","1"],["3125.25","35.24","0","6"],["3125.24","0.26","0","5"],["3125.23","0.16","0","1"],["3125.22","0.74","0","4"],["3125.21","0.01","0","1"],["3125.2","10.7","0","6"],["3125.19","0.04","0","3"],["3125.18","1.42","0","3"],["3125.17","0.34","0","2"],["3125.16","0.46","0","5"],["3125.15","150.02","0","7"],["3125.14","0.89","0","4"],["3125.12","0.02","0","2"],["3125.11","74.37","0","4"],["3125.1","9.98","0","1"],["3125.09","0.2","0","1"],["3125.08","0.01","0","1"],["3125.06","15.19","0","1"],["3125.04","0.24","0","2"],["3125.03","0.36","0","1"],["3125.02","22.86","0","3"],["3125","2042.71","0","121"],["3124.98","1.2","0","2"],["3124.96","211.83","0","5"],["3124.94","0.22","0","1"],["3124.92","0.11","0","2"],["3124.91","231.85","0","3"],["3124.9","18.78","0","3"],["3124.89","0.01","0","1"],["3124.88","198.47","0","4"],["3124.87","0.78","0","5"],["3124.86","7.19","0","1"],["3124","0","0","0"],["3123.99","0","0","0"],["3123.98","0","0","0"],["3123.97","0","0","0"],["3123.95","0","0","0"],["3123.94","0","0","0"],["3123.93","0","0","0"],["3123.92","0","0","0"],["3123.9","0","0","0"],["3123.88","0","0","0"],["3123.87","0","0","0"],["3123.86","0","0","0"],["3123.85","0","0","0"],["3123.84","0","0","0"],["3123.83","0","0","0"],["3123.82","0","0","0"],["3123.81","0","0","0"],["3123.8","0","0","0"],["3123.79","0","0","0"],["3123.78","0","0","0"],["3123.77","0","0","0"],["3123.76","0","0","0"],["3123.75","0","0","0"],["3123.74","0","0","0"],["3123.73","0","0","0"],["3123.71","0","0","0"],["3123.7","0","0","0"],["3123.69","0","0","0"],["3123.68","0","0","0"],["3123.67","0","0","0"],["3123.66","0","0","0"],["3123.65","0","0","0"],["3123.64","0","0","0"],["3123.63","0","0","0"],["3123.61","0","0","0"],["3123.6","0","0","0"],["3123.59","0","0","0"],["3123.58","0","0","0"],["3123.56","0","0","0"],["3123.55","0","0","0"],["3123.54","0","0","0"],["3123.53","0","0","0"],["3123.52","0","0","0"],["3123.51","0","0","0"],["3123.5","0","0","0"],["3123.49","0","0","0"],["3123.48","0","0","0"],["3123.47","0","0","0"],["3123.46","0","0","0"],["3123.45","0","0","0"],["3123.43","0","0","0"],["3123.42","0","0","0"],["3123.41","0","0","0"],["3123.4","0","0","0"],["3123.39","0","0","0"],["3123.38","0","0","0"],["3123.37","0","0","0"],["3123.36","0","0","0"],["3123.35","0","0","0"],["3123.33","0","0","0"],["3123.32","0","0","0"],["3123.3","0","0","0"],["3123.29","0","0","0"],["3123.28","0","0","0"],["3123.27","0","0","0"],["3123.26","0","0","0"],["3123.25","0","0","0"],["3123.24","0","0","0"],["3123.23","0","0","0"],["3123.22","0","0","0"],["3123.2","0","0","0"],["3123.19","0","0","0"],["3123.18","0","0","0"],["3123.17","0","0","0"],["3123.16","0","0","0"],["3123.15","0","0","0"],["3123.14","0","0","0"],["3123.13","0","0","0"],["3123.12","0","0","0"],["3123.11","0","0","0"],["3123.09","0","0","0"],["3123.08","0","0","0"],["3123.07","0","0","0"],["3123.06","0","0","0"],["3123.05","0","0","0"],["3123.04","0","0","0"],["3123.03","0","0","0"],["3123.02","0","0","0"],["3123.01","0","0","0"],["3123","0","0","0"],["3122.99","0","0","0"],["3122.98","0","0","0"],["3122.97","0","0","0"],["3122.96","0","0","0"],["3122.95","0","0","0"],["3122.94","0","0","0"],["3122.93","0","0","0"],["3122.92","0","0","0"],["3122.91","0","0","0"],["3122.9","0","0","0"],["3122.89","0","0","0"],["3122.88","0","0","0"],["3122.87","0","0","0"],["3122.86","0","0","0"],["3122.84","0","0","0"],["3122.83","0","0","0"],["3122.82","0","0","0"],["3122.81","0","0","0"],["3122.8","0","0","0"],["3122.79","0","0","0"],["3122.78","0","0","0"],["3122.77","0","0","0"],["3122.76","0","0","0"],["3122.75","0","0","0"],["3122.73","0","0","0"],["3122.72","0","0","0"],["3122.7","0","0","0"],["3122.69","0","0","0"],["3122.68","0","0","0"],["3122.67","0","0","0"],["3122.66","0","0","0"],["3122.65","0","0","0"],["3122.64","0","0","0"],["3122.63","0","0","0"],["3122.62","0","0","0"],["3122.6","0","0","0"],["3122.59","0","0","0"],["3122.58","0","0","0"],["3122.56","0","0","0"],["3122.55","0","0","0"],["3122.54","0","0","0"],["3122.53","0","0","0"],["3122.52","0","0","0"],["3122.51","0","0","0"],["3122.5","0","0","0"],["3122.49","0","0","0"],["3122.48","0","0","0"],["3122.47","0","0","0"],["3122.46","0","0","0"],["3122.45","0","0","0"],["3122.44","0","0","0"],["3122.43","0","0","0"],["3122.42","0","0","0"],["3122.4","0","0","0"],["3122.39","0","0","0"],["3122.38","0","0","0"],["3122.37","0","0","0"],["3122.36","0","0","0"],["3122.35","0","0","0"],["3122.34","0","0","0"],["3122.33","0","0","0"],["3122.32","0","0","0"],["3122.31","0","0","0"],["3122.3","0","0","0"],["3122.29","0","0","0"],["3122.28","0","0","0"],["3122.27","0","0","0"],["3122.26","0","0","0"],["3122.24","0","0","0"],["3122.23","0","0","0"],["3122.22","0","0","0"],["3122.2","0","0","0"],["3122.19","0","0","0"],["3122.18","0","0","0"],["3122.17","0","0","0"],["3122.15","0","0","0"],["3122.14","0","0","0"],["3122.13","0","0","0"],["3122.12","0","0","0"],["3122.11","0","0","0"],["3122.1","0","0","0"],["3122.08","0","0","0"],["3122.06","0","0","0"],["3122.05","0","0","0"],["3122.04","0","0","0"],["3122.03","0","0","0"],["3122.02","0","0","0"],["3122.01","0","0","0"],["3122","0","0","0"],["3121.99","0","0","0"],["3121.98","0","0","0"],["3121.97","0","0","0"],["3121.96","0","0","0"],["3121.95","0","0","0"],["3121.94","0","0","0"],["3121.93","0","0","0"],["3121.92","0","0","0"],["3121.91","0","0","0"],["3121.9","0","0","0"],["3121.89","0","0","0"],["3121.88","0","0","0"],["3121.87","0","0","0"],["3121.85","0","0","0"],["3121.84","0","0","0"],["3121.83","0","0","0"],["3121.82","0","0","0"],["3121.81","0","0","0"],["3121.8","0","0","0"],["3121.79","0","0","0"],["3121.78","0","0","0"],["3121.77","0","0","0"],["3121.76","0","0","0"],["3121.75","0","0","0"],["3121.74","0","0","0"],["3121.73","0","0","0"],["3121.71","0","0","0"],["3121.7","0","0","0"],["3121.69","0","0","0"],["3121.67","0","0","0"],["3121.66","0","0","0"],["3121.65","0","0","0"],["3121.64","0","0","0"],["3121.63","0","0","0"],["3121.62","0","0","0"],["3121.61","0","0","0"],["3121.6","0","0","0"],["3121.59","0","0","0"],["3121.57","0","0","0"],["3121.56","0","0","0"],["3121.55","0","0","0"],["3121.54","0","0","0"],["3121.53","0","0","0"],["3121.52","0","0","0"],["3121.51","0","0","0"],["3121.5","0","0","0"],["3121.49","0","0","0"],["3121.48","0","0","0"],["3121.47","0","0","0"],["3121.46","0","0","0"],["3121.45","0","0","0"],["3121.44","0","0","0"],["3121.43","0","0","0"],["3121.42","0","0","0"],["3121.41","0","0","0"],["3121.4","0","0","0"],["3121.39","0","0","0"],["3121.38","0","0","0"],["3121.37","0","0","0"],["3121.36","0","0","0"],["3121.35","0","0","0"],["3121.33","0","0","0"],["3121.32","0","0","0"],["3121.31","0","0","0"],["3121.3","0","0","0"],["3121.29","0","0","0"],["3121.28","0","0","0"],["3121.27","0","0","0"],["3121.26","0","0","0"],["3121.25","0","0","0"],["3121.24","0","0","0"],["3121.23","0","0","0"],["3121.22","0","0","0"],["3121.2","0","0","0"],["3121.18","0","0","0"],["3121.17","0","0","0"],["3121.16","0","0","0"],["3121.15","0","0","0"],["3121.14","0","0","0"],["3121.13","0","0","0"],["3121.12","0","0","0"],["3121.11","0","0","0"],["3121.1","0","0","0"],["3121.09","0","0","0"],["3121.08","0","0","0"],["3121.07","0","0","0"],["3121.06","0","0","0"],["3121.05","0","0","0"],["3121.04","0","0","0"],["3121.03","0","0","0"],["3121.02","0","0","0"],["3121.01","0","0","0"],["3121","0","0","0"],["3120.98","0","0","0"],["3120.97","0","0","0"],["3120.95","0","0","0"],["3120.94","0","0","0"],["3120.93","0","0","0"],["3120.92","0","0","0"],["3120.91","0","0","0"],["3120.9","0","0","0"],["3120.88","0","0","0"],["3120.87","0","0","0"],["3120.86","0","0","0"],["3120.85","0","0","0"],["3120.84","0","0","0"],["3120.83","0","0","0"],["3120.82","0","0","0"],["3120.81","0","0","0"],["3120.8","0","0","0"],["3120.79","0","0","0"],["3120.78","0","0","0"],["3120.76","0","0","0"],["3120.75","0","0","0"],["3120.74","0","0","0"],["3120.72","0","0","0"],["3120.71","0","0","0"],["3120.7","0","0","0"],["3120.69","0","0","0"],["3120.68","0","0","0"],["3120.67","0","0","0"],["3120.66","0","0","0"],["3120.65","0","0","0"],["3120.64","0","0","0"],["3120.63","0","0","0"],["3120.62","0","0","0"],["3120.61","0","0","0"],["3120.6","0","0","0"],["3120.59","0","0","0"],["3120.58","0","0","0"],["3120.57","0","0","0"],["3120.56","0","0","0"],["3120.55","0","0","0"],["3120.54","0","0","0"],["3120.53","0","0","0"],["3120.52","0","0","0"],["3120.51","0","0","0"],["3120.5","0","0","0"],["3120.48","0","0","0"]],"ts":"1765632001007","checksum":1320113766,"seqId":1158524611,"prevSeqId":1158519947}]}
{"arg":{"channel":"books5","instId":"ETH-USDT-SWAP"},"data":[{"asks":[["3131","2.96","0","1"],["3131.07","0.02","0","1"],["3131.2","2.39","0","4"],["3131.23","0.07","0","1"],["3131.24","15.16","0","5"]],"bids":[["3129.94","0.01","0","1"],["3129.92","0.04","0","1"],["3129.64","0.05","0","1"],["3129.59","0.03","0","1"],["3129.57","11.11","0","1"]],"instId":"ETH-USDT-SWAP","ts":"1765632001007","seqId":1158524611}]}
{"arg":{"channel":"bbo-tbt","instId":"ETH-USDT-SWAP"},"data":[{"asks":[["3131","2.88","0","1"]],"bids":[["3129.94","0.01","0","1"]],"ts":"1765632001037","seqId":1158524761}]}
{"arg":{"channel":"tickers","instId":"ETH-USDT-SWAP"},"data":[{"instType":"SWAP","instId":"ETH-USDT-SWAP","last":"3124.86","lastSz":"0.12","askPx":"3131.23","askSz":"0.07","bidPx":"3124.86","bidSz":"7.19","open24h":"3248","high24h":"3315.64","low24h":"3072.11","sodUtc0":"3108.41","sodUtc8":"3174.4","volCcy24h":"19460092.069","vol24h":"194600920.69","ts":"1765632000952"}]}
{"arg":{"channel":"books","instId":"ETH-USDT-SWAP"},"action":"update","data":[{"asks":[["3131","2.88","0","1"]],"bids":[],"ts":"1765632001107","checksum":826430343,"seqId":1158524829,"prevSeqId":1158524611}]}
{"arg":{"channel":"books5","instId":"ETH-USDT-SWAP"},"data":[{"asks":[["3131","2.88","0","1"],["3131.07","0.02","0","1"],["3131.2","2.39","0","4"],["3131.23","0.07","0","1"],["3131.24","15.16","0","5"]],"bids":[["3129.94","0.01","0","1"],["3129.92","0.04","0","1"],["3129.64","0.05","0","1"],["3129.59","0.03","0","1"],["3129.57","11.11","0","1"]],"instId":"ETH-USDT-SWAP","ts":"1765632001107","seqId":1158524829}]}
{"arg":{"channel":"bbo-tbt","instId":"ETH-USDT-SWAP"},"data":[{"asks":[["3130.91","0.03","0","1"]],"bids":[["3129.57","10.5","0","1"]],"ts":"1765632001127","seqId":1158524849}]}
{"arg":{"channel":"tickers","instId":"ETH-USDT-SWAP"},"data":[{"instType":"SWAP","instId":"ETH-USDT-SWAP","last":"3131","lastSz":"0.08","askPx":"3131","askSz":"2.88","bidPx":"3129.94","bidSz":"0.01","open24h":"3248","high24h":"3315.64","low24h":"3072.11","sodUtc0":"3108.41","sodUtc8":"3174.4","volCcy24h":"19460094.101","vol24h":"194600941.01","ts":"1765632001087"}]}
{"arg":{"channel":"bbo-tbt","instId":"ETH-USDT-SWAP"},"data":[{"asks":[["3130.91","0.03","0","1"]],"bids":[["3129.57","10.37","0","1"]],"ts":"1765632001157","seqId":1158524879}]}
{"arg":{"channel":"bbo-tbt","instId":"ETH-USDT-SWAP"},"data":[{"asks":[["3131","2.86","0","1"]],"bids":[["3129.57","10.37","0","1"]],"ts":"1765632001207","seqId":1158524885}]}
{"arg":{"channel":"books","instId":"ETH-USDT-SWAP"},"action":"update","data":[{"asks":[["3131","2.86","0","1"],["3131.18","0.04","0","1"],["3131.2","2.4","0","5"],["3135.72","0","0","0"]],"bids":[["3129.94","0","0","0"],["3129.92","0","0","0"],["3129.64","0","0","0"],["3129.59","0","0","0"],["3129.57","10.37","0","1"],["3124","3661.33","0","161"],["3123.99","2.99","0","1"],["3123.98","0.09","0","2"],["3123.97","0.18","0","1"]],"ts":"1765632001207","checksum":1285320536,"seqId":1158524885,"prevSeqId":1158524829}]}
{"arg":{"channel":"books5","instId":"ETH-USDT-SWAP"},"data":[{"asks":[["3131","2.86","0","1"],["3131.07","0.02","0","1"],["3131.18","0.04","0","1"],["3131.2","2.4","0","5"],["3131.23","0.07","0","1"]],"bids":[["3129.57","10.37","0","1"],["3129.55","0.67","0","1"],["3129.54","13.9","0","1"],["3129.53","0.01","0","1"],["3129.5","0.03","0","3"]],"instId":"ETH-USDT-SWAP","ts":"1765632001207","seqId":1158524885}]}
{"arg":{"channel":"bbo-tbt","instId":"ETH-USDT-SWAP"},"data":[{"asks":[["3131","2.86","0","1"]],"bids":[["3129.64","0.05","0","1"]],"ts":"1765632001217","seqId":1158524892}]}
{"arg":{"channel":"bbo-tbt","instId":"ETH-USDT-SWAP"},"data":[{"asks":[["3131","2.86","0","1"]],"bids":[["3129.57","9.08","0","1"]],"ts":"1765632001227","seqId":1158524898}]}
{"arg":{"channel":"bbo-tbt","instId":"ETH-USDT-SWAP"},"data":[{"asks":[["3130.91","0.03","0","1"]],"bids":[["3129.57","9.08","0","1"]],"ts":"1765632001237","seqId":1158524901}]}
{"arg":{"channel":"bbo-tbt","instId":"ETH-USDT-SWAP"},"data":[{"asks":[["3130.99","0.01","0","1"]],"bids":[["3129.57","9.08","0","1"]],"ts":"1765632001247","seqId":1158524906}]}
{"arg":{"channel":"bbo-tbt","instId":"ETH-USDT-SWAP"},"data":[{"asks":[["3130.99","0.01","0","1"]],"bids":[["3129.59","0.03","0","1"]],"ts":"1765632001257","seqId":1158524908}]}
{"arg":{"channel":"tickers","instId":"ETH-USDT-SWAP"},"data":[{"instType":"SWAP","instId":"ETH-USDT-SWAP","last":"3130.91","lastSz":"0.03","askPx":"3130.99","askSz":"0.05","bidPx":"3129.57","bidSz":"10.37","open24h":"3248","high24h":"3315.64","low24h":"3072.11","sodUtc0":"3108.41","sodUtc8":"3174.4","volCcy24h":"19460094.191","vol24h":"194600941.91","ts":"1765632001208"}]}
{"arg":{"channel":"bbo-tbt","instId":"ETH-USDT-SWAP"},"data":[{"asks":[["3130.99","0.01","0","1"]],"bids":[["3129.57","8.99","0","1"]],"ts":"1765632001267","seqId":1158524912}]}
{"arg":{"channel":"bbo-tbt","instId":"ETH-USDT-SWAP"},"data":[{"asks":[["3130.91","0.03","0","1"]],"bids":[["3129.64","0.05","0","1"]],"ts":"1765632001277","seqId":1158524919}]}
{"arg":{"channel":"books","instId":"ETH-USDT-SWAP"},"action":"update","data":[{"asks":[["3130.91","0.03","0","1"],["3131","2.64","0","1"],["3135.71","0","0","0"]],"bids":[["3129.64","0.05","0","1"],["3129.57","8.99","0","1"],["3123.97","0","0","0"]],"ts":"1765632001307","checksum":-353693208,"seqId":1158524919,"prevSeqId":1158524885}]}
{"arg":{"channel":"books5","instId":"ETH-USDT-SWAP"},"data":[{"asks":[["3130.91","0.03","0","1"],["3131","2.64","0","1"],["3131.07","0.02","0","1"],["3131.18","0.04","0","1"],["3131.2","2.4","0","5"]],"bids":[["3129.64","0.05","0","1"],["3129.57","8.99","0","1"],["3129.55","0.67","0","1"],["3129.54","13.9","0","1"],["3129.53","0.01","0","1"]],"instId":"ETH-USDT-SWAP","ts":"1765632001307","seqId":1158524919}]}
{"arg":{"channel":"bbo-tbt","instId":"ETH-USDT-SWAP"},"data":[{"asks":[["3130.91","0.03","0","1"]],"bids":[["3129.57","8.38","0","1"]],"ts":"1765632001327","seqId":1158524923}]}
{"arg":{"channel":"bbo-tbt","instId":"ETH-USDT-SWAP"},"data":[{"asks":[["3131","2.48","0","1"]],"bids":[["3129.57","8.38","0","1"]],"ts":"1765632001347","seqId":1158524932}]}
{"arg":{"channel":"bbo-tbt","instId":"ETH-USDT-SWAP"},"data":[{"asks":[["3131","2.48","0","1"]],"bids":[["3129.64","0.05","0","1"]],"ts":"1765632001357","seqId":1158524936}]}
{"arg":{"channel":"tickers","instId":"ETH-USDT-SWAP"},"data":[{"instType":"SWAP","instId":"ETH-USDT-SWAP","last":"3131","lastSz":"0.22","askPx":"3130.91","askSz":"0.03","bidPx":"3129.64","bidSz":"0.05","open24h":"3248","high24h":"3315.64","low24h":"3072.11","sodUtc0":"3108.41","sodUtc8":"3174.4","volCcy24h":"19460094.377","vol24h":"194600943.77","ts":"1765632001310"}]}
{"arg":{"channel":"books","instId":"ETH-USDT-SWAP"},"action":"update","data":[{"asks":[["3130.91","0","0","0"],["3131","2.48","0","1"],["3135.71","94.85","0","9"]],"bids":[["3129.59","0.03","0","1"],["3129.57","8.38","0","1"],["3123.98","0","0","0"]],"ts":"1765632001407","checksum":1587722890,"seqId":1158524936,"prevSeqId":1158524919}]}
{"arg":{"channel":"books5","instId":"ETH-USDT-SWAP"},"data":[{"asks":[["3131","2.48","0","1"],["3131.07","0.02","0","1"],["3131.18","0.04","0","1"],["3131.2","2.4","0","5"],["3131.23","0.07","0","1"]],"bids":[["3129.64","0.05","0","1"],["3129.59","0.03","0","1"],["3129.57","8.38","0","1"],["3129.55","0.67","0","1"],["3129.54","13.9","0","1"]],"instId":"ETH-USDT-SWAP","ts":"1765632001407","seqId":1158524936}]}
{"arg":{"channel":"bbo-tbt","instId":"ETH-USDT-SWAP"},"data":[{"asks":[["3131","2.42","0","1"]],"bids":[["3129.64","0.05","0","1"]],"ts":"1765632001417","seqId":1158524938}]}
{"arg":{"channel":"bbo-tbt","instId":"ETH-USDT-SWAP"},"data":[{"asks":[["3131","2.42","0","1"]],"bids":[["3129.57","8.35","0","1"]],"ts":"1765632001457","seqId":1158524944}]}
{"arg":{"channel":"bbo-tbt","instId":"ETH-USDT-SWAP"},"data":[{"asks":[["3130.91","0.03","0","1"]],"bids":[["3129.57","8.35","0","1"]],"ts":"1765632001467","seqId":1158524949}]}
{"arg":{"channel":"tickers","instId":"ETH-USDT-SWAP"},"data":[{"instType":"SWAP","instId":"ETH-USDT-SWAP","last":"3131","lastSz":"0.06","askPx":"3131","askSz":"2.42","bidPx":"3129.64","bidSz":"0.05","open24h":"3248","high24h":"3315.64","low24h":"3072.11","sodUtc0":"3108.41","sodUtc8":"3174.4","volCcy24h":"19460094.473","vol24h":"194600944.73","ts":"1765632001419"}]}
{"arg":{"channel":"bbo-tbt","instId":"ETH-USDT-SWAP"},"data":[{"asks":[["3130.91","0.03","0","1"]],"bids":[["3129.57","8.1","0","1"]],"ts":"1765632001487","seqId":1158524954}]}
{"arg":{"channel":"bbo-tbt","instId":"ETH-USDT-SWAP"},"data":[{"asks":[["3131","2.41","0","1"]],"bids":[["3129.57","8.1","0","1"]],"ts":"1765632001507","seqId":1158524976}]}
{"arg":{"channel":"books","instId":"ETH-USDT-SWAP"},"action":"update","data":[{"asks":[["3131","2.41","0","1"]],"bids":[["3129.64","0","0","0"],["3129.59","0","0","0"],["3129.57","8.1","0","1"],["3123.98","0.09","0","2"],["3123.97","0.18","0","1"]],"ts":"1765632001507","checksum":919157917,"seqId":1158524976,"prevSeqId":1158524936}]}
{"arg":{"channel":"books5","instId":"ETH-USDT-SWAP"},"data":[{"asks":[["3131","2.41","0","1"],["3131.07","0.02","0","1"],["3131.18","0.04","0","1"],["3131.2","2.4","0","5"],["3131.23","0.07","0","1"]],"bids":[["3129.57","8.1","0","1"],["3129.55","0.67","0","1"],["3129.54","13.9","0","1"],["3129.53","0.01","0","1"],["3129.5","0.03","0","3"]],"instId":"ETH-USDT-SWAP","ts":"1765632001507","seqId":1158524976}]}
{"arg":{"channel":"bbo-tbt","instId":"ETH-USDT-SWAP"},"data":[{"asks":[["3131","2.41","0","1"]],"bids":[["3129.64","0.05","0","1"]],"ts":"1765632001517","seqId":1158524980}]}
{"arg":{"channel":"bbo-tbt","instId":"ETH-USDT-SWAP"},"data":[{"asks":[["3131","2.33","0","1"]],"bids":[["3129.64","0.05","0","1"]],"ts":"1765632001547","seqId":1158524982}]}
{"arg":{"channel":"bbo-tbt","instId":"ETH-USDT-SWAP"},"data":[{"asks":[["3131","2.33","0","1"]],"bids":[["3129.57","7.91","0","1"]],"ts":"1765632001567","seqId":1158524988}]}
{"arg":{"channel":"bbo-tbt","instId":"ETH-USDT-SWAP"},"data":[{"asks":[["3130.91","0.03","0","1"]],"bids":[["3129.57","7.91","0","1"]],"ts":"1765632001577","seqId":1158524994}]}
{"arg":{"channel":"tickers","instId":"ETH-USDT-SWAP"},"data":[{"instType":"SWAP","instId":"ETH-USDT-SWAP","last":"3131","lastSz":"0.08","askPx":"3131","askSz":"2.33","bidPx":"3129.64","bidSz":"0.05","open24h":"3248","high24h":"3315.64","low24h":"3072.11","sodUtc0":"3108.41","sodUtc8":"3174.4","volCcy24h":"19460094.526","vol24h":"194600945.26","ts":"1765632001541"}]}
{"arg":{"channel":"books","instId":"ETH-USDT-SWAP"},"action":"update","data":[{"asks":[["3130.91","0.03","0","1"],["3130.99","0.05","0","1"],["3131","2.33","0","1"],["3135.7","0","0","0"],["3135.71","0","0","0"]],"bids":[["3129.57","7.91","0","1"]],"ts":"1765632001607","checksum":-2060131632,"seqId":1158524994,"prevSeqId":1158524976}]}
{"arg":{"channel":"books5","instId":"ETH-USDT-SWAP"},"data":[{"asks":[["3130.91","0.03","0","1"],["3130.99","0.05","0","1"],["3131","2.33","0","1"],["3131.07","0.02","0","1"],["3131.18","0.04","0","1"]],"bids":[["3129.57","7.91","0","1"],["3129.55","0.67","0","1"],["3129.54","13.9","0","1"],["3129.53","0.01","0","1"],["3129.5","0.03","0","3"]],"instId":"ETH-USDT-SWAP","ts":"1765632001607","seqId":1158524994}]}
{"arg":{"channel":"bbo-tbt","instId":"ETH-USDT-SWAP"},"data":[{"asks":[["3130.91","0.03","0","1"]],"bids":[["3129.57","7.79","0","1"]],"ts":"1765632001627","seqId":1158524996}]}
{"arg":{"channel":"bbo-tbt","instId":"ETH-USDT-SWAP"},"data":[{"asks":[["3130.91","0.03","0","1"]],"bids":[["3129.57","7.26","0","1"]],"ts":"1765632001687","seqId":1158524998}]}
{"arg":{"channel":"tickers","instId":"ETH-USDT-SWAP"},"data":[{"instType":"SWAP","instId":"ETH-USDT-SWAP","last":"3129.57","lastSz":"0.12","askPx":"3130.91","askSz":"0.03","bidPx":"3129.57","bidSz":"7.79","open24h":"3248","high24h":"3315.64","low24h":"3072.11","sodUtc0":"3108.41","sodUtc8":"3174.4","volCcy24h":"19460094.565","vol24h":"194600945.65","ts":"1765632001659"}]}
{"arg":{"channel":"bbo-tbt","instId":"ETH-USDT-SWAP"},"data":[{"asks":[["3131","2.04","0","1"]],"bids":[["3129.57","7.26","0","1"]],"ts":"1765632001707","seqId":1158525004}]}
{"arg":{"channel":"books","instId":"ETH-USDT-SWAP"},"action":"update","data":[{"asks":[["3130.91","0","0","0"],["3130.99","0","0","0"],["3131","2.04","0","1"],["3135.7","300.02","0","5"],["3135.71","94.85","0","9"]],"bids":[["3129.57","7.26","0","1"]],"ts":"1765632001707","checksum":-1943163765,"seqId":1158525004,"prevSeqId":1158524994}]}
{"arg":{"channel":"books5","instId":"ETH-USDT-SWAP"},"data":[{"asks":[["3131","2.04","0","1"],["3131.07","0.02","0","1"],["3131.18","0.04","0","1"],["3131.2","2.4","0","5"],["3131.23","0.07","0","1"]],"bids":[["3129.57","7.26","0","1"],["3129.55","0.67","0","1"],["3129.54","13.9","0","1"],["3129.53","0.01","0","1"],["3129.5","0.03","0","3"]],"instId":"ETH-USDT-SWAP","ts":"1765632001707","seqId":1158525004}]}
{"arg":{"channel":"bbo-tbt","instId":"ETH-USDT-SWAP"},"data":[{"asks":[["3131","2.04","0","1"]],"bids":[["3129.64","0.05","0","1"]],"ts":"1765632001717","seqId":1158525009}]}
{"arg":{"channel":"bbo-tbt","instId":"ETH-USDT-SWAP"},"data":[{"asks":[["3131","1.82","0","1"]],"bids":[["3129.64","0.05","0","1"]],"ts":"1765632001747","seqId":1158525012}]}
{"arg":{"channel":"bbo-tbt","instId":"ETH-USDT-SWAP"},"data":[{"asks":[["3129.57","12492.66","0","1"]],"bids":[["3129.55","0.67","0","1"]],"ts":"1765632001787","seqId":1158525019}]}
{"arg":{"channel":"books","instId":"ETH-USDT-SWAP"},"action":"update","data":[{"asks":[["3129.57","12492.66","0","1"],["3130.91","0.03","0","1"],["3130.99","0.05","0","1"],["3131","1.82","0","1"],["3131.01","25.5","0","1"],["3135.68","0","0","0"],["3135.69","0","0","0"],["3135.7","0","0","0"],["3135.71","0","0","0"]],"bids":[["3129.57","0","0","0"],["3123.95","0.75","0","3"]],"ts":"1765632001807","checksum":252933472,"seqId":1158525035,"prevSeqId":1158525004}]}
{"arg":{"channel":"books5","instId":"ETH-USDT-SWAP"},"data":[{"asks":[["3129.57","12492.66","0","1"],["3130.91","0.03","0","1"],["3130.99","0.05","0","1"],["3131","1.82","0","1"],["3131.01","25.5","0","1"]],"bids":[["3129.55","0.67","0","1"],["3129.54","13.9","0","1"],["3129.53","0.01","0","1"],["3129.5","0.03","0","3"],["3129.49","0.05","0","3"]],"instId":"ETH-USDT-SWAP","ts":"1765632001807","seqId":1158525035}]}
{"arg":{"channel":"bbo-tbt","instId":"ETH-USDT-SWAP"},"data":[{"asks":[["3129.57","12492.55","0","1"]],"bids":[["3129.55","0.67","0","1"]],"ts":"1765632001817","seqId":1158525037}]}
{"arg":{"channel":"bbo-tbt","instId":"ETH-USDT-SWAP"},"data":[{"asks":[["3129.57","12492.55","0","1"]],"bids":[["3129.35","12.08","0","1"]],"ts":"1765632001837","seqId":1158525086}]}
{"arg":{"channel":"tickers","instId":"ETH-USDT-SWAP"},"data":[{"instType":"SWAP","instId":"ETH-USDT-SWAP","last":"3129.64","lastSz":"0.05","askPx":"3131","askSz":"1.82","bidPx":"3129.59","bidSz":"0.03","open24h":"3248","high24h":"3315.64","low24h":"3072.11","sodUtc0":"3108.41","sodUtc8":"3174.4","volCcy24h":"19460094.682","vol24h":"194600946.82","ts":"1765632001786"}]}
{"arg":{"channel":"bbo-tbt","instId":"ETH-USDT-SWAP"},"data":[{"asks":[["3129.57","12492.46","0","1"]],"bids":[["3129.35","12.08","0","1"]],"ts":"1765632001867","seqId":1158525100}]}
{"arg":{"channel":"bbo-tbt","instId":"ETH-USDT-SWAP"},"data":[{"asks":[["3129.57","12492.38","0","1"]],"bids":[["3129.35","12.08","0","1"]],"ts":"1765632001877","seqId":1158525102}]}
{"arg":{"channel":"books","instId":"ETH-USDT-SWAP"},"action":"update","data":[{"asks":[["3129.57","12492.38","0","1"],["3130.65","0.01","0","1"],["3130.69","0.01","0","1"],["3130.77","0.05","0","3"],["3130.79","0.29","0","1"],["3130.86","13.9","0","1"],["3130.91","0.7","0","2"],["3130.94","0.01","0","1"],["3130.99","0.07","0","2"],["3131","1.85","0","4"],["3135.62","0","0","0"],["3135.63","0","0","0"],["3135.64","0","0","0"],["3135.65","0","0","0"],["3135.66","0","0","0"],["3135.67","0","0","0"]],"bids":[["3129.55","0","0","0"],["3129.54","0","0","0"],["3129.53","0","0","0"],["3129.5","0","0","0"],["3129.49","0","0","0"],["3129.47","0","0","0"],["3129.39","0","0","0"],["3129.37","0","0","0"],["3129.35","12.08","0","1"],["3123.94","4.8","0","5"],["3123.93","3085.25","0","2"],["3123.92","0.11","0","4"],["3123.9","1.88","0","2"],["3123.88","2.68","0","10"],["3123.87","34.79","0","6"],["3123.86","37.54","0","4"],["3123.85","6.16","0","6"]],"ts":"1765632001907","checksum":1675728945,"seqId":1158525103,"prevSeqId":1158525035}]}
{"arg":{"channel":"books5","instId":"ETH-USDT-SWAP"},"data":[{"asks":[["3129.57","12492.38","0","1"],["3130.65","0.01","0","1"],["3130.69","0.01","0","1"],["3130.77","0.05","0","3"],["3130.79","0.29","0","1"]],"bids":[["3129.35","12.08","0","1"],["3129.33","50.04","0","1"],["3129.3","30.16","0","2"],["3129.27","0.01","0","1"],["3129.25","0.09","0","1"]],"instId":"ETH-USDT-SWAP","ts":"1765632001907","seqId":1158525103}]}
{"arg":{"channel":"bbo-tbt","instId":"ETH-USDT-SWAP"},"data":[{"asks":[["3129.57","12492.29","0","1"]],"bids":[["3129.35","12.08","0","1"]],"ts":"1765632001917","seqId":1158525105}]}
{"arg":{"channel":"tickers","instId":"ETH-USDT-SWAP"},"data":[{"instType":"SWAP","instId":"ETH-USDT-SWAP","last":"3129.57","lastSz":"0.08","askPx":"3129.57","askSz":"12492.38","bidPx":"3129.35","bidSz":"12.08","open24h":"3248","high24h":"3315.64","low24h":"3072.11","sodUtc0":"3108.41","sodUtc8":"3174.4","volCcy24h":"19460097.329","vol24h":"194600973.29","ts":"1765632001910"}]}
{"arg":{"channel":"bbo-tbt","instId":"ETH-USDT-SWAP"},"data":[{"asks":[["3129.57","12492.17","0","1"]],"bids":[["3129.35","12.08","0","1"]],"ts":"1765632002007","seqId":1158525135}]}
{"arg":{"channel":"books","instId":"ETH-USDT-SWAP"},"action":"update","data":[{"asks":[["3129.57","12492.17","0","1"]],"bids":[],"ts":"1765632002007","checksum":-2127402832,"seqId":1158525135,"prevSeqId":1158525103}]}
{"arg":{"channel":"books5","instId":"ETH-USDT-SWAP"},"data":[{"asks":[["3129.57","12492.17","0","1"],["3130.65","0.01","0","1"],["3130.69","0.01","0","1"],["3130.77","0.05","0","3"],["3130.79","0.29","0","1"]],"bids":[["3129.35","12.08","0","1"],["3129.33","50.04","0","1"],["3129.3","30.16","0","2"],["3129.27","0.01","0","1"],["3129.25","0.09","0","1"]],"instId":"ETH-USDT-SWAP","ts":"1765632002007","seqId":1158525135}]}
{"arg":{"channel":"bbo-tbt","instId":"ETH-USDT-SWAP"},"data":[{"asks":[["3129.57","12492.11","0","1"]],"bids":[["3129.35","12.08","0","1"]],"ts":"1765632002047","seqId":1158525137}]}
{"arg":{"channel":"tickers","instId":"ETH-USDT-SWAP"},"data":[{"instType":"SWAP","instId":"ETH-USDT-SWAP","last":"3129.57","lastSz":"0.12","askPx":"3129.57","askSz":"12492.17","bidPx":"3129.35","bidSz":"12.08","open24h":"3248","high24h":"3315.64","low24h":"3072.11","sodUtc0":"3108.41","sodUtc8":"3174.4","volCcy24h":"19460097.35","vol24h":"194600973.5","ts":"1765632002011"}]}
{"arg":{"channel":"bbo-tbt","instId":"ETH-USDT-SWAP"},"data":[{"asks":[["3129.57","12492.01","0","1"]],"bids":[["3129.35","12.08","0","1"]],"ts":"1765632002087","seqId":1158525139}]}
{"arg":{"channel":"books","instId":"ETH-USDT-SWAP"},"action":"update","data":[{"asks":[["3129.57","12492.01","0","1"]],"bids":[],"ts":"1765632002107","checksum":-1947819099,"seqId":1158525139,"prevSeqId":1158525135}]}
{"arg":{"channel":"books5","instId":"ETH-USDT-SWAP"},"data":[{"asks":[["3129.57","12492.01","0","1"],["3130.65","0.01","0","1"],["3130.69","0.01","0","1"],["3130.77","0.05","0","3"],["3130.79","0.29","0","1"]],"bids":[["3129.35","12.08","0","1"],["3129.33","50.04","0","1"],["3129.3","30.16","0","2"],["3129.27","0.01","0","1"],["3129.25","0.09","0","1"]],"instId":"ETH-USDT-SWAP","ts":"1765632002107","seqId":1158525139}]}
{"arg":{"channel":"tickers","instId":"ETH-USDT-SWAP"},"data":[{"instType":"SWAP","instId":"ETH-USDT-SWAP","last":"3129.57","lastSz":"0.1","askPx":"3129.57","askSz":"12492.01","bidPx":"3129.35","bidSz":"12.08","open24h":"3248","high24h":"3315.64","low24h":"3072.11","sodUtc0":"3108.41","sodUtc8":"3174.4","volCcy24h":"19460097.366","vol24h":"194600973.66","ts":"1765632002165"}]}
{"arg":{"channel":"bbo-tbt","instId":"ETH-USDT-SWAP"},"data":[{"asks":[["3129.57","12491.88","0","1"]],"bids":[["3129.35","12.08","0","1"]],"ts":"1765632002247","seqId":1158525155}]}
{"arg":{"channel":"books","instId":"ETH-USDT-SWAP"},"action":"update","data":[{"asks":[["3129.57","12491.88","0","1"]],"bids":[],"ts":"1765632002307","checksum":1437693971,"seqId":1158525159,"prevSeqId":1158525139}]}
{"arg":{"channel":"books5","instId":"ETH-USDT-SWAP"},"data":[{"asks":[["3129.57","12491.88","0","1"],["3130.65","0.01","0","1"],["3130.69","0.01","0","1"],["3130.77","0.05","0","3"],["3130.79","0.29","0","1"]],"bids":[["3129.35","12.08","0","1"],["3129.33","50.04","0","1"],["3129.3","30.16","0","2"],["3129.27","0.01","0","1"],["3129.25","0.09","0","1"]],"instId":"ETH-USDT-SWAP","ts":"1765632002307","seqId":1158525159}]}
{"arg":{"channel":"bbo-tbt","instId":"ETH-USDT-SWAP"},"data":[{"asks":[["3129.57","12491.78","0","1"]],"bids":[["3129.35","12.08","0","1"]],"ts":"1765632002337","seqId":1158525161}]}
{"arg":{"channel":"bbo-tbt","instId":"ETH-USDT-SWAP"},"data":[{"asks":[["3129.57","12491.45","0","1"]],"bids":[["3129.35","12.08","0","1"]],"ts":"1765632002347","seqId":1158525166}]}
{"arg":{"channel":"bbo-tbt","instId":"ETH-USDT-SWAP"},"data":[{"asks":[["3129.57","12491.33","0","1"]],"bids":[["3129.35","12.08","0","1"]],"ts":"1765632002387","seqId":1158525169}]}
{"arg":{"channel":"bbo-tbt","instId":"ETH-USDT-SWAP"},"data":[{"asks":[["3129.57","12491.26","0","1"]],"bids":[["3129.35","12.08","0","1"]],"ts":"1765632002407","seqId":1158525171}]}
{"arg":{"channel":"books","instId":"ETH-USDT-SWAP"},"action":"update","data":[{"asks":[["3129.57","12491.26","0","1"]],"bids":[],"ts":"1765632002407","checksum":1922912613,"seqId":1158525171,"prevSeqId":1158525159}]}
{"arg":{"channel":"books5","instId":"ETH-USDT-SWAP"},"data":[{"asks":[["3129.57","12491.26","0","1"],["3130.65","0.01","0","1"],["3130.69","0.01","0","1"],["3130.77","0.05","0","3"],["3130.79","0.29","0","1"]],"bids":[["3129.35","12.08","0","1"],["3129.33","50.04","0","1"],["3129.3","30.16","0","2"],["3129.27","0.01","0","1"],["3129.25","0.09","0","1"]],"instId":"ETH-USDT-SWAP","ts":"1765632002407","seqId":1158525171}]}
{"arg":{"channel":"tickers","instId":"ETH-USDT-SWAP"},"data":[{"instType":"SWAP","instId":"ETH-USDT-SWAP","last":"3129.57","lastSz":"0.13","askPx":"3129.57","askSz":"12491.88","bidPx":"3129.35","bidSz":"12.08","open24h":"3248","high24h":"3315.64","low24h":"3072.11","sodUtc0":"3108.41","sodUtc8":"3174.4","volCcy24h":"19460097.379","vol24h":"194600973.79","ts":"1765632002305"}]}
{"arg":{"channel":"bbo-tbt","instId":"ETH-USDT-SWAP"},"data":[{"asks":[["3129.57","12491.18","0","1"]],"bids":[["3129.35","12.08","0","1"]],"ts":"1765632002447","seqId":1158525173}]}
{"arg":{"channel":"bbo-tbt","instId":"ETH-USDT-SWAP"},"data":[{"asks":[["3129.57","12490.94","0","1"]],"bids":[["3129.35","12.08","0","1"]],"ts":"1765632002467","seqId":1158525175}]}
{"arg":{"channel":"bbo-tbt","instId":"ETH-USDT-SWAP"},"data":[{"asks":[["3129.57","12490.87","0","1"]],"bids":[["3129.35","12.08","0","1"]],"ts":"1765632002507","seqId":1158525177}]}
{"arg":{"channel":"books","instId":"ETH-USDT-SWAP"},"action":"update","data":[{"asks":[["3129.57","12490.87","0","1"]],"bids":[],"ts":"1765632002507","checksum":-67709627,"seqId":1158525177,"prevSeqId":1158525171}]}
{"arg":{"channel":"books5","instId":"ETH-USDT-SWAP"},"data":[{"asks":[["3129.57","12490.87","0","1"],["3130.65","0.01","0","1"],["3130.69","0.01","0","1"],["3130.77","0.05","0","3"],["3130.79","0.29","0","1"]],"bids":[["3129.35","12.08","0","1"],["3129.33","50.04","0","1"],["3129.3","30.16","0","2"],["3129.27","0.01","0","1"],["3129.25","0.09","0","1"]],"instId":"ETH-USDT-SWAP","ts":"1765632002507","seqId":1158525177}]}
{"arg":{"channel":"tickers","instId":"ETH-USDT-SWAP"},"data":[{"instType":"SWAP","instId":"ETH-USDT-SWAP","last":"3129.57","lastSz":"0.07","askPx":"3129.57","askSz":"12491.26","bidPx":"3129.35","bidSz":"12.08","open24h":"3248","high24h":"3315.64","low24h":"3072.11","sodUtc0":"3108.41","sodUtc8":"3174.4","volCcy24h":"19460097.441","vol24h":"194600974.41","ts":"1765632002406"}]}
{"arg":{"channel":"bbo-tbt","instId":"ETH-USDT-SWAP"},"data":[{"asks":[["3129.57","12490.81","0","1"]],"bids":[["3129.35","12.08","0","1"]],"ts":"1765632002527","seqId":1158525179}]}
{"arg":{"channel":"bbo-tbt","instId":"ETH-USDT-SWAP"},"data":[{"asks":[["3129.57","12490.68","0","1"]],"bids":[["3129.35","12.08","0","1"]],"ts":"1765632002547","seqId":1158525181}]}
{"arg":{"channel":"bbo-tbt","instId":"ETH-USDT-SWAP"},"data":[{"asks":[["3129.57","12490.57","0","1"]],"bids":[["3129.35","12.08","0","1"]],"ts":"1765632002587","seqId":1158525183}]}
{"arg":{"channel":"bbo-tbt","instId":"ETH-USDT-SWAP"},"data":[{"asks":[["3129.57","12490.44","0","1"]],"bids":[["3129.35","12.08","0","1"]],"ts":"1765632002597","seqId":1158525185}]}
{"arg":{"channel":"books","instId":"ETH-USDT-SWAP"},"action":"update","data":[{"asks":[["3129.57","12490.44","0","1"]],"bids":[],"ts":"1765632002607","checksum":-802048585,"seqId":1158525185,"prevSeqId":1158525177}]}
{"arg":{"channel":"books5","instId":"ETH-USDT-SWAP"},"data":[{"asks":[["3129.57","12490.44","0","1"],["3130.65","0.01","0","1"],["3130.69","0.01","0","1"],["3130.77","0.05","0","3"],["3130.79","0.29","0","1"]],"bids":[["3129.35","12.08","0","1"],["3129.33","50.04","0","1"],["3129.3","30.16","0","2"],["3129.27","0.01","0","1"],["3129.25","0.09","0","1"]],"instId":"ETH-USDT-SWAP","ts":"1765632002607","seqId":1158525185}]}
{"arg":{"channel":"tickers","instId":"ETH-USDT-SWAP"},"data":[{"instType":"SWAP","instId":"ETH-USDT-SWAP","last":"3129.57","lastSz":"0.07","askPx":"3129.57","askSz":"12490.87","bidPx":"3129.35","bidSz":"12.08","open24h":"3248","high24h":"3315.64","low24h":"3072.11","sodUtc0":"3108.41","sodUtc8":"3174.4","volCcy24h":"19460097.48","vol24h":"194600974.8","ts":"1765632002510"}]}
{"arg":{"channel":"bbo-tbt","instId":"ETH-USDT-SWAP"},"data":[{"asks":[["3129.57","12490.21","0","1"]],"bids":[["3129.35","12.08","0","1"]],"ts":"1765632002637","seqId":1158525189}]}
{"arg":{"channel":"bbo-tbt","instId":"ETH-USDT-SWAP"},"data":[{"asks":[["3129.57","12490.13","0","1"]],"bids":[["3129.35","12.08","0","1"]],"ts":"1765632002667","seqId":1158525191}]}
{"arg":{"channel":"tickers","instId":"ETH-USDT-SWAP"},"data":[{"instType":"SWAP","instId":"ETH-USDT-SWAP","last":"3129.57","lastSz":"0.08","askPx":"3129.57","askSz":"12490.36","bidPx":"3129.35","bidSz":"12.08","open24h":"3248","high24h":"3315.64","low24h":"3072.11","sodUtc0":"3108.41","sodUtc8":"3174.4","volCcy24h":"19460097.531","vol24h":"194600975.31","ts":"1765632002632"}]}
{"arg":{"channel":"books","instId":"ETH-USDT-SWAP"},"action":"update","data":[{"asks":[["3129.57","12490.13","0","1"]],"bids":[],"ts":"1765632002707","checksum":-1012424436,"seqId":1158525191,"prevSeqId":1158525185}]}
{"arg":{"channel":"books5","instId":"ETH-USDT-SWAP"},"data":[{"asks":[["3129.57","12490.13","0","1"],["3130.65","0.01","0","1"],["3130.69","0.01","0","1"],["3130.77","0.05","0","3"],["3130.79","0.29","0","1"]],"bids":[["3129.35","12.08","0","1"],["3129.33","50.04","0","1"],["3129.3","30.16","0","2"],["3129.27","0.01","0","1"],["3129.25","0.09","0","1"]],"instId":"ETH-USDT-SWAP","ts":"1765632002707","seqId":1158525191}]}
{"arg":{"channel":"bbo-tbt","instId":"ETH-USDT-SWAP"},"data":[{"asks":[["3129.57","12490.01","0","1"]],"bids":[["3129.35","12.08","0","1"]],"ts":"1765632002747","seqId":1158525193}]}
{"arg":{"channel":"bbo-tbt","instId":"ETH-USDT-SWAP"},"data":[{"asks":[["3129.57","12489.94","0","1"]],"bids":[["3129.35","12.08","0","1"]],"ts":"1765632002757","seqId":1158525195}]}
{"arg":{"channel":"books","instId":"ETH-USDT-SWAP"},"action":"update","data":[{"asks":[["3129.57","12489.94","0","1"]],"bids":[],"ts":"1765632002807","checksum":1421915093,"seqId":1158525195,"prevSeqId":1158525191}]}
{"arg":{"channel":"books5","instId":"ETH-USDT-SWAP"},"data":[{"asks":[["3129.57","12489.94","0","1"],["3130.65","0.01","0","1"],["3130.69","0.01","0","1"],["3130.77","0.05","0","3"],["3130.79","0.29","0","1"]],"bids":[["3129.35","12.08","0","1"],["3129.33","50.04","0","1"],["3129.3","30.16","0","2"],["3129.27","0.01","0","1"],["3129.25","0.09","0","1"]],"instId":"ETH-USDT-SWAP","ts":"1765632002807","seqId":1158525195}]}
{"arg":{"channel":"bbo-tbt","instId":"ETH-USDT-SWAP"},"data":[{"asks":[["3129.57","12489.7","0","1"]],"bids":[["3129.35","12.08","0","1"]],"ts":"1765632002837","seqId":1158525197}]}
{"arg":{"channel":"tickers","instId":"ETH-USDT-SWAP"},"data":[{"instType":"SWAP","instId":"ETH-USDT-SWAP","last":"3129.57","lastSz":"0.12","askPx":"3129.57","askSz":"12490.01","bidPx":"3129.35","bidSz":"12.08","open24h":"3248","high24h":"3315.64","low24h":"3072.11","sodUtc0":"3108.41","sodUtc8":"3174.4","volCcy24h":"19460097.566","vol24h":"194600975.66","ts":"1765632002748"}]}
{"arg":{"channel":"books","instId":"ETH-USDT-SWAP"},"action":"update","data":[{"asks":[["3129.57","12489.7","0","1"]],"bids":[],"ts":"1765632002907","checksum":1945266922,"seqId":1158525197,"prevSeqId":1158525195}]}
{"arg":{"channel":"books5","instId":"ETH-USDT-SWAP"},"data":[{"asks":[["3129.57","12489.7","0","1"],["3130.65","0.01","0","1"],["3130.69","0.01","0","1"],["3130.77","0.05","0","3"],["3130.79","0.29","0","1"]],"bids":[["3129.35","12.08","0","1"],["3129.33","50.04","0","1"],["3129.3","30.16","0","2"],["3129.27","0.01","0","1"],["3129.25","0.09","0","1"]],"instId":"ETH-USDT-SWAP","ts":"1765632002907","seqId":1158525197}]}
{"arg":{"channel":"bbo-tbt","instId":"ETH-USDT-SWAP"},"data":[{"asks":[["3129.57","12489.59","0","1"]],"bids":[["3129.35","12.08","0","1"]],"ts":"1765632002947","seqId":1158525199}]}
{"arg":{"channel":"bbo-tbt","instId":"ETH-USDT-SWAP"},"data":[{"asks":[["3129.57","12489.51","0","1"]],"bids":[["3129.35","12.08","0","1"]],"ts":"1765632002967","seqId":1158525201}]}
{"arg":{"channel":"tickers","instId":"ETH-USDT-SWAP"},"data":[{"instType":"SWAP","instId":"ETH-USDT-SWAP","last":"3129.57","lastSz":"0.24","askPx":"3129.57","askSz":"12489.7","bidPx":"3129.35","bidSz":"12.08","open24h":"3248","high24h":"3315.64","low24h":"3072.11","sodUtc0":"3108.41","sodUtc8":"3174.4","volCcy24h":"19460097.597","vol24h":"194600975.97","ts":"1765632002868"}]}
{"arg":{"channel":"bbo-tbt","instId":"ETH-USDT-SWAP"},"data":[{"asks":[["3129.57","12489.51","0","1"]],"bids":[["3129.35","11.96","0","1"]],"ts":"1765632002987","seqId":1158525203}]}
{"arg":{"channel":"bbo-tbt","instId":"ETH-USDT-SWAP"},"data":[{"asks":[["3129.57","12489.36","0","1"]],"bids":[["3129.35","11.96","0","1"]],"ts":"1765632002997","seqId":1158525205}]}
{"arg":{"channel":"books","instId":"ETH-USDT-SWAP"},"action":"update","data":[{"asks":[["3129.57","12489.36","0","1"]],"bids":[["3129.35","11.96","0","1"]],"ts":"1765632003007","checksum":-956918095,"seqId":1158525205,"prevSeqId":1158525197}]}
{"arg":{"channel":"books5","instId":"ETH-USDT-SWAP"},"data":[{"asks":[["3129.57","12489.36","0","1"],["3130.65","0.01","0","1"],["3130.69","0.01","0","1"],["3130.77","0.05","0","3"],["3130.79","0.29","0","1"]],"bids":[["3129.35","11.96","0","1"],["3129.33","50.04","0","1"],["3129.3","30.16","0","2"],["3129.27","0.01","0","1"],["3129.25","0.09","0","1"]],"instId":"ETH-USDT-SWAP","ts":"1765632003007","seqId":1158525205}]}
{"arg":{"channel":"bbo-tbt","instId":"ETH-USDT-SWAP"},"data":[{"asks":[["3129.57","12489.28","0","1"]],"bids":[["3129.35","11.96","0","1"]],"ts":"1765632003017","seqId":1158525207}]}
{"arg":{"channel":"tickers","instId":"ETH-USDT-SWAP"},"data":[{"instType":"SWAP","instId":"ETH-USDT-SWAP","last":"3129.35","lastSz":"0.12","askPx":"3129.57","askSz":"12489.51","bidPx":"3129.35","bidSz":"11.96","open24h":"3248","high24h":"3315.64","low24h":"3072.11","sodUtc0":"3108.41","sodUtc8":"3174.4","volCcy24h":"19460097.628","vol24h":"194600976.28","ts":"1765632002988"}]}
{"arg":{"channel":"books","instId":"ETH-USDT-SWAP"},"action":"update","data":[{"asks":[["3129.57","12489.28","0","1"]],"bids":[],"ts":"1765632003107","checksum":-2117027440,"seqId":1158525207,"prevSeqId":1158525205}]}
{"arg":{"channel":"books5","instId":"ETH-USDT-SWAP"},"data":[{"asks":[["3129.57","12489.28","0","1"],["3130.65","0.01","0","1"],["3130.69","0.01","0","1"],["3130.77","0.05","0","3"],["3130.79","0.29","0","1"]],"bids":[["3129.35","11.96","0","1"],["3129.33","50.04","0","1"],["3129.3","30.16","0","2"],["3129.27","0.01","0","1"],["3129.25","0.09","0","1"]],"instId":"ETH-USDT-SWAP","ts":"1765632003107","seqId":1158525207}]}
{"arg":{"channel":"bbo-tbt","instId":"ETH-USDT-SWAP"},"data":[{"asks":[["3129.57","12489.19","0","1"]],"bids":[["3129.35","11.96","0","1"]],"ts":"1765632003187","seqId":1158525249}]}
{"arg":{"channel":"tickers","instId":"ETH-USDT-SWAP"},"data":[{"instType":"SWAP","instId":"ETH-USDT-SWAP","last":"3129.57","lastSz":"0.08","askPx":"3129.57","askSz":"12489.28","bidPx":"3129.35","bidSz":"11.96","open24h":"3248","high24h":"3315.64","low24h":"3072.11","sodUtc0":"3108.41","sodUtc8":"3174.4","volCcy24h":"19460097.651","vol24h":"194600976.51","ts":"1765632003110"}]}
{"arg":{"channel":"books","instId":"ETH-USDT-SWAP"},"action":"update","data":[{"asks":[["3129.57","12489.19","0","1"]],"bids":[],"ts":"1765632003207","checksum":606430768,"seqId":1158525249,"prevSeqId":1158525207}]}
{"arg":{"channel":"books5","instId":"ETH-USDT-SWAP"},"data":[{"asks":[["3129.57","12489.19","0","1"],["3130.65","0.01","0","1"],["3130.69","0.01","0","1"],["3130.77","0.05","0","3"],["3130.79","0.29","0","1"]],"bids":[["3129.35","11.96","0","1"],["3129.33","50.04","0","1"],["3129.3","30.16","0","2"],["3129.27","0.01","0","1"],["3129.25","0.09","0","1"]],"instId":"ETH-USDT-SWAP","ts":"1765632003207","seqId":1158525249}]}
{"arg":{"channel":"bbo-tbt","instId":"ETH-USDT-SWAP"},"data":[{"asks":[["3129.57","12489.09","0","1"]],"bids":[["3129.35","11.96","0","1"]],"ts":"1765632003237","seqId":1158525251}]}
{"arg":{"channel":"tickers","instId":"ETH-USDT-SWAP"},"data":[{"instType":"SWAP","instId":"ETH-USDT-SWAP","last":"3129.57","lastSz":"0.1","askPx":"3129.57","askSz":"12489.09","bidPx":"3129.35","bidSz":"11.96","open24h":"3248","high24h":"3315.64","low24h":"3072.11","sodUtc0":"3108.41","sodUtc8":"3174.4","volCcy24h":"19460097.67","vol24h":"194600976.7","ts":"1765632003234"}]}
{"arg":{"channel":"bbo-tbt","instId":"ETH-USDT-SWAP"},"data":[{"asks":[["3129.57","12488.98","0","1"]],"bids":[["3129.35","11.96","0","1"]],"ts":"1765632003307","seqId":1158525253}]}
{"arg":{"channel":"books","instId":"ETH-USDT-SWAP"},"action":"update","data":[{"asks":[["3129.57","12488.98","0","1"]],"bids":[],"ts":"1765632003307","checksum":-739450348,"seqId":1158525253,"prevSeqId":1158525249}]}
{"arg":{"channel":"books5","instId":"ETH-USDT-SWAP"},"data":[{"asks":[["3129.57","12488.98","0","1"],["3130.65","0.01","0","1"],["3130.69","0.01","0","1"],["3130.77","0.05","0","3"],["3130.79","0.29","0","1"]],"bids":[["3129.35","11.96","0","1"],["3129.33","50.04","0","1"],["3129.3","30.16","0","2"],["3129.27","0.01","0","1"],["3129.25","0.09","0","1"]],"instId":"ETH-USDT-SWAP","ts":"1765632003307","seqId":1158525253}]}
{"arg":{"channel":"bbo-tbt","instId":"ETH-USDT-SWAP"},"data":[{"asks":[["3129.57","12488.98","0","1"]],"bids":[["3129.35","11.43","0","1"]],"ts":"1765632003357","seqId":1158525255}]}
{"arg":{"channel":"books","instId":"ETH-USDT-SWAP"},"action":"update","data":[{"asks":[],"bids":[["3129.35","11.43","0","1"]],"ts":"1765632003407","checksum":779801365,"seqId":1158525255,"prevSeqId":1158525253}]}
{"arg":{"channel":"books5","instId":"ETH-USDT-SWAP"},"data":[{"asks":[["3129.57","12488.98","0","1"],["3130.65","0.01","0","1"],["3130.69","0.01","0","1"],["3130.77","0.05","0","3"],["3130.79","0.29","0","1"]],"bids":[["3129.35","11.43","0","1"],["3129.33","50.04","0","1"],["3129.3","30.16","0","2"],["3129.27","0.01","0","1"],["3129.25","0.09","0","1"]],"instId":"ETH-USDT-SWAP","ts":"1765632003407","seqId":1158525255}]}
{"arg":{"channel":"tickers","instId":"ETH-USDT-SWAP"},"data":[{"instType":"SWAP","instId":"ETH-USDT-SWAP","last":"3129.35","lastSz":"0.53","askPx":"3129.57","askSz":"12488.98","bidPx":"3129.35","bidSz":"11.43","open24h":"3248","high24h":"3315.64","low24h":"3072.11","sodUtc0":"3108.41","sodUtc8":"3174.4","volCcy24h":"19460097.734","vol24h":"194600977.34","ts":"1765632003354"}]}
{"arg":{"channel":"bbo-tbt","instId":"ETH-USDT-SWAP"},"data":[{"asks":[["3129.57","12488.51","0","1"]],"bids":[["3129.35","11.43","0","1"]],"ts":"1765632003437","seqId":1158525259}]}
{"arg":{"channel":"bbo-tbt","instId":"ETH-USDT-SWAP"},"data":[{"asks":[["3129.57","12488.28","0","1"]],"bids":[["3129.35","11.43","0","1"]],"ts":"1765632003447","seqId":1158525261}]}
{"arg":{"channel":"books","instId":"ETH-USDT-SWAP"},"action":"update","data":[{"asks":[["3129.57","12488.28","0","1"]],"bids":[],"ts":"1765632003507","checksum":1316017474,"seqId":1158525261,"prevSeqId":1158525255}]}
{"arg":{"channel":"books5","instId":"ETH-USDT-SWAP"},"data":[{"asks":[["3129.57","12488.28","0","1"],["3130.65","0.01","0","1"],["3130.69","0.01","0","1"],["3130.77","0.05","0","3"],["3130.79","0.29","0","1"]],"bids":[["3129.35","11.43","0","1"],["3129.33","50.04","0","1"],["3129.3","30.16","0","2"],["3129.27","0.01","0","1"],["3129.25","0.09","0","1"]],"instId":"ETH-USDT-SWAP","ts":"1765632003507","seqId":1158525261}]}
{"arg":{"channel":"tickers","instId":"ETH-USDT-SWAP"},"data":[{"instType":"SWAP","instId":"ETH-USDT-SWAP","last":"3129.57","lastSz":"0.23","askPx":"3129.57","askSz":"12488.28","bidPx":"3129.35","bidSz":"11.43","open24h":"3248","high24h":"3315.64","low24h":"3072.11","sodUtc0":"3108.41","sodUtc8":"3174.4","volCcy24h":"19460097.804","vol24h":"194600978.04","ts":"1765632003500"}]}
{"arg":{"channel":"bbo-tbt","instId":"ETH-USDT-SWAP"},"data":[{"asks":[["3129.57","12488.21","0","1"]],"bids":[["3129.35","11.43","0","1"]],"ts":"1765632003527","seqId":1158525263}]}
{"arg":{"channel":"bbo-tbt","instId":"ETH-USDT-SWAP"},"data":[{"asks":[["3129.57","12488","0","1"]],"bids":[["3129.35","11.43","0","1"]],"ts":"1765632003547","seqId":1158525267}]}
{"arg":{"channel":"bbo-tbt","instId":"ETH-USDT-SWAP"},"data":[{"asks":[["3129.57","12487.94","0","1"]],"bids":[["3129.35","11.43","0","1"]],"ts":"1765632003597","seqId":1158525281}]}
{"arg":{"channel":"books","instId":"ETH-USDT-SWAP"},"action":"update","data":[{"asks":[["3129.57","12487.94","0","1"]],"bids":[],"ts":"1765632003607","checksum":-1859044133,"seqId":1158525281,"prevSeqId":1158525261}]}
{"arg":{"channel":"books5","instId":"ETH-USDT-SWAP"},"data":[{"asks":[["3129.57","12487.94","0","1"],["3130.65","0.01","0","1"],["3130.69","0.01","0","1"],["3130.77","0.05","0","3"],["3130.79","0.29","0","1"]],"bids":[["3129.35","11.43","0","1"],["3129.33","50.04","0","1"],["3129.3","30.16","0","2"],["3129.27","0.01","0","1"],["3129.25","0.09","0","1"]],"instId":"ETH-USDT-SWAP","ts":"1765632003607","seqId":1158525281}]}
{"arg":{"channel":"tickers","instId":"ETH-USDT-SWAP"},"data":[{"instType":"SWAP","instId":"ETH-USDT-SWAP","last":"3129.57","lastSz":"0.06","askPx":"3129.57","askSz":"12487.94","bidPx":"3129.35","bidSz":"11.43","open24h":"3248","high24h":"3315.64","low24h":"3072.11","sodUtc0":"3108.41","sodUtc8":"3174.4","volCcy24h":"19460097.838","vol24h":"194600978.38","ts":"1765632003610"}]}
{"arg":{"channel":"bbo-tbt","instId":"ETH-USDT-SWAP"},"data":[{"asks":[["3129.57","12487.86","0","1"]],"bids":[["3129.35","11.43","0","1"]],"ts":"1765632003707","seqId":1158525311}]}
{"arg":{"channel":"books","instId":"ETH-USDT-SWAP"},"action":"update","data":[{"asks":[["3129.57","12487.86","0","1"]],"bids":[],"ts":"1765632003707","checksum":-1122204204,"seqId":1158525311,"prevSeqId":1158525281}]}
{"arg":{"channel":"books5","instId":"ETH-USDT-SWAP"},"data":[{"asks":[["3129.57","12487.86","0","1"],["3130.65","0.01","0","1"],["3130.69","0.01","0","1"],["3130.77","0.05","0","3"],["3130.79","0.29","0","1"]],"bids":[["3129.35","11.43","0","1"],["3129.33","50.04","0","1"],["3129.3","30.16","0","2"],["3129.27","0.01","0","1"],["3129.25","0.09","0","1"]],"instId":"ETH-USDT-SWAP","ts":"1765632003707","seqId":1158525311}]}
{"arg":{"channel":"bbo-tbt","instId":"ETH-USDT-SWAP"},"data":[{"asks":[["3129.57","12487.78","0","1"]],"bids":[["3129.35","11.43","0","1"]],"ts":"1765632003797","seqId":1158525315}]}
{"arg":{"channel":"books","instId":"ETH-USDT-SWAP"},"action":"update","data":[{"asks":[["3129.57","12487.78","0","1"]],"bids":[],"ts":"1765632003807","checksum":1478864040,"seqId":1158525315,"prevSeqId":1158525311}]}
{"arg":{"channel":"books5","instId":"ETH-USDT-SWAP"},"data":[{"asks":[["3129.57","12487.78","0","1"],["3130.65","0.01","0","1"],["3130.69","0.01","0","1"],["3130.77","0.05","0","3"],["3130.79","0.29","0","1"]],"bids":[["3129.35","11.43","0","1"],["3129.33","50.04","0","1"],["3129.3","30.16","0","2"],["3129.27","0.01","0","1"],["3129.25","0.09","0","1"]],"instId":"ETH-USDT-SWAP","ts":"1765632003807","seqId":1158525315}]}
{"arg":{"channel":"bbo-tbt","instId":"ETH-USDT-SWAP"},"data":[{"asks":[["3129.57","12487.71","0","1"]],"bids":[["3129.33","38.71","0","1"]],"ts":"1765632003837","seqId":1158525329}]}
{"arg":{"channel":"tickers","instId":"ETH-USDT-SWAP"},"data":[{"instType":"SWAP","instId":"ETH-USDT-SWAP","last":"3129.57","lastSz":"0.08","askPx":"3129.57","askSz":"12487.86","bidPx":"3129.35","bidSz":"11.43","open24h":"3248","high24h":"3315.64","low24h":"3072.11","sodUtc0":"3108.41","sodUtc8":"3174.4","volCcy24h":"19460097.846","vol24h":"194600978.46","ts":"1765632003765"}]}
{"arg":{"channel":"bbo-tbt","instId":"ETH-USDT-SWAP"},"data":[{"asks":[["3129.57","12487.65","0","1"]],"bids":[["3129.33","38.71","0","1"]],"ts":"1765632003847","seqId":1158525331}]}
{"arg":{"channel":"bbo-tbt","instId":"ETH-USDT-SWAP"},"data":[{"asks":[["3129.57","12487.41","0","1"]],"bids":[["3129.33","38.71","0","1"]],"ts":"1765632003907","seqId":1158525333}]}
{"arg":{"channel":"books","instId":"ETH-USDT-SWAP"},"action":"update","data":[{"asks":[["3129.57","12487.41","0","1"],["3131.19","15.99","0","1"],["3135.61","0","0","0"]],"bids":[["3129.35","0","0","0"],["3129.33","38.71","0","1"],["3123.84","17","0","2"]],"ts":"1765632003907","checksum":-512936682,"seqId":1158525333,"prevSeqId":1158525315}]}
{"arg":{"channel":"books5","instId":"ETH-USDT-SWAP"},"data":[{"asks":[["3129.57","12487.41","0","1"],["3130.65","0.01","0","1"],["3130.69","0.01","0","1"],["3130.77","0.05","0","3"],["3130.79","0.29","0","1"]],"bids":[["3129.33","38.71","0","1"],["3129.3","30.16","0","2"],["3129.27","0.01","0","1"],["3129.25","0.09","0","1"],["3129.2","0.94","0","2"]],"instId":"ETH-USDT-SWAP","ts":"1765632003907","seqId":1158525333}]}
{"arg":{"channel":"tickers","instId":"ETH-USDT-SWAP"},"data":[{"instType":"SWAP","instId":"ETH-USDT-SWAP","last":"3129.57","lastSz":"0.06","askPx":"3129.57","askSz":"12487.65","bidPx":"3129.33","bidSz":"38.71","open24h":"3248","high24h":"3315.64","low24h":"3072.11","sodUtc0":"3108.41","sodUtc8":"3174.4","volCcy24h":"19460100.143","vol24h":"194601001.43","ts":"1765632003898"}]}
{"arg":{"channel":"bbo-tbt","instId":"ETH-USDT-SWAP"},"data":[{"asks":[["3129.57","12487.28","0","1"]],"bids":[["3129.33","38.71","0","1"]],"ts":"1765632003957","seqId":1158525335}]}
{"arg":{"channel":"bbo-tbt","instId":"ETH-USDT-SWAP"},"data":[{"asks":[["3129.57","12487.18","0","1"]],"bids":[["3129.33","38.71","0","1"]],"ts":"1765632004007","seqId":1158525337}]}
{"arg":{"channel":"books","instId":"ETH-USDT-SWAP"},"action":"update","data":[{"asks":[["3129.57","12487.18","0","1"]],"bids":[],"ts":"1765632004007","checksum":-288847603,"seqId":1158525337,"prevSeqId":1158525333}]}
{"arg":{"channel":"books5","instId":"ETH-USDT-SWAP"},"data":[{"asks":[["3129.57","12487.18","0","1"],["3130.65","0.01","0","1"],["3130.69","0.01","0","1"],["3130.77","0.05","0","3"],["3130.79","0.29","0","1"]],"bids":[["3129.33","38.71","0","1"],["3129.3","30.16","0","2"],["3129.27","0.01","0","1"],["3129.25","0.09","0","1"],["3129.2","0.94","0","2"]],"instId":"ETH-USDT-SWAP","ts":"1765632004007","seqId":1158525337}]}
{"arg":{"channel":"tickers","instId":"ETH-USDT-SWAP"},"data":[{"instType":"SWAP","instId":"ETH-USDT-SWAP","last":"3129.57","lastSz":"0.1","askPx":"3129.57","askSz":"12487.18","bidPx":"3129.33","bidSz":"38.71","open24h":"3248","high24h":"3315.64","low24h":"3072.11","sodUtc0":"3108.41","sodUtc8":"3174.4","volCcy24h":"19460100.19","vol24h":"194601001.9","ts":"1765632004006"}]}
{"arg":{"channel":"bbo-tbt","instId":"ETH-USDT-SWAP"},"data":[{"asks":[["3129.57","12487.02","0","1"]],"bids":[["3129.33","38.71","0","1"]],"ts":"1765632004067","seqId":1158525341}]}
{"arg":{"channel":"bbo-tbt","instId":"ETH-USDT-SWAP"},"data":[{"asks":[["3129.57","12486.94","0","1"]],"bids":[["3129.33","38.71","0","1"]],"ts":"1765632004077","seqId":1158525343}]}
{"arg":{"channel":"books","instId":"ETH-USDT-SWAP"},"action":"update","data":[{"asks":[["3129.57","12486.94","0","1"]],"bids":[],"ts":"1765632004107","checksum":-431464208,"seqId":1158525393,"prevSeqId":1158525337}]}
{"arg":{"channel":"books5","instId":"ETH-USDT-SWAP"},"data":[{"asks":[["3129.57","12486.94","0","1"],["3130.65","0.01","0","1"],["3130.69","0.01","0","1"],["3130.77","0.05","0","3"],["3130.79","0.29","0","1"]],"bids":[["3129.33","38.71","0","1"],["3129.3","30.16","0","2"],["3129.27","0.01","0","1"],["3129.25","0.09","0","1"],["3129.2","0.94","0","2"]],"instId":"ETH-USDT-SWAP","ts":"1765632004107","seqId":1158525393}]}
{"arg":{"channel":"bbo-tbt","instId":"ETH-USDT-SWAP"},"data":[{"asks":[["3129.57","12486.79","0","1"]],"bids":[["3129.33","38.71","0","1"]],"ts":"1765632004117","seqId":1158525395}]}
{"arg":{"channel":"tickers","instId":"ETH-USDT-SWAP"},"data":[{"instType":"SWAP","instId":"ETH-USDT-SWAP","last":"3129.57","lastSz":"0.08","askPx":"3129.57","askSz":"12486.94","bidPx":"3129.33","bidSz":"38.71","open24h":"3248","high24h":"3315.64","low24h":"3072.11","sodUtc0":"3108.41","sodUtc8":"3174.4","volCcy24h":"19460100.214","vol24h":"194601002.14","ts":"1765632004110"}]}
{"arg":{"channel":"books","instId":"ETH-USDT-SWAP"},"action":"update","data":[{"asks":[["3129.57","12486.79","0","1"]],"bids":[],"ts":"1765632004207","checksum":-1670724246,"seqId":1158525455,"prevSeqId":1158525393}]}
{"arg":{"channel":"books5","instId":"ETH-USDT-SWAP"},"data":[{"asks":[["3129.57","12486.79","0","1"],["3130.65","0.01","0","1"],["3130.69","0.01","0","1"],["3130.77","0.05","0","3"],["3130.79","0.29","0","1"]],"bids":[["3129.33","38.71","0","1"],["3129.3","30.16","0","2"],["3129.27","0.01","0","1"],["3129.25","0.09","0","1"],["3129.2","0.94","0","2"]],"instId":"ETH-USDT-SWAP","ts":"1765632004207","seqId":1158525455}]}
{"arg":{"channel":"bbo-tbt","instId":"ETH-USDT-SWAP"},"data":[{"asks":[["3129.57","12486.67","0","1"]],"bids":[["3129.33","38.71","0","1"]],"ts":"1765632004247","seqId":1158525457}]}
{"arg":{"channel":"bbo-tbt","instId":"ETH-USDT-SWAP"},"data":[{"asks":[["3129.57","12486.45","0","1"]],"bids":[["3129.33","38.71","0","1"]],"ts":"1765632004297","seqId":1158525459}]}
{"arg":{"channel":"books","instId":"ETH-USDT-SWAP"},"action":"update","data":[{"asks":[["3129.57","12486.45","0","1"]],"bids":[],"ts":"1765632004307","checksum":-217074079,"seqId":1158525459,"prevSeqId":1158525455}]}
{"arg":{"channel":"books5","instId":"ETH-USDT-SWAP"},"data":[{"asks":[["3129.57","12486.45","0","1"],["3130.65","0.01","0","1"],["3130.69","0.01","0","1"],["3130.77","0.05","0","3"],["3130.79","0.29","0","1"]],"bids":[["3129.33","38.71","0","1"],["3129.3","30.16","0","2"],["3129.27","0.01","0","1"],["3129.25","0.09","0","1"],["3129.2","0.94","0","2"]],"instId":"ETH-USDT-SWAP","ts":"1765632004307","seqId":1158525459}]}
{"arg":{"channel":"bbo-tbt","instId":"ETH-USDT-SWAP"},"data":[{"asks":[["3129.57","12486.45","0","1"]],"bids":[["3129.33","38.18","0","1"]],"ts":"1765632004317","seqId":1158525461}]}
{"arg":{"channel":"tickers","instId":"ETH-USDT-SWAP"},"data":[{"instType":"SWAP","instId":"ETH-USDT-SWAP","last":"3129.57","lastSz":"0.12","askPx":"3129.57","askSz":"12486.67","bidPx":"3129.33","bidSz":"38.71","open24h":"3248","high24h":"3315.64","low24h":"3072.11","sodUtc0":"3108.41","sodUtc8":"3174.4","volCcy24h":"19460100.241","vol24h":"194601002.41","ts":"1765632004249"}]}
{"arg":{"channel":"bbo-tbt","instId":"ETH-USDT-SWAP"},"data":[{"asks":[["3129.57","12486.34","0","1"]],"bids":[["3129.33","38.18","0","1"]],"ts":"1765632004397","seqId":1158525463}]}
{"arg":{"channel":"books","instId":"ETH-USDT-SWAP"},"action":"update","data":[{"asks":[["3129.57","12486.34","0","1"]],"bids":[["3129.33","38.18","0","1"]],"ts":"1765632004407","checksum":-1815511208,"seqId":1158525463,"prevSeqId":1158525459}]}
{"arg":{"channel":"books5","instId":"ETH-USDT-SWAP"},"data":[{"asks":[["3129.57","12486.34","0","1"],["3130.65","0.01","0","1"],["3130.69","0.01","0","1"],["3130.77","0.05","0","3"],["3130.79","0.29","0","1"]],"bids":[["3129.33","38.18","0","1"],["3129.3","30.16","0","2"],["3129.27","0.01","0","1"],["3129.25","0.09","0","1"],["3129.2","0.94","0","2"]],"instId":"ETH-USDT-SWAP","ts":"1765632004407","seqId":1158525463}]}
{"arg":{"channel":"bbo-tbt","instId":"ETH-USDT-SWAP"},"data":[{"asks":[["3129.57","12486.26","0","1"]],"bids":[["3129.33","38.18","0","1"]],"ts":"1765632004427","seqId":1158525465}]}
{"arg":{"channel":"bbo-tbt","instId":"ETH-USDT-SWAP"},"data":[{"asks":[["3129.57","12486.13","0","1"]],"bids":[["3129.33","38.18","0","1"]],"ts":"1765632004447","seqId":1158525467}]}
{"arg":{"channel":"tickers","instId":"ETH-USDT-SWAP"},"data":[{"instType":"SWAP","instId":"ETH-USDT-SWAP","last":"3129.33","lastSz":"0.53","askPx":"3129.57","askSz":"12486.45","bidPx":"3129.33","bidSz":"38.18","open24h":"3248","high24h":"3315.64","low24h":"3072.11","sodUtc0":"3108.41","sodUtc8":"3174.4","volCcy24h":"19460100.316","vol24h":"194601003.16","ts":"1765632004369"}]}
{"arg":{"channel":"bbo-tbt","instId":"ETH-USDT-SWAP"},"data":[{"asks":[["3129.57","12486","0","1"]],"bids":[["3129.33","38.18","0","1"]],"ts":"1765632004487","seqId":1158525469}]}
{"arg":{"channel":"books","instId":"ETH-USDT-SWAP"},"action":"update","data":[{"asks":[["3129.57","12486","0","1"]],"bids":[],"ts":"1765632004507","checksum":-841231398,"seqId":1158525469,"prevSeqId":1158525463}]}
{"arg":{"channel":"books5","instId":"ETH-USDT-SWAP"},"data":[{"asks":[["3129.57","12486","0","1"],["3130.65","0.01","0","1"],["3130.69","0.01","0","1"],["3130.77","0.05","0","3"],["3130.79","0.29","0","1"]],"bids":[["3129.33","38.18","0","1"],["3129.3","30.16","0","2"],["3129.27","0.01","0","1"],["3129.25","0.09","0","1"],["3129.2","0.94","0","2"]],"instId":"ETH-USDT-SWAP","ts":"1765632004507","seqId":1158525469}]}
{"arg":{"channel":"bbo-tbt","instId":"ETH-USDT-SWAP"},"data":[{"asks":[["3129.57","12485.77","0","1"]],"bids":[["3129.33","38.18","0","1"]],"ts":"1765632004517","seqId":1158525471}]}
{"arg":{"channel":"tickers","instId":"ETH-USDT-SWAP"},"data":[{"instType":"SWAP","instId":"ETH-USDT-SWAP","last":"3129.57","lastSz":"0.13","askPx":"3129.57","askSz":"12486","bidPx":"3129.33","bidSz":"38.18","open24h":"3248","high24h":"3315.64","low24h":"3072.11","sodUtc0":"3108.41","sodUtc8":"3174.4","volCcy24h":"19460100.361","vol24h":"194601003.61","ts":"1765632004489"}]}
{"arg":{"channel":"bbo-tbt","instId":"ETH-USDT-SWAP"},"data":[{"asks":[["3129.57","12485.6","0","1"]],"bids":[["3129.33","38.18","0","1"]],"ts":"1765632004547","seqId":1158525475}]}
{"arg":{"channel":"bbo-tbt","instId":"ETH-USDT-SWAP"},"data":[{"asks":[["3129.57","12485.48","0","1"]],"bids":[["3129.33","38.18","0","1"]],"ts":"1765632004597","seqId":1158525477}]}
{"arg":{"channel":"books","instId":"ETH-USDT-SWAP"},"action":"update","data":[{"asks":[["3129.57","12485.48","0","1"]],"bids":[],"ts":"1765632004607","checksum":-1658996123,"seqId":1158525477,"prevSeqId":1158525469}]}
{"arg":{"channel":"books5","instId":"ETH-USDT-SWAP"},"data":[{"asks":[["3129.57","12485.48","0","1"],["3130.65","0.01","0","1"],["3130.69","0.01","0","1"],["3130.77","0.05","0","3"],["3130.79","0.29","0","1"]],"bids":[["3129.33","38.18","0","1"],["3129.3","30.16","0","2"],["3129.27","0.01","0","1"],["3129.25","0.09","0","1"],["3129.2","0.94","0","2"]],"instId":"ETH-USDT-SWAP","ts":"1765632004607","seqId":1158525477}]}
{"arg":{"channel":"tickers","instId":"ETH-USDT-SWAP"},"data":[{"instType":"SWAP","instId":"ETH-USDT-SWAP","last":"3129.57","lastSz":"0.12","askPx":"3129.57","askSz":"12485.48","bidPx":"3129.33","bidSz":"38.18","open24h":"3248","high24h":"3315.64","low24h":"3072.11","sodUtc0":"3108.41","sodUtc8":"3174.4","volCcy24h":"19460100.413","vol24h":"194601004.13","ts":"1765632004597"}]}
{"arg":{"channel":"bbo-tbt","instId":"ETH-USDT-SWAP"},"data":[{"asks":[["3129.57","12485.29","0","1"]],"bids":[["3129.33","38.18","0","1"]],"ts":"1765632004667","seqId":1158525481}]}
{"arg":{"channel":"books","instId":"ETH-USDT-SWAP"},"action":"update","data":[{"asks":[["3129.57","12485.29","0","1"]],"bids":[],"ts":"1765632004707","checksum":-789645824,"seqId":1158525481,"prevSeqId":1158525477}]}
{"arg":{"channel":"books5","instId":"ETH-USDT-SWAP"},"data":[{"asks":[["3129.57","12485.29","0","1"],["3130.65","0.01","0","1"],["3130.69","0.01","0","1"],["3130.77","0.05","0","3"],["3130.79","0.29","0","1"]],"bids":[["3129.33","38.18","0","1"],["3129.3","30.16","0","2"],["3129.27","0.01","0","1"],["3129.25","0.09","0","1"],["3129.2","0.94","0","2"]],"instId":"ETH-USDT-SWAP","ts":"1765632004707","seqId":1158525481}]}
{"arg":{"channel":"tickers","instId":"ETH-USDT-SWAP"},"data":[{"instType":"SWAP","instId":"ETH-USDT-SWAP","last":"3129.57","lastSz":"0.09","askPx":"3129.57","askSz":"12485.29","bidPx":"3129.33","bidSz":"38.18","open24h":"3248","high24h":"3315.64","low24h":"3072.11","sodUtc0":"3108.41","sodUtc8":"3174.4","volCcy24h":"19460100.432","vol24h":"194601004.32","ts":"1765632004710"}]}
{"arg":{"channel":"bbo-tbt","instId":"ETH-USDT-SWAP"},"data":[{"asks":[["3129.57","12485.18","0","1"]],"bids":[["3129.33","38.18","0","1"]],"ts":"1765632004727","seqId":1158525483}]}
{"arg":{"channel":"bbo-tbt","instId":"ETH-USDT-SWAP"},"data":[{"asks":[["3129.57","12485.03","0","1"]],"bids":[["3129.33","38.18","0","1"]],"ts":"1765632004737","seqId":1158525485}]}
{"arg":{"channel":"books","instId":"ETH-USDT-SWAP"},"action":"update","data":[{"asks":[["3129.57","12485.03","0","1"]],"bids":[],"ts":"1765632004807","checksum":1636428136,"seqId":1158525485,"prevSeqId":1158525481}]}
{"arg":{"channel":"books5","instId":"ETH-USDT-SWAP"},"data":[{"asks":[["3129.57","12485.03","0","1"],["3130.65","0.01","0","1"],["3130.69","0.01","0","1"],["3130.77","0.05","0","3"],["3130.79","0.29","0","1"]],"bids":[["3129.33","38.18","0","1"],["3129.3","30.16","0","2"],["3129.27","0.01","0","1"],["3129.25","0.09","0","1"],["3129.2","0.94","0","2"]],"instId":"ETH-USDT-SWAP","ts":"1765632004807","seqId":1158525485}]}
{"arg":{"channel":"bbo-tbt","instId":"ETH-USDT-SWAP"},"data":[{"asks":[["3129.57","12484.95","0","1"]],"bids":[["3129.33","38.18","0","1"]],"ts":"1765632004877","seqId":1158525487}]}
{"arg":{"channel":"books","instId":"ETH-USDT-SWAP"},"action":"update","data":[{"asks":[["3129.57","12484.95","0","1"]],"bids":[],"ts":"1765632004907","checksum":-1067456151,"seqId":1158525535,"prevSeqId":1158525485}]}
{"arg":{"channel":"books5","instId":"ETH-USDT-SWAP"},"data":[{"asks":[["3129.57","12484.95","0","1"],["3130.65","0.01","0","1"],["3130.69","0.01","0","1"],["3130.77","0.05","0","3"],["3130.79","0.29","0","1"]],"bids":[["3129.33","38.18","0","1"],["3129.3","30.16","0","2"],["3129.27","0.01","0","1"],["3129.25","0.09","0","1"],["3129.2","0.94","0","2"]],"instId":"ETH-USDT-SWAP","ts":"1765632004907","seqId":1158525535}]}
{"arg":{"channel":"bbo-tbt","instId":"ETH-USDT-SWAP"},"data":[{"asks":[["3129.57","12484.88","0","1"]],"bids":[["3129.33","38.18","0","1"]],"ts":"1765632004937","seqId":1158525539}]}
{"arg":{"channel":"bbo-tbt","instId":"ETH-USDT-SWAP"},"data":[{"asks":[["3129.57","12484.76","0","1"]],"bids":[["3129.33","38.18","0","1"]],"ts":"1765632004947","seqId":1158525541}]}
{"arg":{"channel":"bbo-tbt","instId":"ETH-USDT-SWAP"},"data":[{"asks":[["3129.57","12484.63","0","1"]],"bids":[["3129.33","38.18","0","1"]],"ts":"1765632004967","seqId":1158525563}]}
{"arg":{"channel":"tickers","instId":"ETH-USDT-SWAP"},"data":[{"instType":"SWAP","instId":"ETH-USDT-SWAP","last":"3129.57","lastSz":"0.15","askPx":"3129.57","askSz":"12485.03","bidPx":"3129.33","bidSz":"38.18","open24h":"3248","high24h":"3315.64","low24h":"3072.11","sodUtc0":"3108.41","sodUtc8":"3174.4","volCcy24h":"19460100.458","vol24h":"194601004.58","ts":"1765632004865"}]}
{"arg":{"channel":"bbo-tbt","instId":"ETH-USDT-SWAP"},"data":[{"asks":[["3129.57","12484.57","0","1"]],"bids":[["3129.33","38.18","0","1"]],"ts":"1765632004987","seqId":1158525565}]}
{"arg":{"channel":"books","instId":"ETH-USDT-SWAP"},"action":"update","data":[{"asks":[["3129.57","12484.57","0","1"]],"bids":[],"ts":"1765632005007","checksum":1538879907,"seqId":1158525578,"prevSeqId":1158525535}]}
{"arg":{"channel":"books5","instId":"ETH-USDT-SWAP"},"data":[{"asks":[["3129.57","12484.57","0","1"],["3130.65","0.01","0","1"],["3130.69","0.01","0","1"],["3130.77","0.05","0","3"],["3130.79","0.29","0","1"]],"bids":[["3129.33","38.18","0","1"],["3129.3","30.16","0","2"],["3129.27","0.01","0","1"],["3129.25","0.09","0","1"],["3129.2","0.94","0","2"]],"instId":"ETH-USDT-SWAP","ts":"1765632005007","seqId":1158525578}]}
{"arg":{"channel":"bbo-tbt","instId":"ETH-USDT-SWAP"},"data":[{"asks":[["3129.57","12484.24","0","1"]],"bids":[["3129.33","38.18","0","1"]],"ts":"1765632005017","seqId":1158525595}]}
{"arg":{"channel":"tickers","instId":"ETH-USDT-SWAP"},"data":[{"instType":"SWAP","instId":"ETH-USDT-SWAP","last":"3129.57","lastSz":"0.13","askPx":"3129.57","askSz":"12484.63","bidPx":"3129.33","bidSz":"38.18","open24h":"3248","high24h":"3315.64","low24h":"3072.11","sodUtc0":"3108.41","sodUtc8":"3174.4","volCcy24h":"19460100.498","vol24h":"194601004.98","ts":"1765632004968"}]}
{"arg":{"channel":"books","instId":"ETH-USDT-SWAP"},"action":"update","data":[{"asks":[["3129.57","12484.24","0","1"]],"bids":[],"ts":"1765632005107","checksum":-444869936,"seqId":1158525595,"prevSeqId":1158525578}]}
{"arg":{"channel":"books5","instId":"ETH-USDT-SWAP"},"data":[{"asks":[["3129.57","12484.24","0","1"],["3130.65","0.01","0","1"],["3130.69","0.01","0","1"],["3130.77","0.05","0","3"],["3130.79","0.29","0","1"]],"bids":[["3129.33","38.18","0","1"],["3129.3","30.16","0","2"],["3129.27","0.01","0","1"],["3129.25","0.09","0","1"],["3129.2","0.94","0","2"]],"instId":"ETH-USDT-SWAP","ts":"1765632005107","seqId":1158525595}]}
{"arg":{"channel":"bbo-tbt","instId":"ETH-USDT-SWAP"},"data":[{"asks":[["3129.57","12484.14","0","1"]],"bids":[["3129.33","38.18","0","1"]],"ts":"1765632005117","seqId":1158525597}]}
{"arg":{"channel":"tickers","instId":"ETH-USDT-SWAP"},"data":[{"instType":"SWAP","instId":"ETH-USDT-SWAP","last":"3129.57","lastSz":"0.24","askPx":"3129.57","askSz":"12484.24","bidPx":"3129.33","bidSz":"38.18","open24h":"3248","high24h":"3315.64","low24h":"3072.11","sodUtc0":"3108.41","sodUtc8":"3174.4","volCcy24h":"19460100.537","vol24h":"194601005.37","ts":"1765632005073"}]}
{"arg":{"channel":"bbo-tbt","instId":"ETH-USDT-SWAP"},"data":[{"asks":[["3129.57","12484.14","0","1"]],"bids":[["3129.3","30.04","0","1"]],"ts":"1765632005177","seqId":1158525609}]}
{"arg":{"channel":"bbo-tbt","instId":"ETH-USDT-SWAP"},"data":[{"asks":[["3129.57","12484.06","0","1"]],"bids":[["3129.3","30.04","0","1"]],"ts":"1765632005197","seqId":1158525615}]}
{"arg":{"channel":"bbo-tbt","instId":"ETH-USDT-SWAP"},"data":[{"asks":[["3129.57","12483.99","0","1"]],"bids":[["3129.3","30.04","0","1"]],"ts":"1765632005207","seqId":1158525617}]}
{"arg":{"channel":"books","instId":"ETH-USDT-SWAP"},"action":"update","data":[{"asks":[["3129.57","12483.99","0","1"],["3130.93","50.04","0","1"],["3131.2","2.45","0","6"],["3135.6","0","0","0"]],"bids":[["3129.33","0","0","0"],["3129.3","30.04","0","1"],["3123.83","0.28","0","2"]],"ts":"1765632005207","checksum":956890613,"seqId":1158525617,"prevSeqId":1158525595}]}
{"arg":{"channel":"books5","instId":"ETH-USDT-SWAP"},"data":[{"asks":[["3129.57","12483.99","0","1"],["3130.65","0.01","0","1"],["3130.69","0.01","0","1"],["3130.77","0.05","0","3"],["3130.79","0.29","0","1"]],"bids":[["3129.3","30.04","0","1"],["3129.27","0.01","0","1"],["3129.25","0.09","0","1"],["3129.2","0.94","0","2"],["3129.19","0.08","0","2"]],"instId":"ETH-USDT-SWAP","ts":"1765632005207","seqId":1158525617}]}
{"arg":{"channel":"bbo-tbt","instId":"ETH-USDT-SWAP"},"data":[{"asks":[["3129.57","12483.91","0","1"]],"bids":[["3129.3","30.04","0","1"]],"ts":"1765632005217","seqId":1158525619}]}
{"arg":{"channel":"tickers","instId":"ETH-USDT-SWAP"},"data":[{"instType":"SWAP","instId":"ETH-USDT-SWAP","last":"3129.33","lastSz":"38.18","askPx":"3129.57","askSz":"12484.14","bidPx":"3129.3","bidSz":"30.16","open24h":"3248","high24h":"3315.64","low24h":"3072.11","sodUtc0":"3108.41","sodUtc8":"3174.4","volCcy24h":"19460104.365","vol24h":"194601043.65","ts":"1765632005179"}]}
{"arg":{"channel":"books","instId":"ETH-USDT-SWAP"},"action":"update","data":[{"asks":[["3129.57","12483.91","0","1"]],"bids":[],"ts":"1765632005307","checksum":1962547649,"seqId":1158525619,"prevSeqId":1158525617}]}
{"arg":{"channel":"books5","instId":"ETH-USDT-SWAP"},"data":[{"asks":[["3129.57","12483.91","0","1"],["3130.65","0.01","0","1"],["3130.69","0.01","0","1"],["3130.77","0.05","0","3"],["3130.79","0.29","0","1"]],"bids":[["3129.3","30.04","0","1"],["3129.27","0.01","0","1"],["3129.25","0.09","0","1"],["3129.2","0.94","0","2"],["3129.19","0.08","0","2"]],"instId":"ETH-USDT-SWAP","ts":"1765632005307","seqId":1158525619}]}
{"arg":{"channel":"bbo-tbt","instId":"ETH-USDT-SWAP"},"data":[{"asks":[["3129.57","12483.67","0","1"]],"bids":[["3129.3","30.04","0","1"]],"ts":"1765632005387","seqId":1158525627}]}
{"arg":{"channel":"tickers","instId":"ETH-USDT-SWAP"},"data":[{"instType":"SWAP","instId":"ETH-USDT-SWAP","last":"3129.57","lastSz":"0.08","askPx":"3129.57","askSz":"12483.91","bidPx":"3129.3","bidSz":"30.04","open24h":"3248","high24h":"3315.64","low24h":"3072.11","sodUtc0":"3108.41","sodUtc8":"3174.4","volCcy24h":"19460104.4","vol24h":"194601044","ts":"1765632005310"}]}
{"arg":{"channel":"books","instId":"ETH-USDT-SWAP"},"action":"update","data":[{"asks":[["3129.57","12483.67","0","1"]],"bids":[],"ts":"1765632005407","checksum":-600714103,"seqId":1158525627,"prevSeqId":1158525619}]}
{"arg":{"channel":"books5","instId":"ETH-USDT-SWAP"},"data":[{"asks":[["3129.57","12483.67","0","1"],["3130.65","0.01","0","1"],["3130.69","0.01","0","1"],["3130.77","0.05","0","3"],["3130.79","0.29","0","1"]],"bids":[["3129.3","30.04","0","1"],["3129.27","0.01","0","1"],["3129.25","0.09","0","1"],["3129.2","0.94","0","2"],["3129.19","0.08","0","2"]],"instId":"ETH-USDT-SWAP","ts":"1765632005407","seqId":1158525627}]}
{"arg":{"channel":"tickers","instId":"ETH-USDT-SWAP"},"data":[{"instType":"SWAP","instId":"ETH-USDT-SWAP","last":"3129.57","lastSz":"0.24","askPx":"3129.57","askSz":"12483.67","bidPx":"3129.3","bidSz":"30.04","open24h":"3248","high24h":"3315.64","low24h":"3072.11","sodUtc0":"3108.41","sodUtc8":"3174.4","volCcy24h":"19460104.424","vol24h":"194601044.24","ts":"1765632005411"}]}
{"arg":{"channel":"bbo-tbt","instId":"ETH-USDT-SWAP"},"data":[{"asks":[["3129.57","12483.55","0","1"]],"bids":[["3129.3","30.04","0","1"]],"ts":"1765632005537","seqId":1158525653}]}
{"arg":{"channel":"bbo-tbt","instId":"ETH-USDT-SWAP"},"data":[{"asks":[["3129.57","12483.47","0","1"]],"bids":[["3129.3","30.04","0","1"]],"ts":"1765632005557","seqId":1158525655}]}
{"arg":{"channel":"bbo-tbt","instId":"ETH-USDT-SWAP"},"data":[{"asks":[["3129.57","12483.34","0","1"]],"bids":[["3129.3","30.04","0","1"]],"ts":"1765632005577","seqId":1158525657}]}
{"arg":{"channel":"bbo-tbt","instId":"ETH-USDT-SWAP"},"data":[{"asks":[["3129.57","12483.11","0","1"]],"bids":[["3129.3","29.51","0","1"]],"ts":"1765632005587","seqId":1158525661}]}
{"arg":{"channel":"books","instId":"ETH-USDT-SWAP"},"action":"update","data":[{"asks":[["3129.57","12483.11","0","1"]],"bids":[["3129.3","29.51","0","1"]],"ts":"1765632005607","checksum":1364145049,"seqId":1158525661,"prevSeqId":1158525627}]}
{"arg":{"channel":"books5","instId":"ETH-USDT-SWAP"},"data":[{"asks":[["3129.57","12483.11","0","1"],["3130.65","0.01","0","1"],["3130.69","0.01","0","1"],["3130.77","0.05","0","3"],["3130.79","0.29","0","1"]],"bids":[["3129.3","29.51","0","1"],["3129.27","0.01","0","1"],["3129.25","0.09","0","1"],["3129.2","0.94","0","2"],["3129.19","0.08","0","2"]],"instId":"ETH-USDT-SWAP","ts":"1765632005607","seqId":1158525661}]}
{"arg":{"channel":"bbo-tbt","instId":"ETH-USDT-SWAP"},"data":[{"asks":[["3129.57","12482.89","0","1"]],"bids":[["3129.3","29.51","0","1"]],"ts":"1765632005637","seqId":1158525663}]}
{"arg":{"channel":"tickers","instId":"ETH-USDT-SWAP"},"data":[{"instType":"SWAP","instId":"ETH-USDT-SWAP","last":"3129.57","lastSz":"0.22","askPx":"3129.57","askSz":"12482.89","bidPx":"3129.3","bidSz":"29.51","open24h":"3248","high24h":"3315.64","low24h":"3072.11","sodUtc0":"3108.41","sodUtc8":"3174.4","volCcy24h":"19460104.555","vol24h":"194601045.55","ts":"1765632005638"}]}
{"arg":{"channel":"books","instId":"ETH-USDT-SWAP"},"action":"update","data":[{"asks":[["3129.57","12482.89","0","1"]],"bids":[],"ts":"1765632005707","checksum":807636013,"seqId":1158525681,"prevSeqId":1158525661}]}
{"arg":{"channel":"books5","instId":"ETH-USDT-SWAP"},"data":[{"asks":[["3129.57","12482.89","0","1"],["3130.65","0.01","0","1"],["3130.69","0.01","0","1"],["3130.77","0.05","0","3"],["3130.79","0.29","0","1"]],"bids":[["3129.3","29.51","0","1"],["3129.27","0.01","0","1"],["3129.25","0.09","0","1"],["3129.2","0.94","0","2"],["3129.19","0.08","0","2"]],"instId":"ETH-USDT-SWAP","ts":"1765632005707","seqId":1158525681}]}
{"arg":{"channel":"tickers","instId":"ETH-USDT-SWAP"},"data":[{"instType":"SWAP","instId":"ETH-USDT-SWAP","last":"3129.57","lastSz":"0.22","askPx":"3129.57","askSz":"12482.89","bidPx":"3129.3","bidSz":"29.51","open24h":"3248","high24h":"3315.64","low24h":"3072.11","sodUtc0":"3108.41","sodUtc8":"3174.4","volCcy24h":"19460104.555","vol24h":"194601045.55","ts":"1765632005765"}]}
{"arg":{"channel":"bbo-tbt","instId":"ETH-USDT-SWAP"},"data":[{"asks":[["3129.3","523.87","0","1"]],"bids":[["3129.27","0.01","0","1"]],"ts":"1765632005827","seqId":1158525686}]}
{"arg":{"channel":"bbo-tbt","instId":"ETH-USDT-SWAP"},"data":[{"asks":[["3129.3","523.77","0","1"]],"bids":[["3129.13","1.36","0","1"]],"ts":"1765632005837","seqId":1158525732}]}
{"arg":{"channel":"books","instId":"ETH-USDT-SWAP"},"action":"update","data":[{"asks":[["3129.3","523.77","0","1"],["3130.46","0.04","0","1"],["3130.56","37.73","0","1"],["3130.57","30.11","0","1"],["3130.61","0.09","0","1"],["3130.63","0.02","0","1"],["3130.68","0.06","0","1"],["3130.74","0.02","0","1"],["3131","2.79","0","6"],["3131.1","0.01","0","1"],["3135.48","0","0","0"],["3135.49","0","0","0"],["3135.5","0","0","0"],["3135.51","0","0","0"],["3135.53","0","0","0"],["3135.54","0","0","0"],["3135.56","0","0","0"],["3135.57","0","0","0"],["3135.58","0","0","0"]],"bids":[["3129.3","0","0","0"],["3129.27","0","0","0"],["3129.25","0","0","0"],["3129.2","0","0","0"],["3129.19","0","0","0"],["3129.17","0","0","0"],["3129.14","0","0","0"],["3129.13","1.36","0","1"],["3123.82","38.44","0","7"],["3123.81","0.18","0","5"],["3123.8","3.65","0","6"],["3123.79","0.73","0","3"],["3123.78","0.88","0","5"],["3123.77","2.23","0","3"],["3123.76","0.09","0","3"]],"ts":"1765632005907","checksum":-350994823,"seqId":1158525732,"prevSeqId":1158525681}]}
{"arg":{"channel":"books5","instId":"ETH-USDT-SWAP"},"data":[{"asks":[["3129.3","523.77","0","1"],["3129.57","12482.89","0","1"],["3130.46","0.04","0","1"],["3130.56","37.73","0","1"],["3130.57","30.11","0","1"]],"bids":[["3129.13","1.36","0","1"],["3129.11","0.02","0","1"],["3129.09","7.4","0","2"],["3129.07","0.01","0","1"],["3129.06","47.58","0","2"]],"instId":"ETH-USDT-SWAP","ts":"1765632005907","seqId":1158525732}]}
{"arg":{"channel":"bbo-tbt","instId":"ETH-USDT-SWAP"},"data":[{"asks":[["3129.3","523.67","0","1"]],"bids":[["3129.13","1.36","0","1"]],"ts":"1765632005967","seqId":1158525734}]}
{"arg":{"channel":"tickers","instId":"ETH-USDT-SWAP"},"data":[{"instType":"SWAP","instId":"ETH-USDT-SWAP","last":"3129.13","lastSz":"0.1","askPx":"3129.3","askSz":"523.77","bidPx":"3129.13","bidSz":"1.36","open24h":"3248","high24h":"3315.64","low24h":"3072.11","sodUtc0":"3108.41","sodUtc8":"3174.4","volCcy24h":"19460111.616","vol24h":"194601116.16","ts":"1765632005887"}]}
{"arg":{"channel":"bbo-tbt","instId":"ETH-USDT-SWAP"},"data":[{"asks":[["3129.3","523.61","0","1"]],"bids":[["3129.13","1.36","0","1"]],"ts":"1765632005987","seqId":1158525736}]}
{"arg":{"channel":"books","instId":"ETH-USDT-SWAP"},"action":"update","data":[{"asks":[["3129.3","523.61","0","1"]],"bids":[],"ts":"1765632006007","checksum":-1841874198,"seqId":1158525736,"prevSeqId":1158525732}]}
{"arg":{"channel":"books5","instId":"ETH-USDT-SWAP"},"data":[{"asks":[["3129.3","523.61","0","1"],["3129.57","12482.89","0","1"],["3130.46","0.04","0","1"],["3130.56","37.73","0","1"],["3130.57","30.11","0","1"]],"bids":[["3129.13","1.36","0","1"],["3129.11","0.02","0","1"],["3129.09","7.4","0","2"],["3129.07","0.01","0","1"],["3129.06","47.58","0","2"]],"instId":"ETH-USDT-SWAP","ts":"1765632006007","seqId":1158525736}]}
{"arg":{"channel":"bbo-tbt","instId":"ETH-USDT-SWAP"},"data":[{"asks":[["3129.3","523.46","0","1"]],"bids":[["3129.13","1.36","0","1"]],"ts":"1765632006027","seqId":1158525747}]}
{"arg":{"channel":"bbo-tbt","instId":"ETH-USDT-SWAP"},"data":[{"asks":[["3129.3","523.33","0","1"]],"bids":[["3129.13","1.36","0","1"]],"ts":"1765632006067","seqId":1158525758}]}
{"arg":{"channel":"books","instId":"ETH-USDT-SWAP"},"action":"update","data":[{"asks":[["3129.3","523.33","0","1"]],"bids":[],"ts":"1765632006107","checksum":-1622613221,"seqId":1158525758,"prevSeqId":1158525736}]}
{"arg":{"channel":"books5","instId":"ETH-USDT-SWAP"},"data":[{"asks":[["3129.3","523.33","0","1"],["3129.57","12482.89","0","1"],["3130.46","0.04","0","1"],["3130.56","37.73","0","1"],["3130.57","30.11","0","1"]],"bids":[["3129.13","1.36","0","1"],["3129.11","0.02","0","1"],["3129.09","7.4","0","2"],["3129.07","0.01","0","1"],["3129.06","47.58","0","2"]],"instId":"ETH-USDT-SWAP","ts":"1765632006107","seqId":1158525758}]}
{"arg":{"channel":"tickers","instId":"ETH-USDT-SWAP"},"data":[{"instType":"SWAP","instId":"ETH-USDT-SWAP","last":"3129.3","lastSz":"0.06","askPx":"3129.3","askSz":"523.61","bidPx":"3129.13","bidSz":"1.36","open24h":"3248","high24h":"3315.64","low24h":"3072.11","sodUtc0":"3108.41","sodUtc8":"3174.4","volCcy24h":"19460111.632","vol24h":"194601116.32","ts":"1765632006011"}]}
{"arg":{"channel":"bbo-tbt","instId":"ETH-USDT-SWAP"},"data":[{"asks":[["3129.3","523.33","0","1"]],"bids":[["3129.13","0.83","0","1"]],"ts":"1765632006117","seqId":1158525760}]}
{"arg":{"channel":"bbo-tbt","instId":"ETH-USDT-SWAP"},"data":[{"asks":[["3129.3","523.24","0","1"]],"bids":[["3129.13","0.83","0","1"]],"ts":"1765632006147","seqId":1158525762}]}
{"arg":{"channel":"bbo-tbt","instId":"ETH-USDT-SWAP"},"data":[{"asks":[["3129.3","523.14","0","1"]],"bids":[["3129.13","0.83","0","1"]],"ts":"1765632006187","seqId":1158525773}]}
{"arg":{"channel":"books","instId":"ETH-USDT-SWAP"},"action":"update","data":[{"asks":[["3129.3","523.14","0","1"]],"bids":[["3129.13","0.83","0","1"]],"ts":"1765632006207","checksum":-745107357,"seqId":1158525773,"prevSeqId":1158525758}]}
{"arg":{"channel":"books5","instId":"ETH-USDT-SWAP"},"data":[{"asks":[["3129.3","523.14","0","1"],["3129.57","12482.89","0","1"],["3130.46","0.04","0","1"],["3130.56","37.73","0","1"],["3130.57","30.11","0","1"]],"bids":[["3129.13","0.83","0","1"],["3129.11","0.02","0","1"],["3129.09","7.4","0","2"],["3129.07","0.01","0","1"],["3129.06","47.58","0","2"]],"instId":"ETH-USDT-SWAP","ts":"1765632006207","seqId":1158525773}]}
{"arg":{"channel":"tickers","instId":"ETH-USDT-SWAP"},"data":[{"instType":"SWAP","instId":"ETH-USDT-SWAP","last":"3129.13","lastSz":"0.53","askPx":"3129.3","askSz":"523.33","bidPx":"3129.13","bidSz":"0.83","open24h":"3248","high24h":"3315.64","low24h":"3072.11","sodUtc0":"3108.41","sodUtc8":"3174.4","volCcy24h":"19460111.713","vol24h":"194601117.13","ts":"1765632006116"}]}
{"arg":{"channel":"bbo-tbt","instId":"ETH-USDT-SWAP"},"data":[{"asks":[["3129.3","523.06","0","1"]],"bids":[["3129.13","0.83","0","1"]],"ts":"1765632006267","seqId":1158525775}]}
{"arg":{"channel":"bbo-tbt","instId":"ETH-USDT-SWAP"},"data":[{"asks":[["3129.3","522.94","0","1"]],"bids":[["3129.13","0.83","0","1"]],"ts":"1765632006287","seqId":1158525783}]}
{"arg":{"channel":"books","instId":"ETH-USDT-SWAP"},"action":"update","data":[{"asks":[["3129.3","522.94","0","1"]],"bids":[],"ts":"1765632006307","checksum":-6263843,"seqId":1158525789,"prevSeqId":1158525773}]}
{"arg":{"channel":"books5","instId":"ETH-USDT-SWAP"},"data":[{"asks":[["3129.3","522.94","0","1"],["3129.57","12482.89","0","1"],["3130.46","0.04","0","1"],["3130.56","37.73","0","1"],["3130.57","30.11","0","1"]],"bids":[["3129.13","0.83","0","1"],["3129.11","0.02","0","1"],["3129.09","7.4","0","2"],["3129.07","0.01","0","1"],["3129.06","47.58","0","2"]],"instId":"ETH-USDT-SWAP","ts":"1765632006307","seqId":1158525789}]}
{"arg":{"channel":"tickers","instId":"ETH-USDT-SWAP"},"data":[{"instType":"SWAP","instId":"ETH-USDT-SWAP","last":"3129.3","lastSz":"0.08","askPx":"3129.3","askSz":"523.06","bidPx":"3129.13","bidSz":"0.83","open24h":"3248","high24h":"3315.64","low24h":"3072.11","sodUtc0":"3108.41","sodUtc8":"3174.4","volCcy24h":"19460111.74","vol24h":"194601117.4","ts":"1765632006262"}]}
{"arg":{"channel":"bbo-tbt","instId":"ETH-USDT-SWAP"},"data":[{"asks":[["3129.3","522.88","0","1"]],"bids":[["3129.13","0.83","0","1"]],"ts":"1765632006357","seqId":1158525807}]}
{"arg":{"channel":"bbo-tbt","instId":"ETH-USDT-SWAP"},"data":[{"asks":[["3129.3","522.73","0","1"]],"bids":[["3129.13","0.83","0","1"]],"ts":"1765632006387","seqId":1158525809}]}
{"arg":{"channel":"books","instId":"ETH-USDT-SWAP"},"action":"update","data":[{"asks":[["3129.3","522.73","0","1"]],"bids":[],"ts":"1765632006407","checksum":412071350,"seqId":1158525809,"prevSeqId":1158525789}]}
{"arg":{"channel":"books5","instId":"ETH-USDT-SWAP"},"data":[{"asks":[["3129.3","522.73","0","1"],["3129.57","12482.89","0","1"],["3130.46","0.04","0","1"],["3130.56","37.73","0","1"],["3130.57","30.11","0","1"]],"bids":[["3129.13","0.83","0","1"],["3129.11","0.02","0","1"],["3129.09","7.4","0","2"],["3129.07","0.01","0","1"],["3129.06","47.58","0","2"]],"instId":"ETH-USDT-SWAP","ts":"1765632006407","seqId":1158525809}]}
{"arg":{"channel":"tickers","instId":"ETH-USDT-SWAP"},"data":[{"instType":"SWAP","instId":"ETH-USDT-SWAP","last":"3129.3","lastSz":"0.15","askPx":"3129.3","askSz":"522.73","bidPx":"3129.13","bidSz":"0.83","open24h":"3248","high24h":"3315.64","low24h":"3072.11","sodUtc0":"3108.41","sodUtc8":"3174.4","volCcy24h":"19460111.773","vol24h":"194601117.73","ts":"1765632006389"}]}
{"arg":{"channel":"tickers","instId":"ETH-USDT-SWAP"},"data":[{"instType":"SWAP","instId":"ETH-USDT-SWAP","last":"3129.3","lastSz":"0.15","askPx":"3129.3","askSz":"522.73","bidPx":"3129.13","bidSz":"0.83","open24h":"3248","high24h":"3315.64","low24h":"3072.11","sodUtc0":"3108.41","sodUtc8":"3174.4","volCcy24h":"19460111.773","vol24h":"194601117.73","ts":"1765632006520"}]}
{"arg":{"channel":"bbo-tbt","instId":"ETH-USDT-SWAP"},"data":[{"asks":[["3129.3","522.59","0","1"]],"bids":[["3129.13","0.83","0","1"]],"ts":"1765632006567","seqId":1158525813}]}
{"arg":{"channel":"bbo-tbt","instId":"ETH-USDT-SWAP"},"data":[{"asks":[["3129.3","522.22","0","1"]],"bids":[["3129.13","0.83","0","1"]],"ts":"1765632006577","seqId":1158525815}]}
{"arg":{"channel":"bbo-tbt","instId":"ETH-USDT-SWAP"},"data":[{"asks":[["3129.3","522.09","0","1"]],"bids":[["3129.13","0.83","0","1"]],"ts":"1765632006597","seqId":1158525825}]}
{"arg":{"channel":"books","instId":"ETH-USDT-SWAP"},"action":"update","data":[{"asks":[["3129.3","522.09","0","1"]],"bids":[],"ts":"1765632006607","checksum":1964722478,"seqId":1158525825,"prevSeqId":1158525809}]}
{"arg":{"channel":"books5","instId":"ETH-USDT-SWAP"},"data":[{"asks":[["3129.3","522.09","0","1"],["3129.57","12482.89","0","1"],["3130.46","0.04","0","1"],["3130.56","37.73","0","1"],["3130.57","30.11","0","1"]],"bids":[["3129.13","0.83","0","1"],["3129.11","0.02","0","1"],["3129.09","7.4","0","2"],["3129.07","0.01","0","1"],["3129.06","47.58","0","2"]],"instId":"ETH-USDT-SWAP","ts":"1765632006607","seqId":1158525825}]}
{"arg":{"channel":"bbo-tbt","instId":"ETH-USDT-SWAP"},"data":[{"asks":[["3129.3","521.99","0","1"]],"bids":[["3129.13","0.83","0","1"]],"ts":"1765632006647","seqId":1158525827}]}
{"arg":{"channel":"bbo-tbt","instId":"ETH-USDT-SWAP"},"data":[{"asks":[["3129.3","521.87","0","1"]],"bids":[["3129.13","0.83","0","1"]],"ts":"1765632006657","seqId":1158525829}]}
{"arg":{"channel":"tickers","instId":"ETH-USDT-SWAP"},"data":[{"instType":"SWAP","instId":"ETH-USDT-SWAP","last":"3129.3","lastSz":"0.13","askPx":"3129.3","askSz":"522.09","bidPx":"3129.13","bidSz":"0.83","open24h":"3248","high24h":"3315.64","low24h":"3072.11","sodUtc0":"3108.41","sodUtc8":"3174.4","volCcy24h":"19460111.837","vol24h":"194601118.37","ts":"1765632006634"}]}
{"arg":{"channel":"bbo-tbt","instId":"ETH-USDT-SWAP"},"data":[{"asks":[["3129.3","521.69","0","1"]],"bids":[["3129.13","0.83","0","1"]],"ts":"1765632006677","seqId":1158525833}]}
{"arg":{"channel":"books","instId":"ETH-USDT-SWAP"},"action":"update","data":[{"asks":[["3129.3","521.69","0","1"]],"bids":[],"ts":"1765632006707","checksum":1120330586,"seqId":1158525833,"prevSeqId":1158525825}]}
{"arg":{"channel":"books5","instId":"ETH-USDT-SWAP"},"data":[{"asks":[["3129.3","521.69","0","1"],["3129.57","12482.89","0","1"],["3130.46","0.04","0","1"],["3130.56","37.73","0","1"],["3130.57","30.11","0","1"]],"bids":[["3129.13","0.83","0","1"],["3129.11","0.02","0","1"],["3129.09","7.4","0","2"],["3129.07","0.01","0","1"],["3129.06","47.58","0","2"]],"instId":"ETH-USDT-SWAP","ts":"1765632006707","seqId":1158525833}]}
{"arg":{"channel":"bbo-tbt","instId":"ETH-USDT-SWAP"},"data":[{"asks":[["3129.3","521.46","0","1"]],"bids":[["3129.13","0.83","0","1"]],"ts":"1765632006727","seqId":1158525835}]}
{"arg":{"channel":"bbo-tbt","instId":"ETH-USDT-SWAP"},"data":[{"asks":[["3129.3","521.36","0","1"]],"bids":[["3129.13","0.83","0","1"]],"ts":"1765632006747","seqId":1158525837}]}
{"arg":{"channel":"tickers","instId":"ETH-USDT-SWAP"},"data":[{"instType":"SWAP","instId":"ETH-USDT-SWAP","last":"3129.3","lastSz":"0.1","askPx":"3129.3","askSz":"521.36","bidPx":"3129.13","bidSz":"0.83","open24h":"3248","high24h":"3315.64","low24h":"3072.11","sodUtc0":"3108.41","sodUtc8":"3174.4","volCcy24h":"19460111.91","vol24h":"194601119.1","ts":"1765632006748"}]}
{"arg":{"channel":"bbo-tbt","instId":"ETH-USDT-SWAP"},"data":[{"asks":[["3129.3","521.27","0","1"]],"bids":[["3129.13","0.83","0","1"]],"ts":"1765632006767","seqId":1158525839}]}
{"arg":{"channel":"books","instId":"ETH-USDT-SWAP"},"action":"update","data":[{"asks":[["3129.3","521.27","0","1"]],"bids":[],"ts":"1765632006807","checksum":1818195424,"seqId":1158525839,"prevSeqId":1158525833}]}
{"arg":{"channel":"books5","instId":"ETH-USDT-SWAP"},"data":[{"asks":[["3129.3","521.27","0","1"],["3129.57","12482.89","0","1"],["3130.46","0.04","0","1"],["3130.56","37.73","0","1"],["3130.57","30.11","0","1"]],"bids":[["3129.13","0.83","0","1"],["3129.11","0.02","0","1"],["3129.09","7.4","0","2"],["3129.07","0.01","0","1"],["3129.06","47.58","0","2"]],"instId":"ETH-USDT-SWAP","ts":"1765632006807","seqId":1158525839}]}
{"arg":{"channel":"bbo-tbt","instId":"ETH-USDT-SWAP"},"data":[{"asks":[["3129.3","521.15","0","1"]],"bids":[["3129.13","0.83","0","1"]],"ts":"1765632006837","seqId":1158525841}]}
{"arg":{"channel":"bbo-tbt","instId":"ETH-USDT-SWAP"},"data":[{"asks":[["3129.3","521.02","0","1"]],"bids":[["3129.13","0.83","0","1"]],"ts":"1765632006847","seqId":1158525843}]}
{"arg":{"channel":"tickers","instId":"ETH-USDT-SWAP"},"data":[{"instType":"SWAP","instId":"ETH-USDT-SWAP","last":"3129.3","lastSz":"0.13","askPx":"3129.3","askSz":"521.02","bidPx":"3129.13","bidSz":"0.83","open24h":"3248","high24h":"3315.64","low24h":"3072.11","sodUtc0":"3108.41","sodUtc8":"3174.4","volCcy24h":"19460111.944","vol24h":"194601119.44","ts":"1765632006849"}]}
{"arg":{"channel":"books","instId":"ETH-USDT-SWAP"},"action":"update","data":[{"asks":[["3129.3","521.02","0","1"]],"bids":[],"ts":"1765632006907","checksum":-537023558,"seqId":1158525843,"prevSeqId":1158525839}]}
{"arg":{"channel":"books5","instId":"ETH-USDT-SWAP"},"data":[{"asks":[["3129.3","521.02","0","1"],["3129.57","12482.89","0","1"],["3130.46","0.04","0","1"],["3130.56","37.73","0","1"],["3130.57","30.11","0","1"]],"bids":[["3129.13","0.83","0","1"],["3129.11","0.02","0","1"],["3129.09","7.4","0","2"],["3129.07","0.01","0","1"],["3129.06","47.58","0","2"]],"instId":"ETH-USDT-SWAP","ts":"1765632006907","seqId":1158525843}]}
{"arg":{"channel":"bbo-tbt","instId":"ETH-USDT-SWAP"},"data":[{"asks":[["3129.3","520.89","0","1"]],"bids":[["3129.13","0.83","0","1"]],"ts":"1765632006927","seqId":1158525845}]}
{"arg":{"channel":"tickers","instId":"ETH-USDT-SWAP"},"data":[{"instType":"SWAP","instId":"ETH-USDT-SWAP","last":"3129.3","lastSz":"0.13","askPx":"3129.3","askSz":"520.89","bidPx":"3129.13","bidSz":"0.83","open24h":"3248","high24h":"3315.64","low24h":"3072.11","sodUtc0":"3108.41","sodUtc8":"3174.4","volCcy24h":"19460111.957","vol24h":"194601119.57","ts":"1765632006985"}]}
{"arg":{"channel":"books","instId":"ETH-USDT-SWAP"},"action":"update","data":[{"asks":[["3129.3","520.89","0","1"]],"bids":[],"ts":"1765632007007","checksum":381784703,"seqId":1158525845,"prevSeqId":1158525843}]}
{"arg":{"channel":"books5","instId":"ETH-USDT-SWAP"},"data":[{"asks":[["3129.3","520.89","0","1"],["3129.57","12482.89","0","1"],["3130.46","0.04","0","1"],["3130.56","37.73","0","1"],["3130.57","30.11","0","1"]],"bids":[["3129.13","0.83","0","1"],["3129.11","0.02","0","1"],["3129.09","7.4","0","2"],["3129.07","0.01","0","1"],["3129.06","47.58","0","2"]],"instId":"ETH-USDT-SWAP","ts":"1765632007007","seqId":1158525845}]}
{"arg":{"channel":"bbo-tbt","instId":"ETH-USDT-SWAP"},"data":[{"asks":[["3129.3","520.79","0","1"]],"bids":[["3129.13","0.83","0","1"]],"ts":"1765632007067","seqId":1158525847}]}
{"arg":{"channel":"bbo-tbt","instId":"ETH-USDT-SWAP"},"data":[{"asks":[["3129.3","520.71","0","1"]],"bids":[["3129.13","0.83","0","1"]],"ts":"1765632007077","seqId":1158525849}]}
{"arg":{"channel":"books","instId":"ETH-USDT-SWAP"},"action":"update","data":[{"asks":[["3129.3","520.71","0","1"]],"bids":[],"ts":"1765632007107","checksum":-920018949,"seqId":1158525849,"prevSeqId":1158525845}]}
{"arg":{"channel":"books5","instId":"ETH-USDT-SWAP"},"data":[{"asks":[["3129.3","520.71","0","1"],["3129.57","12482.89","0","1"],["3130.46","0.04","0","1"],["3130.56","37.73","0","1"],["3130.57","30.11","0","1"]],"bids":[["3129.13","0.83","0","1"],["3129.11","0.02","0","1"],["3129.09","7.4","0","2"],["3129.07","0.01","0","1"],["3129.06","47.58","0","2"]],"instId":"ETH-USDT-SWAP","ts":"1765632007107","seqId":1158525849}]}
{"arg":{"channel":"bbo-tbt","instId":"ETH-USDT-SWAP"},"data":[{"asks":[["3129.3","520.58","0","1"]],"bids":[["3129.13","0.83","0","1"]],"ts":"1765632007157","seqId":1158525851}]}
{"arg":{"channel":"bbo-tbt","instId":"ETH-USDT-SWAP"},"data":[{"asks":[["3129.3","520.58","0","1"]],"bids":[["3129.13","0.3","0","1"]],"ts":"1765632007187","seqId":1158525853}]}
{"arg":{"channel":"bbo-tbt","instId":"ETH-USDT-SWAP"},"data":[{"asks":[["3129.3","520.36","0","1"]],"bids":[["3129.13","0.3","0","1"]],"ts":"1765632007197","seqId":1158525855}]}
{"arg":{"channel":"books","instId":"ETH-USDT-SWAP"},"action":"update","data":[{"asks":[["3129.3","520.36","0","1"]],"bids":[["3129.13","0.3","0","1"]],"ts":"1765632007207","checksum":-1740278760,"seqId":1158525855,"prevSeqId":1158525849}]}
{"arg":{"channel":"books5","instId":"ETH-USDT-SWAP"},"data":[{"asks":[["3129.3","520.36","0","1"],["3129.57","12482.89","0","1"],["3130.46","0.04","0","1"],["3130.56","37.73","0","1"],["3130.57","30.11","0","1"]],"bids":[["3129.13","0.3","0","1"],["3129.11","0.02","0","1"],["3129.09","7.4","0","2"],["3129.07","0.01","0","1"],["3129.06","47.58","0","2"]],"instId":"ETH-USDT-SWAP","ts":"1765632007207","seqId":1158525855}]}
{"arg":{"channel":"tickers","instId":"ETH-USDT-SWAP"},"data":[{"instType":"SWAP","instId":"ETH-USDT-SWAP","last":"3129.3","lastSz":"0.08","askPx":"3129.3","askSz":"520.71","bidPx":"3129.13","bidSz":"0.83","open24h":"3248","high24h":"3315.64","low24h":"3072.11","sodUtc0":"3108.41","sodUtc8":"3174.4","volCcy24h":"19460111.975","vol24h":"194601119.75","ts":"1765632007110"}]}
{"arg":{"channel":"tickers","instId":"ETH-USDT-SWAP"},"data":[{"instType":"SWAP","instId":"ETH-USDT-SWAP","last":"3129.3","lastSz":"0.22","askPx":"3129.3","askSz":"520.36","bidPx":"3129.13","bidSz":"0.3","open24h":"3248","high24h":"3315.64","low24h":"3072.11","sodUtc0":"3108.41","sodUtc8":"3174.4","volCcy24h":"19460112.063","vol24h":"194601120.63","ts":"1765632007265"}]}
{"arg":{"channel":"bbo-tbt","instId":"ETH-USDT-SWAP"},"data":[{"asks":[["3129.3","520.3","0","1"]],"bids":[["3129.13","0.3","0","1"]],"ts":"1765632007437","seqId":1158525857}]}
{"arg":{"channel":"books","instId":"ETH-USDT-SWAP"},"action":"update","data":[{"asks":[["3129.3","520.3","0","1"]],"bids":[],"ts":"1765632007507","checksum":772910629,"seqId":1158525857,"prevSeqId":1158525855}]}
{"arg":{"channel":"books5","instId":"ETH-USDT-SWAP"},"data":[{"asks":[["3129.3","520.3","0","1"],["3129.57","12482.89","0","1"],["3130.46","0.04","0","1"],["3130.56","37.73","0","1"],["3130.57","30.11","0","1"]],"bids":[["3129.13","0.3","0","1"],["3129.11","0.02","0","1"],["3129.09","7.4","0","2"],["3129.07","0.01","0","1"],["3129.06","47.58","0","2"]],"instId":"ETH-USDT-SWAP","ts":"1765632007507","seqId":1158525857}]}
{"arg":{"channel":"bbo-tbt","instId":"ETH-USDT-SWAP"},"data":[{"asks":[["3129.3","520.3","0","1"]],"bids":[["3129.09","7.19","0","2"]],"ts":"1765632007547","seqId":1158525863}]}
{"arg":{"channel":"tickers","instId":"ETH-USDT-SWAP"},"data":[{"instType":"SWAP","instId":"ETH-USDT-SWAP","last":"3129.3","lastSz":"0.06","askPx":"3129.3","askSz":"520.3","bidPx":"3129.13","bidSz":"0.3","open24h":"3248","high24h":"3315.64","low24h":"3072.11","sodUtc0":"3108.41","sodUtc8":"3174.4","volCcy24h":"19460112.069","vol24h":"194601120.69","ts":"1765632007489"}]}
{"arg":{"channel":"books","instId":"ETH-USDT-SWAP"},"action":"update","data":[{"asks":[["3130.63","0.04","0","2"],["3130.67","3.45","0","1"],["3135.47","0","0","0"]],"bids":[["3129.13","0","0","0"],["3129.11","0","0","0"],["3129.09","7.19","0","2"],["3123.75","4.1","0","10"],["3123.74","4.44","0","5"]],"ts":"1765632007607","checksum":-952602949,"seqId":1158525867,"prevSeqId":1158525857}]}
{"arg":{"channel":"books5","instId":"ETH-USDT-SWAP"},"data":[{"asks":[["3129.3","520.3","0","1"],["3129.57","12482.89","0","1"],["3130.46","0.04","0","1"],["3130.56","37.73","0","1"],["3130.57","30.11","0","1"]],"bids":[["3129.09","7.19","0","2"],["3129.07","0.01","0","1"],["3129.06","47.58","0","2"],["3129.02","117.47","0","1"],["3129","14.25","0","5"]],"instId":"ETH-USDT-SWAP","ts":"1765632007607","seqId":1158525867}]}
{"arg":{"channel":"bbo-tbt","instId":"ETH-USDT-SWAP"},"data":[{"asks":[["3129.3","520.06","0","1"]],"bids":[["3129.09","7.19","0","2"]],"ts":"1765632007627","seqId":1158525869}]}
{"arg":{"channel":"tickers","instId":"ETH-USDT-SWAP"},"data":[{"instType":"SWAP","instId":"ETH-USDT-SWAP","last":"3129.09","lastSz":"0.21","askPx":"3129.3","askSz":"520.3","bidPx":"3129.09","bidSz":"7.19","open24h":"3248","high24h":"3315.64","low24h":"3072.11","sodUtc0":"3108.41","sodUtc8":"3174.4","volCcy24h":"19460112.122","vol24h":"194601121.22","ts":"1765632007603"}]}
{"arg":{"channel":"bbo-tbt","instId":"ETH-USDT-SWAP"},"data":[{"asks":[["3129.3","519.96","0","1"]],"bids":[["3129.09","7.19","0","2"]],"ts":"1765632007667","seqId":1158525871}]}
{"arg":{"channel":"bbo-tbt","instId":"ETH-USDT-SWAP"},"data":[{"asks":[["3129.3","519.59","0","1"]],"bids":[["3129.09","7.19","0","2"]],"ts":"1765632007697","seqId":1158525873}]}
{"arg":{"channel":"books","instId":"ETH-USDT-SWAP"},"action":"update","data":[{"asks":[["3129.3","519.59","0","1"]],"bids":[],"ts":"1765632007707","checksum":-1084530923,"seqId":1158525873,"prevSeqId":1158525867}]}
{"arg":{"channel":"books5","instId":"ETH-USDT-SWAP"},"data":[{"asks":[["3129.3","519.59","0","1"],["3129.57","12482.89","0","1"],["3130.46","0.04","0","1"],["3130.56","37.73","0","1"],["3130.57","30.11","0","1"]],"bids":[["3129.09","7.19","0","2"],["3129.07","0.01","0","1"],["3129.06","47.58","0","2"],["3129.02","117.47","0","1"],["3129","14.25","0","5"]],"instId":"ETH-USDT-SWAP","ts":"1765632007707","seqId":1158525873}]}
{"arg":{"channel":"bbo-tbt","instId":"ETH-USDT-SWAP"},"data":[{"asks":[["3129.3","519.51","0","1"]],"bids":[["3129.09","7.19","0","2"]],"ts":"1765632007727","seqId":1158525875}]}
{"arg":{"channel":"bbo-tbt","instId":"ETH-USDT-SWAP"},"data":[{"asks":[["3129.3","519.41","0","1"]],"bids":[["3129.09","7.19","0","2"]],"ts":"1765632007747","seqId":1158525877}]}
{"arg":{"channel":"tickers","instId":"ETH-USDT-SWAP"},"data":[{"instType":"SWAP","instId":"ETH-USDT-SWAP","last":"3129.3","lastSz":"0.37","askPx":"3129.3","askSz":"519.59","bidPx":"3129.09","bidSz":"7.19","open24h":"3248","high24h":"3315.64","low24h":"3072.11","sodUtc0":"3108.41","sodUtc8":"3174.4","volCcy24h":"19460112.193","vol24h":"194601121.93","ts":"1765632007710"}]}
{"arg":{"channel":"bbo-tbt","instId":"ETH-USDT-SWAP"},"data":[{"asks":[["3129.3","519.29","0","1"]],"bids":[["3129.09","7.19","0","2"]],"ts":"1765632007777","seqId":1158525879}]}
{"arg":{"channel":"bbo-tbt","instId":"ETH-USDT-SWAP"},"data":[{"asks":[["3129.3","519.05","0","1"]],"bids":[["3129.09","7.19","0","2"]],"ts":"1765632007807","seqId":1158525881}]}
{"arg":{"channel":"books","instId":"ETH-USDT-SWAP"},"action":"update","data":[{"asks":[["3129.3","519.05","0","1"]],"bids":[],"ts":"1765632007807","checksum":-1608136536,"seqId":1158525881,"prevSeqId":1158525873}]}
{"arg":{"channel":"books5","instId":"ETH-USDT-SWAP"},"data":[{"asks":[["3129.3","519.05","0","1"],["3129.57","12482.89","0","1"],["3130.46","0.04","0","1"],["3130.56","37.73","0","1"],["3130.57","30.11","0","1"]],"bids":[["3129.09","7.19","0","2"],["3129.07","0.01","0","1"],["3129.06","47.58","0","2"],["3129.02","117.47","0","1"],["3129","14.25","0","5"]],"instId":"ETH-USDT-SWAP","ts":"1765632007807","seqId":1158525881}]}
{"arg":{"channel":"bbo-tbt","instId":"ETH-USDT-SWAP"},"data":[{"asks":[["3129.3","518.96","0","1"]],"bids":[["3129.09","7.19","0","2"]],"ts":"1765632007817","seqId":1158525883}]}
{"arg":{"channel":"bbo-tbt","instId":"ETH-USDT-SWAP"},"data":[{"asks":[["3129.3","518.96","0","1"]],"bids":[["3129.06","27.67","0","2"]],"ts":"1765632007837","seqId":1158525903}]}
{"arg":{"channel":"bbo-tbt","instId":"ETH-USDT-SWAP"},"data":[{"asks":[["3129.3","518.83","0","1"]],"bids":[["3129.06","27.67","0","2"]],"ts":"1765632007897","seqId":1158525977}]}
{"arg":{"channel":"tickers","instId":"ETH-USDT-SWAP"},"data":[{"instType":"SWAP","instId":"ETH-USDT-SWAP","last":"3129.3","lastSz":"0.09","askPx":"3129.3","askSz":"518.96","bidPx":"3129.09","bidSz":"7.19","open24h":"3248","high24h":"3315.64","low24h":"3072.11","sodUtc0":"3108.41","sodUtc8":"3174.4","volCcy24h":"19460112.256","vol24h":"194601122.56","ts":"1765632007820"}]}
{"arg":{"channel":"bbo-tbt","instId":"ETH-USDT-SWAP"},"data":[{"asks":[["3129.3","518.75","0","1"]],"bids":[["3129.06","27.67","0","2"]],"ts":"1765632007907","seqId":1158525979}]}
{"arg":{"channel":"books","instId":"ETH-USDT-SWAP"},"action":"update","data":[{"asks":[["3129.3","518.75","0","1"],["3130.91","0.73","0","3"],["3131.09","0.01","0","1"],["3131.22","7.37","0","1"],["3135.45","0","0","0"],["3135.46","0","0","0"]],"bids":[["3129.09","0","0","0"],["3129.07","0","0","0"],["3129.06","27.67","0","2"],["3123.73","0.04","0","2"],["3123.71","0.26","0","3"]],"ts":"1765632007907","checksum":-1182498996,"seqId":1158525979,"prevSeqId":1158525881}]}
{"arg":{"channel":"books5","instId":"ETH-USDT-SWAP"},"data":[{"asks":[["3129.3","518.75","0","1"],["3129.57","12482.89","0","1"],["3130.46","0.04","0","1"],["3130.56","37.73","0","1"],["3130.57","30.11","0","1"]],"bids":[["3129.06","27.67","0","2"],["3129.02","117.47","0","1"],["3129","14.25","0","5"],["3128.99","0.06","0","1"],["3128.97","0.92","0","1"]],"instId":"ETH-USDT-SWAP","ts":"1765632007907","seqId":1158525979}]}
{"arg":{"channel":"bbo-tbt","instId":"ETH-USDT-SWAP"},"data":[{"asks":[["3129.3","518.68","0","1"]],"bids":[["3129.06","27.67","0","2"]],"ts":"1765632007977","seqId":1158526009}]}
{"arg":{"channel":"tickers","instId":"ETH-USDT-SWAP"},"data":[{"instType":"SWAP","instId":"ETH-USDT-SWAP","last":"3129.3","lastSz":"0.08","askPx":"3129.3","askSz":"518.75","bidPx":"3129.06","bidSz":"27.67","open24h":"3248","high24h":"3315.64","low24h":"3072.11","sodUtc0":"3108.41","sodUtc8":"3174.4","volCcy24h":"19460114.988","vol24h":"194601149.88","ts":"1765632007965"}]}
{"arg":{"channel":"bbo-tbt","instId":"ETH-USDT-SWAP"},"data":[{"asks":[["3129.3","518.58","0","1"]],"bids":[["3129.06","27.67","0","2"]],"ts":"1765632007997","seqId":1158526011}]}
{"arg":{"channel":"books","instId":"ETH-USDT-SWAP"},"action":"update","data":[{"asks":[["3129.3","518.58","0","1"]],"bids":[],"ts":"1765632008007","checksum":565354640,"seqId":1158526011,"prevSeqId":1158525979}]}
{"arg":{"channel":"books5","instId":"ETH-USDT-SWAP"},"data":[{"asks":[["3129.3","518.58","0","1"],["3129.57","12482.89","0","1"],["3130.46","0.04","0","1"],["3130.56","37.73","0","1"],["3130.57","30.11","0","1"]],"bids":[["3129.06","27.67","0","2"],["3129.02","117.47","0","1"],["3129","14.25","0","5"],["3128.99","0.06","0","1"],["3128.97","0.92","0","1"]],"instId":"ETH-USDT-SWAP","ts":"1765632008007","seqId":1158526011}]}
{"arg":{"channel":"bbo-tbt","instId":"ETH-USDT-SWAP"},"data":[{"asks":[["3129.3","518.44","0","1"]],"bids":[["3129.06","27.67","0","2"]],"ts":"1765632008037","seqId":1158526039}]}
{"arg":{"channel":"books","instId":"ETH-USDT-SWAP"},"action":"update","data":[{"asks":[["3129.3","518.44","0","1"]],"bids":[],"ts":"1765632008107","checksum":32483605,"seqId":1158526047,"prevSeqId":1158526011}]}
{"arg":{"channel":"books5","instId":"ETH-USDT-SWAP"},"data":[{"asks":[["3129.3","518.44","0","1"],["3129.57","12482.89","0","1"],["3130.46","0.04","0","1"],["3130.56","37.73","0","1"],["3130.57","30.11","0","1"]],"bids":[["3129.06","27.67","0","2"],["3129.02","117.47","0","1"],["3129","14.25","0","5"],["3128.99","0.06","0","1"],["3128.97","0.92","0","1"]],"instId":"ETH-USDT-SWAP","ts":"1765632008107","seqId":1158526047}]}
{"arg":{"channel":"bbo-tbt","instId":"ETH-USDT-SWAP"},"data":[{"asks":[["3129.3","518.34","0","1"]],"bids":[["3129.06","27.67","0","2"]],"ts":"1765632008147","seqId":1158526085}]}
{"arg":{"channel":"bbo-tbt","instId":"ETH-USDT-SWAP"},"data":[{"asks":[["3129.3","518.21","0","1"]],"bids":[["3129.06","27.67","0","2"]],"ts":"1765632008197","seqId":1158526097}]}
{"arg":{"channel":"tickers","instId":"ETH-USDT-SWAP"},"data":[{"instType":"SWAP","instId":"ETH-USDT-SWAP","last":"3129.3","lastSz":"0.14","askPx":"3129.3","askSz":"518.44","bidPx":"3129.06","bidSz":"27.67","open24h":"3248","high24h":"3315.64","low24h":"3072.11","sodUtc0":"3108.41","sodUtc8":"3174.4","volCcy24h":"19460115.019","vol24h":"194601150.19","ts":"1765632008099"}]}
{"arg":{"channel":"books","instId":"ETH-USDT-SWAP"},"action":"update","data":[{"asks":[["3129.3","518.21","0","1"]],"bids":[],"ts":"1765632008207","checksum":1296931297,"seqId":1158526097,"prevSeqId":1158526047}]}
{"arg":{"channel":"books5","instId":"ETH-USDT-SWAP"},"data":[{"asks":[["3129.3","518.21","0","1"],["3129.57","12482.89","0","1"],["3130.46","0.04","0","1"],["3130.56","37.73","0","1"],["3130.57","30.11","0","1"]],"bids":[["3129.06","27.67","0","2"],["3129.02","117.47","0","1"],["3129","14.25","0","5"],["3128.99","0.06","0","1"],["3128.97","0.92","0","1"]],"instId":"ETH-USDT-SWAP","ts":"1765632008207","seqId":1158526097}]}
{"arg":{"channel":"bbo-tbt","instId":"ETH-USDT-SWAP"},"data":[{"asks":[["3129.3","518.12","0","1"]],"bids":[["3129.06","27.67","0","2"]],"ts":"1765632008237","seqId":1158526165}]}
{"arg":{"channel":"bbo-tbt","instId":"ETH-USDT-SWAP"},"data":[{"asks":[["3129.3","518.04","0","1"]],"bids":[["3129.06","27.67","0","2"]],"ts":"1765632008277","seqId":1158526167}]}
{"arg":{"channel":"bbo-tbt","instId":"ETH-USDT-SWAP"},"data":[{"asks":[["3129.3","517.58","0","1"]],"bids":[["3129.06","27.67","0","2"]],"ts":"1765632008297","seqId":1158526171}]}
{"arg":{"channel":"books","instId":"ETH-USDT-SWAP"},"action":"update","data":[{"asks":[["3129.3","517.58","0","1"]],"bids":[],"ts":"1765632008307","checksum":1444236964,"seqId":1158526171,"prevSeqId":1158526097}]}
{"arg":{"channel":"books5","instId":"ETH-USDT-SWAP"},"data":[{"asks":[["3129.3","517.58","0","1"],["3129.57","12482.89","0","1"],["3130.46","0.04","0","1"],["3130.56","37.73","0","1"],["3130.57","30.11","0","1"]],"bids":[["3129.06","27.67","0","2"],["3129.02","117.47","0","1"],["3129","14.25","0","5"],["3128.99","0.06","0","1"],["3128.97","0.92","0","1"]],"instId":"ETH-USDT-SWAP","ts":"1765632008307","seqId":1158526171}]}
{"arg":{"channel":"tickers","instId":"ETH-USDT-SWAP"},"data":[{"instType":"SWAP","instId":"ETH-USDT-SWAP","last":"3129.3","lastSz":"0.13","askPx":"3129.3","askSz":"518.21","bidPx":"3129.06","bidSz":"27.67","open24h":"3248","high24h":"3315.64","low24h":"3072.11","sodUtc0":"3108.41","sodUtc8":"3174.4","volCcy24h":"19460115.042","vol24h":"194601150.42","ts":"1765632008210"}]}
{"arg":{"channel":"bbo-tbt","instId":"ETH-USDT-SWAP"},"data":[{"asks":[["3129.3","517.45","0","1"]],"bids":[["3129.06","27.67","0","2"]],"ts":"1765632008357","seqId":1158526173}]}
{"arg":{"channel":"bbo-tbt","instId":"ETH-USDT-SWAP"},"data":[{"asks":[["3129.3","517.31","0","1"]],"bids":[["3129.06","27.67","0","2"]],"ts":"1765632008397","seqId":1158526182}]}
{"arg":{"channel":"books","instId":"ETH-USDT-SWAP"},"action":"update","data":[{"asks":[["3129.3","517.31","0","1"]],"bids":[],"ts":"1765632008407","checksum":148646406,"seqId":1158526182,"prevSeqId":1158526171}]}
{"arg":{"channel":"books5","instId":"ETH-USDT-SWAP"},"data":[{"asks":[["3129.3","517.31","0","1"],["3129.57","12482.89","0","1"],["3130.46","0.04","0","1"],["3130.56","37.73","0","1"],["3130.57","30.11","0","1"]],"bids":[["3129.06","27.67","0","2"],["3129.02","117.47","0","1"],["3129","14.25","0","5"],["3128.99","0.06","0","1"],["3128.97","0.92","0","1"]],"instId":"ETH-USDT-SWAP","ts":"1765632008407","seqId":1158526182}]}
{"arg":{"channel":"tickers","instId":"ETH-USDT-SWAP"},"data":[{"instType":"SWAP","instId":"ETH-USDT-SWAP","last":"3129.3","lastSz":"0.22","askPx":"3129.3","askSz":"517.58","bidPx":"3129.06","bidSz":"27.67","open24h":"3248","high24h":"3315.64","low24h":"3072.11","sodUtc0":"3108.41","sodUtc8":"3174.4","volCcy24h":"19460115.105","vol24h":"194601151.05","ts":"1765632008311"}]}
{"arg":{"channel":"bbo-tbt","instId":"ETH-USDT-SWAP"},"data":[{"asks":[["3129.3","517.21","0","1"]],"bids":[["3129.06","27.67","0","2"]],"ts":"1765632008467","seqId":1158526186}]}
{"arg":{"channel":"bbo-tbt","instId":"ETH-USDT-SWAP"},"data":[{"asks":[["3129.3","517.14","0","1"]],"bids":[["3129.06","27.67","0","2"]],"ts":"1765632008487","seqId":1158526188}]}
{"arg":{"channel":"books","instId":"ETH-USDT-SWAP"},"action":"update","data":[{"asks":[["3129.3","517.14","0","1"]],"bids":[],"ts":"1765632008507","checksum":-1935184450,"seqId":1158526188,"prevSeqId":1158526182}]}
{"arg":{"channel":"books5","instId":"ETH-USDT-SWAP"},"data":[{"asks":[["3129.3","517.14","0","1"],["3129.57","12482.89","0","1"],["3130.46","0.04","0","1"],["3130.56","37.73","0","1"],["3130.57","30.11","0","1"]],"bids":[["3129.06","27.67","0","2"],["3129.02","117.47","0","1"],["3129","14.25","0","5"],["3128.99","0.06","0","1"],["3128.97","0.92","0","1"]],"instId":"ETH-USDT-SWAP","ts":"1765632008507","seqId":1158526188}]}
{"arg":{"channel":"tickers","instId":"ETH-USDT-SWAP"},"data":[{"instType":"SWAP","instId":"ETH-USDT-SWAP","last":"3129.3","lastSz":"0.14","askPx":"3129.3","askSz":"517.31","bidPx":"3129.06","bidSz":"27.67","open24h":"3248","high24h":"3315.64","low24h":"3072.11","sodUtc0":"3108.41","sodUtc8":"3174.4","volCcy24h":"19460115.132","vol24h":"194601151.32","ts":"1765632008465"}]}
{"arg":{"channel":"bbo-tbt","instId":"ETH-USDT-SWAP"},"data":[{"asks":[["3129.3","517.02","0","1"]],"bids":[["3129.06","27.14","0","2"]],"ts":"1765632008637","seqId":1158526232}]}
{"arg":{"channel":"tickers","instId":"ETH-USDT-SWAP"},"data":[{"instType":"SWAP","instId":"ETH-USDT-SWAP","last":"3129.3","lastSz":"0.07","askPx":"3129.3","askSz":"517.14","bidPx":"3129.06","bidSz":"27.67","open24h":"3248","high24h":"3315.64","low24h":"3072.11","sodUtc0":"3108.41","sodUtc8":"3174.4","volCcy24h":"19460115.149","vol24h":"194601151.49","ts":"1765632008611"}]}
{"arg":{"channel":"books","instId":"ETH-USDT-SWAP"},"action":"update","data":[{"asks":[["3129.3","517.02","0","1"]],"bids":[["3129.06","27.14","0","2"]],"ts":"1765632008707","checksum":-913373560,"seqId":1158526232,"prevSeqId":1158526188}]}
{"arg":{"channel":"books5","instId":"ETH-USDT-SWAP"},"data":[{"asks":[["3129.3","517.02","0","1"],["3129.57","12482.89","0","1"],["3130.46","0.04","0","1"],["3130.56","37.73","0","1"],["3130.57","30.11","0","1"]],"bids":[["3129.06","27.14","0","2"],["3129.02","117.47","0","1"],["3129","14.25","0","5"],["3128.99","0.06","0","1"],["3128.97","0.92","0","1"]],"instId":"ETH-USDT-SWAP","ts":"1765632008707","seqId":1158526232}]}
{"arg":{"channel":"tickers","instId":"ETH-USDT-SWAP"},"data":[{"instType":"SWAP","instId":"ETH-USDT-SWAP","last":"3129.3","lastSz":"0.12","askPx":"3129.3","askSz":"517.02","bidPx":"3129.06","bidSz":"27.14","open24h":"3248","high24h":"3315.64","low24h":"3072.11","sodUtc0":"3108.41","sodUtc8":"3174.4","volCcy24h":"19460115.214","vol24h":"194601152.14","ts":"1765632008766"}]}
{"arg":{"channel":"bbo-tbt","instId":"ETH-USDT-SWAP"},"data":[{"asks":[["3129.3","516.96","0","1"]],"bids":[["3129.06","27.14","0","2"]],"ts":"1765632008807","seqId":1158526243}]}
{"arg":{"channel":"books","instId":"ETH-USDT-SWAP"},"action":"update","data":[{"asks":[["3129.3","516.96","0","1"]],"bids":[],"ts":"1765632008807","checksum":9696787,"seqId":1158526243,"prevSeqId":1158526232}]}
{"arg":{"channel":"books5","instId":"ETH-USDT-SWAP"},"data":[{"asks":[["3129.3","516.96","0","1"],["3129.57","12482.89","0","1"],["3130.46","0.04","0","1"],["3130.56","37.73","0","1"],["3130.57","30.11","0","1"]],"bids":[["3129.06","27.14","0","2"],["3129.02","117.47","0","1"],["3129","14.25","0","5"],["3128.99","0.06","0","1"],["3128.97","0.92","0","1"]],"instId":"ETH-USDT-SWAP","ts":"1765632008807","seqId":1158526243}]}
{"arg":{"channel":"bbo-tbt","instId":"ETH-USDT-SWAP"},"data":[{"asks":[["3129.3","516.86","0","1"]],"bids":[["3129.06","27.14","0","2"]],"ts":"1765632008887","seqId":1158526245}]}
{"arg":{"channel":"bbo-tbt","instId":"ETH-USDT-SWAP"},"data":[{"asks":[["3129.3","516.74","0","1"]],"bids":[["3129.06","27.14","0","2"]],"ts":"1765632008897","seqId":1158526247}]}
{"arg":{"channel":"tickers","instId":"ETH-USDT-SWAP"},"data":[{"instType":"SWAP","instId":"ETH-USDT-SWAP","last":"3129.3","lastSz":"0.06","askPx":"3129.3","askSz":"516.96","bidPx":"3129.06","bidSz":"27.14","open24h":"3248","high24h":"3315.64","low24h":"3072.11","sodUtc0":"3108.41","sodUtc8":"3174.4","volCcy24h":"19460115.22","vol24h":"194601152.2","ts":"1765632008885"}]}
{"arg":{"channel":"books","instId":"ETH-USDT-SWAP"},"action":"update","data":[{"asks":[["3129.3","516.74","0","1"]],"bids":[],"ts":"1765632008907","checksum":-503925703,"seqId":1158526247,"prevSeqId":1158526243}]}
{"arg":{"channel":"books5","instId":"ETH-USDT-SWAP"},"data":[{"asks":[["3129.3","516.74","0","1"],["3129.57","12482.89","0","1"],["3130.46","0.04","0","1"],["3130.56","37.73","0","1"],["3130.57","30.11","0","1"]],"bids":[["3129.06","27.14","0","2"],["3129.02","117.47","0","1"],["3129","14.25","0","5"],["3128.99","0.06","0","1"],["3128.97","0.92","0","1"]],"instId":"ETH-USDT-SWAP","ts":"1765632008907","seqId":1158526247}]}
{"arg":{"channel":"bbo-tbt","instId":"ETH-USDT-SWAP"},"data":[{"asks":[["3129.3","516.5","0","1"]],"bids":[["3129.06","27.14","0","2"]],"ts":"1765632008927","seqId":1158526249}]}
{"arg":{"channel":"bbo-tbt","instId":"ETH-USDT-SWAP"},"data":[{"asks":[["3132.4","28706.88","0","2"]],"bids":[["3129.06","27.14","0","2"]],"ts":"1765632008977","seqId":1158527235}]}
{"arg":{"channel":"bbo-tbt","instId":"ETH-USDT-SWAP"},"data":[{"asks":[["3132.4","28706.88","0","2"]],"bids":[["3131.07","0.02","0","1"]],"ts":"1765632008987","seqId":1158528119}]}
{"arg":{"channel":"bbo-tbt","instId":"ETH-USDT-SWAP"},"data":[{"asks":[["3132.39","0.02","0","1"]],"bids":[["3131","2.59","0","1"]],"ts":"1765632009007","seqId":1158528219}]}
{"arg":{"channel":"books","instId":"ETH-USDT-SWAP"},"action":"update","data":[{"asks":[["3129.3","0","0","0"],["3129.57","0","0","0"],["3130.46","0","0","0"],["3130.56","0","0","0"],["3130.57","0","0","0"],["3130.61","0","0","0"],["3130.63","0","0","0"],["3130.65","0","0","0"],["3130.67","0","0","0"],["3130.68","0","0","0"],["3130.69","0","0","0"],["3130.74","0","0","0"],["3130.77","0","0","0"],["3130.79","0","0","0"],["3130.86","0","0","0"],["3130.91","0","0","0"],["3130.93","0","0","0"],["3130.94","0","0","0"],["3130.99","0","0","0"],["3131","0","0","0"],["3131.01","0","0","0"],["3131.07","0","0","0"],["3131.09","0","0","0"],["3131.1","0","0","0"],["3131.18","0","0","0"],["3131.19","0","0","0"],["3131.2","0","0","0"],["3131.22","0","0","0"],["3131.23","0","0","0"],["3131.24","0","0","0"],["3131.25","0","0","0"],["3131.26","0","0","0"],["3131.27","0","0","0"],["3131.28","0","0","0"],["3131.29","0","0","0"],["3131.3","0","0","0"],["3131.31","0","0","0"],["3131.32","0","0","0"],["3131.33","0","0","0"],["3131.34","0","0","0"],["3131.35","0","0","0"],["3131.36","0","0","0"],["3131.37","0","0","0"],["3131.38","0","0","0"],["3131.39","0","0","0"],["3131.4","0","0","0"],["3131.42","0","0","0"],["3131.43","0","0","0"],["3131.44","0","0","0"],["3131.45","0","0","0"],["3131.46","0","0","0"],["3131.47","0","0","0"],["3131.48","0","0","0"],["3131.5","0","0","0"],["3131.51","0","0","0"],["3131.52","0","0","0"],["3131.53","0","0","0"],["3131.56","0","0","0"],["3131.58","0","0","0"],["3131.59","0","0","0"],["3131.6","0","0","0"],["3131.61","0","0","0"],["3131.63","0","0","0"],["3131.64","0","0","0"],["3131.65","0","0","0"],["3131.66","0","0","0"],["3131.67","0","0","0"],["3131.68","0","0","0"],["3131.7","0","0","0"],["3131.71","0","0","0"],["3131.72","0","0","0"],["3131.73","0","0","0"],["3131.74","0","0","0"],["3131.75","0","0","0"],["3131.76","0","0","0"],["3131.77","0","0","0"],["3131.78","0","0","0"],["3131.8","0","0","0"],["3131.81","0","0","0"],["3131.82","0","0","0"],["3131.83","0","0","0"],["3131.84","0","0","0"],["3131.86","0","0","0"],["3131.87","0","0","0"],["3131.88","0","0","0"],["3131.89","0","0","0"],["3131.9","0","0","0"],["3131.91","0","0","0"],["3131.92","0","0","0"],["3131.93","0","0","0"],["3131.94","0","0","0"],["3131.95","0","0","0"],["3131.96","0","0","0"],["3131.97","0","0","0"],["3131.98","0","0","0"],["3132","0","0","0"],["3132.01","0","0","0"],["3132.02","0","0","0"],["3132.03","0","0","0"],["3132.04","0","0","0"],["3132.05","0","0","0"],["3132.07","0","0","0"],["3132.08","0","0","0"],["3132.1","0","0","0"],["3132.11","0","0","0"],["3132.13","0","0","0"],["3132.14","0","0","0"],["3132.15","0","0","0"],["3132.16","0","0","0"],["3132.17","0","0","0"],["3132.18","0","0","0"],["3132.2","0","0","0"],["3132.21","0","0","0"],["3132.22","0","0","0"],["3132.23","0","0","0"],["3132.24","0","0","0"],["3132.25","0","0","0"],["3132.26","0","0","0"],["3132.27","0","0","0"],["3132.28","0","0","0"],["3132.29","0","0","0"],["3132.3","0","0","0"],["3132.31","0","0","0"],["3132.32","0","0","0"],["3132.33","0","0","0"],["3132.34","0","0","0"],["3132.36","0","0","0"],["3132.37","0","0","0"],["3132.38","0","0","0"],["3132.4","28706.88","0","2"],["3135.45","17.6","0","2"],["3135.46","5.93","0","1"],["3135.47","45.22","0","6"],["3135.48","8.08","0","6"],["3135.49","1.17","0","2"],["3135.5","21617.05","0","12"],["3135.51","4.83","0","8"],["3135.53","0.51","0","3"],["3135.54","0.03","0","2"],["3135.56","0.14","0","6"],["3135.57","1.28","0","4"],["3135.58","0.49","0","4"],["3135.6","66.39","0","6"],["3135.61","0.01","0","1"],["3135.62","2.05","0","2"],["3135.63","40.46","0","2"],["3135.64","30.26","0","4"],["3135.65","0.02","0","1"],["3135.66","57.34","0","5"],["3135.67","5.86","0","2"],["3135.68","0.05","0","2"],["3135.69","12.05","0","2"],["3135.7","300.02","0","5"],["3135.71","94.85","0","9"],["3135.72","4.88","0","2"],["3135.73","1.45","0","1"],["3135.74","50.04","0","1"],["3135.75","0.3","0","5"],["3135.77","2.07","0","5"],["3135.78","1.66","0","6"],["3135.8","1209.48","0","6"],["3135.81","0.06","0","2"],["3135.83","0.1","0","2"],["3135.84","1177.62","0","2"],["3135.85","0.66","0","3"],["3135.86","90.16","0","3"],["3135.87","0.44","0","3"],["3135.89","90.25","0","4"],["3135.9","0.18","0","6"],["3135.91","1921.91","0","6"],["3135.92","0.05","0","3"],["3135.93","54.97","0","2"],["3135.94","2.19","0","3"],["3135.96","127.91","0","4"],["3135.97","37.26","0","6"],["3135.98","0.05","0","5"],["3135.99","0.07","0","1"],["3136","19999.71","0","202"],["3136.01","0.32","0","2"],["3136.02","2.7","0","6"],["3136.04","14.19","0","6"],["3136.05","0.11","0","2"],["3136.08","0.65","0","6"],["3136.11","37.79","0","3"],["3136.13","13.91","0","2"],["3136.14","1.69","0","7"],["3136.16","0.05","0","1"],["3136.17","3.87","0","3"],["3136.19","107.92","0","2"],["3136.2","9.83","0","7"],["3136.21","0.19","0","2"],["3136.22","0.34","0","4"],["3136.24","0.93","0","7"],["3136.25","0.59","0","3"],["3136.26","8.89","0","4"],["3136.27","0.07","0","3"],["3136.28","0.52","0","1"],["3136.29","0.08","0","3"],["3136.3","83.17","0","3"],["3136.31","0.8","0","3"],["3136.32","1.39","0","2"],["3136.34","3558.67","0","2"],["3136.35","74.22","0","7"],["3136.36","4.19","0","7"],["3136.37","0.02","0","1"],["3136.38","1.17","0","2"],["3136.39","0.05","0","2"],["3136.4","43294.39","0","10"],["3136.41","1.95","0","1"],["3136.42","0.04","0","2"],["3136.43","1.69","0","3"],["3136.44","0.91","0","1"],["3136.45","0.01","0","1"],["3136.46","2.41","0","2"],["3136.47","0.68","0","4"],["3136.49","12.26","0","1"],["3136.5","153.53","0","9"],["3136.51","0.02","0","1"],["3136.53","0.16","0","1"],["3136.54","0.03","0","3"],["3136.55","208.96","0","3"],["3136.56","1.28","0","3"],["3136.57","0.11","0","2"],["3136.58","0.7","0","4"],["3136.6","0.01","0","1"],["3136.61","2.84","0","7"],["3136.62","0.2","0","2"],["3136.63","4.81","0","4"],["3136.64","6.38","0","6"],["3136.65","0.24","0","4"],["3136.66","0.01","0","1"],["3136.67","264.16","0","18"],["3136.68","0.6","0","1"],["3136.69","0.05","0","1"],["3136.7","0.01","0","1"],["3136.71","0.05","0","2"],["3136.72","16.01","0","2"],["3136.73","0.33","0","2"],["3136.75","0.04","0","1"],["3136.76","0.73","0","2"],["3136.77","25.84","0","3"],["3136.78","0.63","0","5"],["3136.79","0.01","0","1"],["3136.8","38.31","0","9"],["3136.81","2.37","0","4"],["3136.82","0.3","0","2"],["3136.83","0.07","0","1"],["3136.84","0.5","0","2"],["3136.85","34.58","0","5"],["3136.86","0.25","0","3"],["3136.87","0.01","0","1"],["3136.88","1.07","0","2"],["3136.89","38.24","0","3"],["3136.9","100.45","0","4"],["3136.91","0.45","0","2"],["3136.92","27.76","0","5"],["3136.93","0.13","0","1"],["3136.94","1.28","0","2"],["3136.95","219.91","0","1"]],"bids":[["3131","2.59","0","1"],["3130.99","0.05","0","1"],["3130.94","0.01","0","1"],["3130.91","0.7","0","2"],["3130.86","13.9","0","1"],["3130.79","0.29","0","1"],["3130.77","0.05","0","3"],["3130.74","0.02","0","1"],["3130.69","0.01","0","1"],["3130.68","0.06","0","1"],["3130.67","3.45","0","1"],["3130.65","0.01","0","1"],["3130.63","0.04","0","2"],["3130.62","0.92","0","1"],["3130.61","0.09","0","1"],["3130.57","30.11","0","1"],["3130.56","37.73","0","1"],["3130.46","0.04","0","1"],["3130.44","0.01","0","1"],["3130.4","11.94","0","5"],["3130.39","0.1","0","1"],["3130.27","0.02","0","2"],["3130.26","0.47","0","1"],["3130.22","0.03","0","1"],["3130.21","36.67","0","2"],["3130.2","0.06","0","2"],["3130.13","0.97","0","2"],["3130.09","90.05","0","1"],["3130.07","0.03","0","1"],["3130.04","0.02","0","1"],["3130.02","10.35","0","1"],["3130","133.87","0","33"],["3129.94","0.03","0","2"],["3129.93","0.01","0","1"],["3129.92","0.06","0","2"],["3129.91","4.76","0","2"],["3129.87","0.03","0","2"],["3129.84","0.2","0","1"],["3129.81","0.04","0","1"],["3129.79","59.07","0","1"],["3129.78","22.85","0","2"],["3129.76","2.11","0","3"],["3129.75","68.63","0","3"],["3129.73","13.95","0","1"],["3129.71","0.36","0","1"],["3129.7","0.27","0","1"],["3129.69","9.54","0","1"],["3129.65","0.74","0","4"],["3129.64","0.05","0","1"],["3129.6","38.16","0","7"],["3129.59","0.03","0","1"],["3129.57","25.5","0","1"],["3129.56","49.9","0","1"],["3129.55","0.67","0","1"],["3129.54","13.92","0","2"],["3129.53","0.01","0","1"],["3129.5","1.31","0","5"],["3129.49","0.14","0","5"],["3129.47","0.02","0","1"],["3129.46","0.05","0","2"],["3129.43","5.93","0","1"],["3129.42","0.2","0","1"],["3129.39","0.29","0","1"],["3129.37","0.01","0","1"],["3129.35","16","0","2"],["3129.34","0.01","0","1"],["3129.33","99.05","0","2"],["3129.3","31.25","0","3"],["3129.29","0.59","0","1"],["3129.27","0.12","0","3"],["3129.25","0.19","0","2"],["3129.23","0.25","0","3"],["3129.22","0.01","0","1"],["3129.21","11.05","0","2"],["3129.2","28.04","0","4"],["3129.19","0.08","0","2"],["3129.17","37.73","0","1"],["3129.16","0.11","0","1"],["3129.15","0.01","0","1"],["3129.14","0.08","0","3"],["3129.13","3.77","0","2"],["3129.12","23.52","0","1"],["3129.11","0.02","0","1"],["3129.1","2.21","0","2"],["3129.09","7.42","0","4"],["3129.07","0.08","0","8"],["3129.05","107.53","0","3"],["3129.04","90.19","0","2"],["3129.02","117.48","0","2"],["3129","257.25","0","18"],["3128.99","0.08","0","2"],["3128.97","57.68","0","3"],["3128.95","0.74","0","3"],["3128.94","1.53","0","1"],["3128.89","171.45","0","6"],["3128.88","1.74","0","2"],["3128.86","0.12","0","3"],["3128.85","114.47","0","7"],["3128.83","0.21","0","2"],["3128.81","1.22","0","2"],["3128.8","1.36","0","3"],["3128.75","0.16","0","3"],["3128.7","0.02","0","1"],["3128.68","0.04","0","2"],["3128.67","0.1","0","1"],["3128.66","0.32","0","3"],["3128.65","92.39","0","6"],["3128.63","2.01","0","5"],["3128.61","0.23","0","3"],["3128.6","8.7","0","3"],["3128.59","0.17","0","2"],["3128.57","0.61","0","2"],["3128.55","0.01","0","1"],["3128.54","3.34","0","4"],["3128.53","0.05","0","1"],["3128.51","0.01","0","1"],["3128.5","5.82","0","5"],["3128.47","1.12","0","1"],["3128.44","0.32","0","2"],["3128.4","4.05","0","9"],["3128.36","0.33","0","2"],["3128.35","7.48","0","1"],["3128.33","5.82","0","3"],["3128.32","0.23","0","3"],["3128.31","0.03","0","2"],["3128.3","6.13","0","2"],["3128.29","0.24","0","3"],["3128.25","0.03","0","3"],["3128.24","9.98","0","1"],["3128.21","232.36","0","7"],["3128.2","15.24","0","2"],["3128.18","1","0","5"],["3128.17","13.88","0","1"],["3128.16","0.05","0","2"],["3128.15","0.38","0","3"],["3128.13","0.1","0","2"],["3128.08","4.03","0","4"],["3128.06","0.1","0","1"],["3128.05","0.02","0","2"],["3128.02","1.92","0","4"],["3128.01","0.24","0","5"],["3128","3148.99","0","123"],["3127.99","0.4","0","2"],["3127.97","0.33","0","5"],["3127.93","36.87","0","3"],["3127.88","4.76","0","3"],["3127.83","0.02","0","1"],["3127.75","0.04","0","3"],["3127.74","0.18","0","1"],["3127.71","11","0","1"],["3127.67","4.75","0","5"],["3127.64","0.01","0","1"],["3127.63","3100.24","0","7"],["3127.5","94.31","0","20"],["3127.44","0.01","0","1"],["3127.43","9.98","0","4"],["3127.4","24.46","0","8"],["3127.37","1.34","0","4"],["3127.29","1.92","0","2"],["3127.27","4.05","0","5"],["3127.25","0.39","0","5"],["3127.19","0.07","0","2"],["3127.15","3456","0","1"],["3127.14","0.02","0","2"],["3127.11","0.63","0","3"],["3127.05","0.1","0","2"],["3127","165.45","0","19"],["3126.91","13.93","0","3"],["3126.88","99.25","0","3"],["3126.81","193.68","0","4"],["3126.67","310.36","0","16"],["3126.65","0.61","0","7"],["3126.59","12.71","0","5"],["3126.5","1229.42","0","10"],["3126.4","150.57","0","11"],["3126.35","0.29","0","2"],["3126.29","0.02","0","2"],["3126.26","0.61","0","3"],["3126.21","0.62","0","4"],["3126.2","46.99","0","10"],["3126.19","355.02","0","2"],["3126.15","1.38","0","5"],["3126.1","12.26","0","4"],["3126.06","0.09","0","3"],["3126.05","0.61","0","7"],["3126","581.82","0","64"],["3125.92","0.05","0","3"],["3125.9","39.99","0","2"],["3125.78","1.35","0","5"],["3125.75","174.61","0","10"],["3125.74","0.21","0","5"],["3125.72","116.6","0","7"],["3125.6","8.22","0","17"],["3125.56","0.38","0","3"],["3125.53","15.5","0","4"],["3125.51","0.74","0","2"],["3125.33","11.96","0","5"],["3125.22","0.87","0","5"],["3125.16","2096.78","0","6"],["3125.15","150.23","0","9"],["3125.14","10.45","0","6"],["3125.02","0","0","0"],["3125","0","0","0"],["3124.98","0","0","0"],["3124.96","0","0","0"],["3124.94","0","0","0"],["3124.92","0","0","0"],["3124.91","0","0","0"],["3124.9","0","0","0"],["3124.89","0","0","0"],["3124.88","0","0","0"],["3124.87","0","0","0"],["3124.86","0","0","0"],["3124.85","0","0","0"],["3124.84","0","0","0"],["3124.83","0","0","0"],["3124.82","0","0","0"],["3124.81","0","0","0"],["3124.8","0","0","0"],["3124.78","0","0","0"],["3124.77","0","0","0"],["3124.76","0","0","0"],["3124.75","0","0","0"],["3124.74","0","0","0"],["3124.73","0","0","0"],["3124.72","0","0","0"],["3124.71","0","0","0"],["3124.7","0","0","0"],["3124.69","0","0","0"],["3124.68","0","0","0"],["3124.67","0","0","0"],["3124.66","0","0","0"],["3124.65","0","0","0"],["3124.64","0","0","0"],["3124.63","0","0","0"],["3124.62","0","0","0"],["3124.61","0","0","0"],["3124.6","0","0","0"],["3124.59","0","0","0"],["3124.58","0","0","0"],["3124.56","0","0","0"],["3124.55","0","0","0"],["3124.54","0","0","0"],["3124.53","0","0","0"],["3124.52","0","0","0"],["3124.51","0","0","0"],["3124.5","0","0","0"],["3124.49","0","0","0"],["3124.48","0","0","0"],["3124.47","0","0","0"],["3124.46","0","0","0"],["3124.45","0","0","0"],["3124.44","0","0","0"],["3124.43","0","0","0"],["3124.42","0","0","0"],["3124.4","0","0","0"],["3124.39","0","0","0"],["3124.38","0","0","0"],["3124.37","0","0","0"],["3124.36","0","0","0"],["3124.35","0","0","0"],["3124.34","0","0","0"],["3124.33","0","0","0"],["3124.32","0","0","0"],["3124.31","0","0","0"],["3124.3","0","0","0"],["3124.29","0","0","0"],["3124.28","0","0","0"],["3124.27","0","0","0"],["3124.25","0","0","0"],["3124.24","0","0","0"],["3124.23","0","0","0"],["3124.22","0","0","0"],["3124.21","0","0","0"],["3124.2","0","0","0"],["3124.19","0","0","0"],["3124.18","0","0","0"],["3124.17","0","0","0"],["3124.16","0","0","0"],["3124.15","0","0","0"],["3124.14","0","0","0"],["3124.13","0","0","0"],["3124.12","0","0","0"],["3124.11","0","0","0"],["3124.1","0","0","0"],["3124.09","0","0","0"],["3124.08","0","0","0"],["3124.07","0","0","0"],["3124.06","0","0","0"],["3124.05","0","0","0"],["3124.04","0","0","0"],["3124.03","0","0","0"],["3124.02","0","0","0"],["3124.01","0","0","0"],["3124","0","0","0"],["3123.99","0","0","0"],["3123.98","0","0","0"],["3123.97","0","0","0"],["3123.95","0","0","0"],["3123.94","0","0","0"],["3123.93","0","0","0"],["3123.92","0","0","0"],["3123.9","0","0","0"],["3123.88","0","0","0"],["3123.87","0","0","0"],["3123.86","0","0","0"],["3123.85","0","0","0"],["3123.84","0","0","0"],["3123.83","0","0","0"],["3123.82","0","0","0"],["3123.81","0","0","0"],["3123.8","0","0","0"],["3123.79","0","0","0"],["3123.78","0","0","0"],["3123.77","0","0","0"],["3123.76","0","0","0"],["3123.75","0","0","0"],["3123.74","0","0","0"],["3123.73","0","0","0"],["3123.71","0","0","0"]],"ts":"1765632009007","checksum":-1859213170,"seqId":1158528219,"prevSeqId":1158526247}]}
{"arg":{"channel":"books5","instId":"ETH-USDT-SWAP"},"data":[{"asks":[["3132.39","0.02","0","1"],["3132.4","28706.88","0","2"],["3132.41","24.84","0","2"],["3132.42","0.01","0","1"],["3132.43","102.67","0","1"]],"bids":[["3131","2.59","0","1"],["3130.99","0.05","0","1"],["3130.94","0.01","0","1"],["3130.91","0.7","0","2"],["3130.86","13.9","0","1"]],"instId":"ETH-USDT-SWAP","ts":"1765632009007","seqId":1158528219}]}
{"arg":{"channel":"bbo-tbt","instId":"ETH-USDT-SWAP"},"data":[{"asks":[["3132.4","28706.52","0","2"]],"bids":[["3131","2.59","0","1"]],"ts":"1765632009017","seqId":1158528250}]}
{"arg":{"channel":"tickers","instId":"ETH-USDT-SWAP"},"data":[{"instType":"SWAP","instId":"ETH-USDT-SWAP","last":"3131.5","lastSz":"0.01","askPx":"3131.5","askSz":"0.01","bidPx":"3129.06","bidSz":"27.14","open24h":"3248","high24h":"3315.64","low24h":"3072.11","sodUtc0":"3108.41","sodUtc8":"3174.4","volCcy24h":"19461782.845","vol24h":"194617828.45","ts":"1765632008985"}]}
{"arg":{"channel":"bbo-tbt","instId":"ETH-USDT-SWAP"},"data":[{"asks":[["3132.4","28706.52","0","2"]],"bids":[["3131.07","0.02","0","1"]],"ts":"1765632009027","seqId":1158528260}]}
{"arg":{"channel":"books","instId":"ETH-USDT-SWAP"},"action":"update","data":[{"asks":[["3132.39","0","0","0"],["3132.4","28706.52","0","2"],["3136.96","0.06","0","2"]],"bids":[["3131.07","0.02","0","1"],["3125.03","0","0","0"]],"ts":"1765632009107","checksum":-992971106,"seqId":1158528290,"prevSeqId":1158528219}]}
{"arg":{"channel":"books5","instId":"ETH-USDT-SWAP"},"data":[{"asks":[["3132.4","28706.52","0","2"],["3132.41","24.84","0","2"],["3132.42","0.01","0","1"],["3132.43","102.67","0","1"],["3132.44","63.74","0","6"]],"bids":[["3131.07","0.02","0","1"],["3131","2.59","0","1"],["3130.99","0.05","0","1"],["3130.94","0.01","0","1"],["3130.91","0.7","0","2"]],"instId":"ETH-USDT-SWAP","ts":"1765632009107","seqId":1158528290}]}
